Workbook

Sheet BB816使い方
A1: BB816 ― ボリンジャーバンド判定を切り離して、スイング用に組み直したブック
A2: 300銘柄 × 250営業日（2025-07-29〜2026-08-06）の実データで検証した結果に基づいています。
A3: 指標の計算は V815 の BBスクリーニング と突き合わせ、300銘柄すべてで一致することを確認済みです。
A5: ■ 売買ルール（これだけ守れば動く）
A6: 入口 終値が +2σ を上抜け、かつ 出来高が直近5日平均の1.5倍以上、
A7: かつ MFI14 が 55以上、かつ RSI14 が 80以下
A8: 順位 BB816スコアの高い順。1日に建てるのは最大3銘柄
A9: 建て方 翌営業日の寄付（始値）で買う
A10: 枠 資金を8等分。1銘柄あたり12.5%。同じ銘柄を重ねて持たない
A11: 損切り 建値から -8%。買えたその日に逆指値を置く
A12: 手仕舞い 10営業日たったら損益に関わらず引けで売る
A13: 置かない 利確目標・トレーリングストップ・地合いフィルタ（いずれも検証で成績を下げた）
... A73: ※ 楽天RSSアドインが入っていないパソコンでも開けます。

Sheet BB816候補
A1: 🏆 BB816 明日の買い候補
A2: 総合判定が「◎買い」の銘柄を、翌営業日の寄付で買う。1日に建てるのは上から最大3銘柄まで。1銘柄は資金の1÷枠数（既定8枠＝12.5%）。
A3: ◎買いの件数 | C3: =COUNTIF(BB816判定!$S$6:$S$505,"◎買い") | D3: SMA20より上の銘柄の割合（地合いの参考。売買条件には使いません） | H3: =IFERROR(SUMPRODUCT((BB816判定!$D$6:$D$505<>"")*(BB816判定!$D$6:$D$505>BB816判定!$E$6:$E$505))/COUNT(BB816判定!$D$6:$D$505),"") | I3: データ最終日 | K3: =終値!E3
A4: 順位 | B4: コード | C4: 銘柄名 | D4: 現在値 | E4: BB816 スコア | F4: 総合判定 | G4: 守り 分析官 | H4: 攻め 分析官 | I4: RSI14 | J4: MFI14 | K4: 出来高 倍率 | L4: 20日 騰落率 | M4: エントリー (翌日寄付) | N4: 損切り 価格 | O4: 必要資金 (100株) | P4: 資金枠に 収まるか | Q4: 株探
A5: 1 | B5: =IFERROR(INDEX(BB816判定!$B$6:$B$505,MATCH(LARGE(BB816判定!$Y$6:$Y$505,$A5),BB816判定!$Y$6:$Y$505,0)),"") | C5: =IFERROR(INDEX(BB816判定!$C$6:$C$505,MATCH(LARGE(BB816判定!$Y$6:$Y$505,$A5),BB816判定!$Y$6:$Y$505,0)),"") | D5: =IFERROR(INDEX(BB816判定!$D$6:$D$505,MATCH(LARGE(BB816判定!$Y$6:$Y$505,$A5),BB816判定!$Y$6:$Y$505,0)),"") | E5: =IFERROR(INDEX(BB816判定!$Q$6:$Q$505,MATCH(LARGE(BB816判定!$Y$6:$Y$505,$A5),BB816判定!$Y$6:$Y$505,0)),"") | F5: =IFERROR(INDEX(BB816判定!$S$6:$S$505,MATCH(LARGE(BB816判定!$Y$6:$Y$505,$A5),BB816判定!$Y$6:$Y$505,0)),"") | G5: =IFERROR(INDEX(BB816判定!$T$6:$T$505,MATCH(LARGE(BB816判定!$Y$6:$Y$505,$A5),BB816判定!$Y$6:$Y$505,0)),"") | H5: =IFERROR(INDEX(BB816判定!$U$6:$U$505,MATCH(LARGE(BB816判定!$Y$6:$Y$505,$A5),BB816判定!$Y$6:$Y$505,0)),"") | I5: =IFERROR(INDEX(BB816判定!$M$6:$M$505,MATCH(LARGE(BB816判定!$Y$6:$Y$505,$A5),BB816判定!$Y$6:$Y$505,0)),"") | J5: =IFERROR(INDEX(BB816判定!$N$6:$N$505,MATCH(LARGE(BB816判定!$Y$6:$Y$505,$A5),BB816判定!$Y$6:$Y$505,0)),"") | K5: =IFERROR(INDEX(BB816判定!$O$6:$O$505,MATCH(LARGE(BB816判定!$Y$6:$Y$505,$A5),BB816判定!$Y$6:$Y$505,0)),"") | L5: =IFERROR(INDEX(BB816判定!$P$6:$P$505,MATCH(LARGE(BB816判定!$Y$6:$Y$505,$A5),BB816判定!$Y$6:$Y$505,0)),"") | M5: =IFERROR(INDEX(BB816判定!$V$6:$V$505,MATCH(LARGE(BB816判定!$Y$6:$Y$505,$A5),BB816判定!$Y$6:$Y$505,0)),"") | N5: =IFERROR(INDEX(BB816判定!$W$6:$W$505,MATCH(LARGE(BB816判定!$Y$6:$Y$505,$A5),BB816判定!$Y$6:$Y$505,0)),"") | O5: =IFERROR(INDEX(BB816判定!$Z$6:$Z$505,MATCH(LARGE(BB816判定!$Y$6:$Y$505,$A5),BB816判定!$Y$6:$Y$505,0)),"") | P5: =IFERROR(INDEX(BB816判定!$AA$6:$AA$505,MATCH(LARGE(BB816判定!$Y$6:$Y$505,$A5),BB816判定!$Y$6:$Y$505,0)),"") | Q5: =IF($B5="","",HYPERLINK("https://kabutan.jp/stock/?code="&$B5,"📈"))
A6: 2 | B6: =IFERROR(INDEX(BB816判定!$B$6:$B$505,MATCH(LARGE(BB816判定!$Y$6:$Y$505,$A6),BB816判定!$Y$6:$Y$505,0)),"") | C6: =IFERROR(INDEX(BB816判定!$C$6:$C$505,MATCH(LARGE(BB816判定!$Y$6:$Y$505,$A6),BB816判定!$Y$6:$Y$505,0)),"") | D6: =IFERROR(INDEX(BB816判定!$D$6:$D$505,MATCH(LARGE(BB816判定!$Y$6:$Y$505,$A6),BB816判定!$Y$6:$Y$505,0)),"") | E6: =IFERROR(INDEX(BB816判定!$Q$6:$Q$505,MATCH(LARGE(BB816判定!$Y$6:$Y$505,$A6),BB816判定!$Y$6:$Y$505,0)),"") | F6: =IFERROR(INDEX(BB816判定!$S$6:$S$505,MATCH(LARGE(BB816判定!$Y$6:$Y$505,$A6),BB816判定!$Y$6:$Y$505,0)),"") | G6: =IFERROR(INDEX(BB816判定!$T$6:$T$505,MATCH(LARGE(BB816判定!$Y$6:$Y$505,$A6),BB816判定!$Y$6:$Y$505,0)),"") | H6: =IFERROR(INDEX(BB816判定!$U$6:$U$505,MATCH(LARGE(BB816判定!$Y$6:$Y$505,$A6),BB816判定!$Y$6:$Y$505,0)),"") | I6: =IFERROR(INDEX(BB816判定!$M$6:$M$505,MATCH(LARGE(BB816判定!$Y$6:$Y$505,$A6),BB816判定!$Y$6:$Y$505,0)),"") | J6: =IFERROR(INDEX(BB816判定!$N$6:$N$505,MATCH(LARGE(BB816判定!$Y$6:$Y$505,$A6),BB816判定!$Y$6:$Y$505,0)),"") | K6: =IFERROR(INDEX(BB816判定!$O$6:$O$505,MATCH(LARGE(BB816判定!$Y$6:$Y$505,$A6),BB816判定!$Y$6:$Y$505,0)),"") | L6: =IFERROR(INDEX(BB816判定!$P$6:$P$505,MATCH(LARGE(BB816判定!$Y$6:$Y$505,$A6),BB816判定!$Y$6:$Y$505,0)),"") | M6: =IFERROR(INDEX(BB816判定!$V$6:$V$505,MATCH(LARGE(BB816判定!$Y$6:$Y$505,$A6),BB816判定!$Y$6:$Y$505,0)),"") | N6: =IFERROR(INDEX(BB816判定!$W$6:$W$505,MATCH(LARGE(BB816判定!$Y$6:$Y$505,$A6),BB816判定!$Y$6:$Y$505,0)),"") | O6: =IFERROR(INDEX(BB816判定!$Z$6:$Z$505,MATCH(LARGE(BB816判定!$Y$6:$Y$505,$A6),BB816判定!$Y$6:$Y$505,0)),"") | P6: =IFERROR(INDEX(BB816判定!$AA$6:$AA$505,MATCH(LARGE(BB816判定!$Y$6:$Y$505,$A6),BB816判定!$Y$6:$Y$505,0)),"") | Q6: =IF($B6="","",HYPERLINK("https://kabutan.jp/stock/?code="&$B6,"📈"))
A7: 3 | B7: =IFERROR(INDEX(BB816判定!$B$6:$B$505,MATCH(LARGE(BB816判定!$Y$6:$Y$505,$A7),BB816判定!$Y$6:$Y$505,0)),"") | C7: =IFERROR(INDEX(BB816判定!$C$6:$C$505,MATCH(LARGE(BB816判定!$Y$6:$Y$505,$A7),BB816判定!$Y$6:$Y$505,0)),"") | D7: =IFERROR(INDEX(BB816判定!$D$6:$D$505,MATCH(LARGE(BB816判定!$Y$6:$Y$505,$A7),BB816判定!$Y$6:$Y$505,0)),"") | E7: =IFERROR(INDEX(BB816判定!$Q$6:$Q$505,MATCH(LARGE(BB816判定!$Y$6:$Y$505,$A7),BB816判定!$Y$6:$Y$505,0)),"") | F7: =IFERROR(INDEX(BB816判定!$S$6:$S$505,MATCH(LARGE(BB816判定!$Y$6:$Y$505,$A7),BB816判定!$Y$6:$Y$505,0)),"") | G7: =IFERROR(INDEX(BB816判定!$T$6:$T$505,MATCH(LARGE(BB816判定!$Y$6:$Y$505,$A7),BB816判定!$Y$6:$Y$505,0)),"") | H7: =IFERROR(INDEX(BB816判定!$U$6:$U$505,MATCH(LARGE(BB816判定!$Y$6:$Y$505,$A7),BB816判定!$Y$6:$Y$505,0)),"") | I7: =IFERROR(INDEX(BB816判定!$M$6:$M$505,MATCH(LARGE(BB816判定!$Y$6:$Y$505,$A7),BB816判定!$Y$6:$Y$505,0)),"") | J7: =IFERROR(INDEX(BB816判定!$N$6:$N$505,MATCH(LARGE(BB816判定!$Y$6:$Y$505,$A7),BB816判定!$Y$6:$Y$505,0)),"") | K7: =IFERROR(INDEX(BB816判定!$O$6:$O$505,MATCH(LARGE(BB816判定!$Y$6:$Y$505,$A7),BB816判定!$Y$6:$Y$505,0)),"") | L7: =IFERROR(INDEX(BB816判定!$P$6:$P$505,MATCH(LARGE(BB816判定!$Y$6:$Y$505,$A7),BB816判定!$Y$6:$Y$505,0)),"") | M7: =IFERROR(INDEX(BB816判定!$V$6:$V$505,MATCH(LARGE(BB816判定!$Y$6:$Y$505,$A7),BB816判定!$Y$6:$Y$505,0)),"") | N7: =IFERROR(INDEX(BB816判定!$W$6:$W$505,MATCH(LARGE(BB816判定!$Y$6:$Y$505,$A7),BB816判定!$Y$6:$Y$505,0)),"") | O7: =IFERROR(INDEX(BB816判定!$Z$6:$Z$505,MATCH(LARGE(BB816判定!$Y$6:$Y$505,$A7),BB816判定!$Y$6:$Y$505,0)),"") | P7: =IFERROR(INDEX(BB816判定!$AA$6:$AA$505,MATCH(LARGE(BB816判定!$Y$6:$Y$505,$A7),BB816判定!$Y$6:$Y$505,0)),"") | Q7: =IF($B7="","",HYPERLINK("https://kabutan.jp/stock/?code="&$B7,"📈"))
A8: 4 | B8: =IFERROR(INDEX(BB816判定!$B$6:$B$505,MATCH(LARGE(BB816判定!$Y$6:$Y$505,$A8),BB816判定!$Y$6:$Y$505,0)),"") | C8: =IFERROR(INDEX(BB816判定!$C$6:$C$505,MATCH(LARGE(BB816判定!$Y$6:$Y$505,$A8),BB816判定!$Y$6:$Y$505,0)),"") | D8: =IFERROR(INDEX(BB816判定!$D$6:$D$505,MATCH(LARGE(BB816判定!$Y$6:$Y$505,$A8),BB816判定!$Y$6:$Y$505,0)),"") | E8: =IFERROR(INDEX(BB816判定!$Q$6:$Q$505,MATCH(LARGE(BB816判定!$Y$6:$Y$505,$A8),BB816判定!$Y$6:$Y$505,0)),"") | F8: =IFERROR(INDEX(BB816判定!$S$6:$S$505,MATCH(LARGE(BB816判定!$Y$6:$Y$505,$A8),BB816判定!$Y$6:$Y$505,0)),"") | G8: =IFERROR(INDEX(BB816判定!$T$6:$T$505,MATCH(LARGE(BB816判定!$Y$6:$Y$505,$A8),BB816判定!$Y$6:$Y$505,0)),"") | H8: =IFERROR(INDEX(BB816判定!$U$6:$U$505,MATCH(LARGE(BB816判定!$Y$6:$Y$505,$A8),BB816判定!$Y$6:$Y$505,0)),"") | I8: =IFERROR(INDEX(BB816判定!$M$6:$M$505,MATCH(LARGE(BB816判定!$Y$6:$Y$505,$A8),BB816判定!$Y$6:$Y$505,0)),"") | J8: =IFERROR(INDEX(BB816判定!$N$6:$N$505,MATCH(LARGE(BB816判定!$Y$6:$Y$505,$A8),BB816判定!$Y$6:$Y$505,0)),"") | K8: =IFERROR(INDEX(BB816判定!$O$6:$O$505,MATCH(LARGE(BB816判定!$Y$6:$Y$505,$A8),BB816判定!$Y$6:$Y$505,0)),"") | L8: =IFERROR(INDEX(BB816判定!$P$6:$P$505,MATCH(LARGE(BB816判定!$Y$6:$Y$505,$A8),BB816判定!$Y$6:$Y$505,0)),"") | M8: =IFERROR(INDEX(BB816判定!$V$6:$V$505,MATCH(LARGE(BB816判定!$Y$6:$Y$505,$A8),BB816判定!$Y$6:$Y$505,0)),"") | N8: =IFERROR(INDEX(BB816判定!$W$6:$W$505,MATCH(LARGE(BB816判定!$Y$6:$Y$505,$A8),BB816判定!$Y$6:$Y$505,0)),"") | O8: =IFERROR(INDEX(BB816判定!$Z$6:$Z$505,MATCH(LARGE(BB816判定!$Y$6:$Y$505,$A8),BB816判定!$Y$6:$Y$505,0)),"") | P8: =IFERROR(INDEX(BB816判定!$AA$6:$AA$505,MATCH(LARGE(BB816判定!$Y$6:$Y$505,$A8),BB816判定!$Y$6:$Y$505,0)),"") | Q8: =IF($B8="","",HYPERLINK("https://kabutan.jp/stock/?code="&$B8,"📈"))
A9: 5 | B9: =IFERROR(INDEX(BB816判定!$B$6:$B$505,MATCH(LARGE(BB816判定!$Y$6:$Y$505,$A9),BB816判定!$Y$6:$Y$505,0)),"") | C9: =IFERROR(INDEX(BB816判定!$C$6:$C$505,MATCH(LARGE(BB816判定!$Y$6:$Y$505,$A9),BB816判定!$Y$6:$Y$505,0)),"") | D9: =IFERROR(INDEX(BB816判定!$D$6:$D$505,MATCH(LARGE(BB816判定!$Y$6:$Y$505,$A9),BB816判定!$Y$6:$Y$505,0)),"") | E9: =IFERROR(INDEX(BB816判定!$Q$6:$Q$505,MATCH(LARGE(BB816判定!$Y$6:$Y$505,$A9),BB816判定!$Y$6:$Y$505,0)),"") | F9: =IFERROR(INDEX(BB816判定!$S$6:$S$505,MATCH(LARGE(BB816判定!$Y$6:$Y$505,$A9),BB816判定!$Y$6:$Y$505,0)),"") | G9: =IFERROR(INDEX(BB816判定!$T$6:$T$505,MATCH(LARGE(BB816判定!$Y$6:$Y$505,$A9),BB816判定!$Y$6:$Y$505,0)),"") | H9: =IFERROR(INDEX(BB816判定!$U$6:$U$505,MATCH(LARGE(BB816判定!$Y$6:$Y$505,$A9),BB816判定!$Y$6:$Y$505,0)),"") | I9: =IFERROR(INDEX(BB816判定!$M$6:$M$505,MATCH(LARGE(BB816判定!$Y$6:$Y$505,$A9),BB816判定!$Y$6:$Y$505,0)),"") | J9: =IFERROR(INDEX(BB816判定!$N$6:$N$505,MATCH(LARGE(BB816判定!$Y$6:$Y$505,$A9),BB816判定!$Y$6:$Y$505,0)),"") | K9: =IFERROR(INDEX(BB816判定!$O$6:$O$505,MATCH(LARGE(BB816判定!$Y$6:$Y$505,$A9),BB816判定!$Y$6:$Y$505,0)),"") | L9: =IFERROR(INDEX(BB816判定!$P$6:$P$505,MATCH(LARGE(BB816判定!$Y$6:$Y$505,$A9),BB816判定!$Y$6:$Y$505,0)),"") | M9: =IFERROR(INDEX(BB816判定!$V$6:$V$505,MATCH(LARGE(BB816判定!$Y$6:$Y$505,$A9),BB816判定!$Y$6:$Y$505,0)),"") | N9: =IFERROR(INDEX(BB816判定!$W$6:$W$505,MATCH(LARGE(BB816判定!$Y$6:$Y$505,$A9),BB816判定!$Y$6:$Y$505,0)),"") | O9: =IFERROR(INDEX(BB816判定!$Z$6:$Z$505,MATCH(LARGE(BB816判定!$Y$6:$Y$505,$A9),BB816判定!$Y$6:$Y$505,0)),"") | P9: =IFERROR(INDEX(BB816判定!$AA$6:$AA$505,MATCH(LARGE(BB816判定!$Y$6:$Y$505,$A9),BB816判定!$Y$6:$Y$505,0)),"") | Q9: =IF($B9="","",HYPERLINK("https://kabutan.jp/stock/?code="&$B9,"📈"))
A10: 6 | B10: =IFERROR(INDEX(BB816判定!$B$6:$B$505,MATCH(LARGE(BB816判定!$Y$6:$Y$505,$A10),BB816判定!$Y$6:$Y$505,0)),"") | C10: =IFERROR(INDEX(BB816判定!$C$6:$C$505,MATCH(LARGE(BB816判定!$Y$6:$Y$505,$A10),BB816判定!$Y$6:$Y$505,0)),"") | D10: =IFERROR(INDEX(BB816判定!$D$6:$D$505,MATCH(LARGE(BB816判定!$Y$6:$Y$505,$A10),BB816判定!$Y$6:$Y$505,0)),"") | E10: =IFERROR(INDEX(BB816判定!$Q$6:$Q$505,MATCH(LARGE(BB816判定!$Y$6:$Y$505,$A10),BB816判定!$Y$6:$Y$505,0)),"") | F10: =IFERROR(INDEX(BB816判定!$S$6:$S$505,MATCH(LARGE(BB816判定!$Y$6:$Y$505,$A10),BB816判定!$Y$6:$Y$505,0)),"") | G10: =IFERROR(INDEX(BB816判定!$T$6:$T$505,MATCH(LARGE(BB816判定!$Y$6:$Y$505,$A10),BB816判定!$Y$6:$Y$505,0)),"") | H10: =IFERROR(INDEX(BB816判定!$U$6:$U$505,MATCH(LARGE(BB816判定!$Y$6:$Y$505,$A10),BB816判定!$Y$6:$Y$505,0)),"") | I10: =IFERROR(INDEX(BB816判定!$M$6:$M$505,MATCH(LARGE(BB816判定!$Y$6:$Y$505,$A10),BB816判定!$Y$6:$Y$505,0)),"") | J10: =IFERROR(INDEX(BB816判定!$N$6:$N$505,MATCH(LARGE(BB816判定!$Y$6:$Y$505,$A10),BB816判定!$Y$6:$Y$505,0)),"") | K10: =IFERROR(INDEX(BB816判定!$O$6:$O$505,MATCH(LARGE(BB816判定!$Y$6:$Y$505,$A10),BB816判定!$Y$6:$Y$505,0)),"") | L10: =IFERROR(INDEX(BB816判定!$P$6:$P$505,MATCH(LARGE(BB816判定!$Y$6:$Y$505,$A10),BB816判定!$Y$6:$Y$505,0)),"") | M10: =IFERROR(INDEX(BB816判定!$V$6:$V$505,MATCH(LARGE(BB816判定!$Y$6:$Y$505,$A10),BB816判定!$Y$6:$Y$505,0)),"") | N10: =IFERROR(INDEX(BB816判定!$W$6:$W$505,MATCH(LARGE(BB816判定!$Y$6:$Y$505,$A10),BB816判定!$Y$6:$Y$505,0)),"") | O10: =IFERROR(INDEX(BB816判定!$Z$6:$Z$505,MATCH(LARGE(BB816判定!$Y$6:$Y$505,$A10),BB816判定!$Y$6:$Y$505,0)),"") | P10: =IFERROR(INDEX(BB816判定!$AA$6:$AA$505,MATCH(LARGE(BB816判定!$Y$6:$Y$505,$A10),BB816判定!$Y$6:$Y$505,0)),"") | Q10: =IF($B10="","",HYPERLINK("https://kabutan.jp/stock/?code="&$B10,"📈"))
A11: 7 | B11: =IFERROR(INDEX(BB816判定!$B$6:$B$505,MATCH(LARGE(BB816判定!$Y$6:$Y$505,$A11),BB816判定!$Y$6:$Y$505,0)),"") | C11: =IFERROR(INDEX(BB816判定!$C$6:$C$505,MATCH(LARGE(BB816判定!$Y$6:$Y$505,$A11),BB816判定!$Y$6:$Y$505,0)),"") | D11: =IFERROR(INDEX(BB816判定!$D$6:$D$505,MATCH(LARGE(BB816判定!$Y$6:$Y$505,$A11),BB816判定!$Y$6:$Y$505,0)),"") | E11: =IFERROR(INDEX(BB816判定!$Q$6:$Q$505,MATCH(LARGE(BB816判定!$Y$6:$Y$505,$A11),BB816判定!$Y$6:$Y$505,0)),"") | F11: =IFERROR(INDEX(BB816判定!$S$6:$S$505,MATCH(LARGE(BB816判定!$Y$6:$Y$505,$A11),BB816判定!$Y$6:$Y$505,0)),"") | G11: =IFERROR(INDEX(BB816判定!$T$6:$T$505,MATCH(LARGE(BB816判定!$Y$6:$Y$505,$A11),BB816判定!$Y$6:$Y$505,0)),"") | H11: =IFERROR(INDEX(BB816判定!$U$6:$U$505,MATCH(LARGE(BB816判定!$Y$6:$Y$505,$A11),BB816判定!$Y$6:$Y$505,0)),"") | I11: =IFERROR(INDEX(BB816判定!$M$6:$M$505,MATCH(LARGE(BB816判定!$Y$6:$Y$505,$A11),BB816判定!$Y$6:$Y$505,0)),"") | J11: =IFERROR(INDEX(BB816判定!$N$6:$N$505,MATCH(LARGE(BB816判定!$Y$6:$Y$505,$A11),BB816判定!$Y$6:$Y$505,0)),"") | K11: =IFERROR(INDEX(BB816判定!$O$6:$O$505,MATCH(LARGE(BB816判定!$Y$6:$Y$505,$A11),BB816判定!$Y$6:$Y$505,0)),"") | L11: =IFERROR(INDEX(BB816判定!$P$6:$P$505,MATCH(LARGE(BB816判定!$Y$6:$Y$505,$A11),BB816判定!$Y$6:$Y$505,0)),"") | M11: =IFERROR(INDEX(BB816判定!$V$6:$V$505,MATCH(LARGE(BB816判定!$Y$6:$Y$505,$A11),BB816判定!$Y$6:$Y$505,0)),"") | N11: =IFERROR(INDEX(BB816判定!$W$6:$W$505,MATCH(LARGE(BB816判定!$Y$6:$Y$505,$A11),BB816判定!$Y$6:$Y$505,0)),"") | O11: =IFERROR(INDEX(BB816判定!$Z$6:$Z$505,MATCH(LARGE(BB816判定!$Y$6:$Y$505,$A11),BB816判定!$Y$6:$Y$505,0)),"") | P11: =IFERROR(INDEX(BB816判定!$AA$6:$AA$505,MATCH(LARGE(BB816判定!$Y$6:$Y$505,$A11),BB816判定!$Y$6:$Y$505,0)),"") | Q11: =IF($B11="","",HYPERLINK("https://kabutan.jp/stock/?code="&$B11,"📈"))
A12: 8 | B12: =IFERROR(INDEX(BB816判定!$B$6:$B$505,MATCH(LARGE(BB816判定!$Y$6:$Y$505,$A12),BB816判定!$Y$6:$Y$505,0)),"") | C12: =IFERROR(INDEX(BB816判定!$C$6:$C$505,MATCH(LARGE(BB816判定!$Y$6:$Y$505,$A12),BB816判定!$Y$6:$Y$505,0)),"") | D12: =IFERROR(INDEX(BB816判定!$D$6:$D$505,MATCH(LARGE(BB816判定!$Y$6:$Y$505,$A12),BB816判定!$Y$6:$Y$505,0)),"") | E12: =IFERROR(INDEX(BB816判定!$Q$6:$Q$505,MATCH(LARGE(BB816判定!$Y$6:$Y$505,$A12),BB816判定!$Y$6:$Y$505,0)),"") | F12: =IFERROR(INDEX(BB816判定!$S$6:$S$505,MATCH(LARGE(BB816判定!$Y$6:$Y$505,$A12),BB816判定!$Y$6:$Y$505,0)),"") | G12: =IFERROR(INDEX(BB816判定!$T$6:$T$505,MATCH(LARGE(BB816判定!$Y$6:$Y$505,$A12),BB816判定!$Y$6:$Y$505,0)),"") | H12: =IFERROR(INDEX(BB816判定!$U$6:$U$505,MATCH(LARGE(BB816判定!$Y$6:$Y$505,$A12),BB816判定!$Y$6:$Y$505,0)),"") | I12: =IFERROR(INDEX(BB816判定!$M$6:$M$505,MATCH(LARGE(BB816判定!$Y$6:$Y$505,$A12),BB816判定!$Y$6:$Y$505,0)),"") | J12: =IFERROR(INDEX(BB816判定!$N$6:$N$505,MATCH(LARGE(BB816判定!$Y$6:$Y$505,$A12),BB816判定!$Y$6:$Y$505,0)),"") | K12: =IFERROR(INDEX(BB816判定!$O$6:$O$505,MATCH(LARGE(BB816判定!$Y$6:$Y$505,$A12),BB816判定!$Y$6:$Y$505,0)),"") | L12: =IFERROR(INDEX(BB816判定!$P$6:$P$505,MATCH(LARGE(BB816判定!$Y$6:$Y$505,$A12),BB816判定!$Y$6:$Y$505,0)),"") | M12: =IFERROR(INDEX(BB816判定!$V$6:$V$505,MATCH(LARGE(BB816判定!$Y$6:$Y$505,$A12),BB816判定!$Y$6:$Y$505,0)),"") | N12: =IFERROR(INDEX(BB816判定!$W$6:$W$505,MATCH(LARGE(BB816判定!$Y$6:$Y$505,$A12),BB816判定!$Y$6:$Y$505,0)),"") | O12: =IFERROR(INDEX(BB816判定!$Z$6:$Z$505,MATCH(LARGE(BB816判定!$Y$6:$Y$505,$A12),BB816判定!$Y$6:$Y$505,0)),"") | P12: =IFERROR(INDEX(BB816判定!$AA$6:$AA$505,MATCH(LARGE(BB816判定!$Y$6:$Y$505,$A12),BB816判定!$Y$6:$Y$505,0)),"") | Q12: =IF($B12="","",HYPERLINK("https://kabutan.jp/stock/?code="&$B12,"📈"))
A13: 9 | B13: =IFERROR(INDEX(BB816判定!$B$6:$B$505,MATCH(LARGE(BB816判定!$Y$6:$Y$505,$A13),BB816判定!$Y$6:$Y$505,0)),"") | C13: =IFERROR(INDEX(BB816判定!$C$6:$C$505,MATCH(LARGE(BB816判定!$Y$6:$Y$505,$A13),BB816判定!$Y$6:$Y$505,0)),"") | D13: =IFERROR(INDEX(BB816判定!$D$6:$D$505,MATCH(LARGE(BB816判定!$Y$6:$Y$505,$A13),BB816判定!$Y$6:$Y$505,0)),"") | E13: =IFERROR(INDEX(BB816判定!$Q$6:$Q$505,MATCH(LARGE(BB816判定!$Y$6:$Y$505,$A13),BB816判定!$Y$6:$Y$505,0)),"") | F13: =IFERROR(INDEX(BB816判定!$S$6:$S$505,MATCH(LARGE(BB816判定!$Y$6:$Y$505,$A13),BB816判定!$Y$6:$Y$505,0)),"") | G13: =IFERROR(INDEX(BB816判定!$T$6:$T$505,MATCH(LARGE(BB816判定!$Y$6:$Y$505,$A13),BB816判定!$Y$6:$Y$505,0)),"") | H13: =IFERROR(INDEX(BB816判定!$U$6:$U$505,MATCH(LARGE(BB816判定!$Y$6:$Y$505,$A13),BB816判定!$Y$6:$Y$505,0)),"") | I13: =IFERROR(INDEX(BB816判定!$M$6:$M$505,MATCH(LARGE(BB816判定!$Y$6:$Y$505,$A13),BB816判定!$Y$6:$Y$505,0)),"") | J13: =IFERROR(INDEX(BB816判定!$N$6:$N$505,MATCH(LARGE(BB816判定!$Y$6:$Y$505,$A13),BB816判定!$Y$6:$Y$505,0)),"") | K13: =IFERROR(INDEX(BB816判定!$O$6:$O$505,MATCH(LARGE(BB816判定!$Y$6:$Y$505,$A13),BB816判定!$Y$6:$Y$505,0)),"") | L13: =IFERROR(INDEX(BB816判定!$P$6:$P$505,MATCH(LARGE(BB816判定!$Y$6:$Y$505,$A13),BB816判定!$Y$6:$Y$505,0)),"") | M13: =IFERROR(INDEX(BB816判定!$V$6:$V$505,MATCH(LARGE(BB816判定!$Y$6:$Y$505,$A13),BB816判定!$Y$6:$Y$505,0)),"") | N13: =IFERROR(INDEX(BB816判定!$W$6:$W$505,MATCH(LARGE(BB816判定!$Y$6:$Y$505,$A13),BB816判定!$Y$6:$Y$505,0)),"") | O13: =IFERROR(INDEX(BB816判定!$Z$6:$Z$505,MATCH(LARGE(BB816判定!$Y$6:$Y$505,$A13),BB816判定!$Y$6:$Y$505,0)),"") | P13: =IFERROR(INDEX(BB816判定!$AA$6:$AA$505,MATCH(LARGE(BB816判定!$Y$6:$Y$505,$A13),BB816判定!$Y$6:$Y$505,0)),"") | Q13: =IF($B13="","",HYPERLINK("https://kabutan.jp/stock/?code="&$B13,"📈"))
A14: 10 | B14: =IFERROR(INDEX(BB816判定!$B$6:$B$505,MATCH(LARGE(BB816判定!$Y$6:$Y$505,$A14),BB816判定!$Y$6:$Y$505,0)),"") | C14: =IFERROR(INDEX(BB816判定!$C$6:$C$505,MATCH(LARGE(BB816判定!$Y$6:$Y$505,$A14),BB816判定!$Y$6:$Y$505,0)),"") | D14: =IFERROR(INDEX(BB816判定!$D$6:$D$505,MATCH(LARGE(BB816判定!$Y$6:$Y$505,$A14),BB816判定!$Y$6:$Y$505,0)),"") | E14: =IFERROR(INDEX(BB816判定!$Q$6:$Q$505,MATCH(LARGE(BB816判定!$Y$6:$Y$505,$A14),BB816判定!$Y$6:$Y$505,0)),"") | F14: =IFERROR(INDEX(BB816判定!$S$6:$S$505,MATCH(LARGE(BB816判定!$Y$6:$Y$505,$A14),BB816判定!$Y$6:$Y$505,0)),"") | G14: =IFERROR(INDEX(BB816判定!$T$6:$T$505,MATCH(LARGE(BB816判定!$Y$6:$Y$505,$A14),BB816判定!$Y$6:$Y$505,0)),"") | H14: =IFERROR(INDEX(BB816判定!$U$6:$U$505,MATCH(LARGE(BB816判定!$Y$6:$Y$505,$A14),BB816判定!$Y$6:$Y$505,0)),"") | I14: =IFERROR(INDEX(BB816判定!$M$6:$M$505,MATCH(LARGE(BB816判定!$Y$6:$Y$505,$A14),BB816判定!$Y$6:$Y$505,0)),"") | J14: =IFERROR(INDEX(BB816判定!$N$6:$N$505,MATCH(LARGE(BB816判定!$Y$6:$Y$505,$A14),BB816判定!$Y$6:$Y$505,0)),"") | K14: =IFERROR(INDEX(BB816判定!$O$6:$O$505,MATCH(LARGE(BB816判定!$Y$6:$Y$505,$A14),BB816判定!$Y$6:$Y$505,0)),"") | L14: =IFERROR(INDEX(BB816判定!$P$6:$P$505,MATCH(LARGE(BB816判定!$Y$6:$Y$505,$A14),BB816判定!$Y$6:$Y$505,0)),"") | M14: =IFERROR(INDEX(BB816判定!$V$6:$V$505,MATCH(LARGE(BB816判定!$Y$6:$Y$505,$A14),BB816判定!$Y$6:$Y$505,0)),"") | N14: =IFERROR(INDEX(BB816判定!$W$6:$W$505,MATCH(LARGE(BB816判定!$Y$6:$Y$505,$A14),BB816判定!$Y$6:$Y$505,0)),"") | O14: =IFERROR(INDEX(BB816判定!$Z$6:$Z$505,MATCH(LARGE(BB816判定!$Y$6:$Y$505,$A14),BB816判定!$Y$6:$Y$505,0)),"") | P14: =IFERROR(INDEX(BB816判定!$AA$6:$AA$505,MATCH(LARGE(BB816判定!$Y$6:$Y$505,$A14),BB816判定!$Y$6:$Y$505,0)),"") | Q14: =IF($B14="","",HYPERLINK("https://kabutan.jp/stock/?code="&$B14,"📈"))
A15: 11 | B15: =IFERROR(INDEX(BB816判定!$B$6:$B$505,MATCH(LARGE(BB816判定!$Y$6:$Y$505,$A15),BB816判定!$Y$6:$Y$505,0)),"") | C15: =IFERROR(INDEX(BB816判定!$C$6:$C$505,MATCH(LARGE(BB816判定!$Y$6:$Y$505,$A15),BB816判定!$Y$6:$Y$505,0)),"") | D15: =IFERROR(INDEX(BB816判定!$D$6:$D$505,MATCH(LARGE(BB816判定!$Y$6:$Y$505,$A15),BB816判定!$Y$6:$Y$505,0)),"") | E15: =IFERROR(INDEX(BB816判定!$Q$6:$Q$505,MATCH(LARGE(BB816判定!$Y$6:$Y$505,$A15),BB816判定!$Y$6:$Y$505,0)),"") | F15: =IFERROR(INDEX(BB816判定!$S$6:$S$505,MATCH(LARGE(BB816判定!$Y$6:$Y$505,$A15),BB816判定!$Y$6:$Y$505,0)),"") | G15: =IFERROR(INDEX(BB816判定!$T$6:$T$505,MATCH(LARGE(BB816判定!$Y$6:$Y$505,$A15),BB816判定!$Y$6:$Y$505,0)),"") | H15: =IFERROR(INDEX(BB816判定!$U$6:$U$505,MATCH(LARGE(BB816判定!$Y$6:$Y$505,$A15),BB816判定!$Y$6:$Y$505,0)),"") | I15: =IFERROR(INDEX(BB816判定!$M$6:$M$505,MATCH(LARGE(BB816判定!$Y$6:$Y$505,$A15),BB816判定!$Y$6:$Y$505,0)),"") | J15: =IFERROR(INDEX(BB816判定!$N$6:$N$505,MATCH(LARGE(BB816判定!$Y$6:$Y$505,$A15),BB816判定!$Y$6:$Y$505,0)),"") | K15: =IFERROR(INDEX(BB816判定!$O$6:$O$505,MATCH(LARGE(BB816判定!$Y$6:$Y$505,$A15),BB816判定!$Y$6:$Y$505,0)),"") | L15: =IFERROR(INDEX(BB816判定!$P$6:$P$505,MATCH(LARGE(BB816判定!$Y$6:$Y$505,$A15),BB816判定!$Y$6:$Y$505,0)),"") | M15: =IFERROR(INDEX(BB816判定!$V$6:$V$505,MATCH(LARGE(BB816判定!$Y$6:$Y$505,$A15),BB816判定!$Y$6:$Y$505,0)),"") | N15: =IFERROR(INDEX(BB816判定!$W$6:$W$505,MATCH(LARGE(BB816判定!$Y$6:$Y$505,$A15),BB816判定!$Y$6:$Y$505,0)),"") | O15: =IFERROR(INDEX(BB816判定!$Z$6:$Z$505,MATCH(LARGE(BB816判定!$Y$6:$Y$505,$A15),BB816判定!$Y$6:$Y$505,0)),"") | P15: =IFERROR(INDEX(BB816判定!$AA$6:$AA$505,MATCH(LARGE(BB816判定!$Y$6:$Y$505,$A15),BB816判定!$Y$6:$Y$505,0)),"") | Q15: =IF($B15="","",HYPERLINK("https://kabutan.jp/stock/?code="&$B15,"📈"))
A16: 12 | B16: =IFERROR(INDEX(BB816判定!$B$6:$B$505,MATCH(LARGE(BB816判定!$Y$6:$Y$505,$A16),BB816判定!$Y$6:$Y$505,0)),"") | C16: =IFERROR(INDEX(BB816判定!$C$6:$C$505,MATCH(LARGE(BB816判定!$Y$6:$Y$505,$A16),BB816判定!$Y$6:$Y$505,0)),"") | D16: =IFERROR(INDEX(BB816判定!$D$6:$D$505,MATCH(LARGE(BB816判定!$Y$6:$Y$505,$A16),BB816判定!$Y$6:$Y$505,0)),"") | E16: =IFERROR(INDEX(BB816判定!$Q$6:$Q$505,MATCH(LARGE(BB816判定!$Y$6:$Y$505,$A16),BB816判定!$Y$6:$Y$505,0)),"") | F16: =IFERROR(INDEX(BB816判定!$S$6:$S$505,MATCH(LARGE(BB816判定!$Y$6:$Y$505,$A16),BB816判定!$Y$6:$Y$505,0)),"") | G16: =IFERROR(INDEX(BB816判定!$T$6:$T$505,MATCH(LARGE(BB816判定!$Y$6:$Y$505,$A16),BB816判定!$Y$6:$Y$505,0)),"") | H16: =IFERROR(INDEX(BB816判定!$U$6:$U$505,MATCH(LARGE(BB816判定!$Y$6:$Y$505,$A16),BB816判定!$Y$6:$Y$505,0)),"") | I16: =IFERROR(INDEX(BB816判定!$M$6:$M$505,MATCH(LARGE(BB816判定!$Y$6:$Y$505,$A16),BB816判定!$Y$6:$Y$505,0)),"") | J16: =IFERROR(INDEX(BB816判定!$N$6:$N$505,MATCH(LARGE(BB816判定!$Y$6:$Y$505,$A16),BB816判定!$Y$6:$Y$505,0)),"") | K16: =IFERROR(INDEX(BB816判定!$O$6:$O$505,MATCH(LARGE(BB816判定!$Y$6:$Y$505,$A16),BB816判定!$Y$6:$Y$505,0)),"") | L16: =IFERROR(INDEX(BB816判定!$P$6:$P$505,MATCH(LARGE(BB816判定!$Y$6:$Y$505,$A16),BB816判定!$Y$6:$Y$505,0)),"") | M16: =IFERROR(INDEX(BB816判定!$V$6:$V$505,MATCH(LARGE(BB816判定!$Y$6:$Y$505,$A16),BB816判定!$Y$6:$Y$505,0)),"") | N16: =IFERROR(INDEX(BB816判定!$W$6:$W$505,MATCH(LARGE(BB816判定!$Y$6:$Y$505,$A16),BB816判定!$Y$6:$Y$505,0)),"") | O16: =IFERROR(INDEX(BB816判定!$Z$6:$Z$505,MATCH(LARGE(BB816判定!$Y$6:$Y$505,$A16),BB816判定!$Y$6:$Y$505,0)),"") | P16: =IFERROR(INDEX(BB816判定!$AA$6:$AA$505,MATCH(LARGE(BB816判定!$Y$6:$Y$505,$A16),BB816判定!$Y$6:$Y$505,0)),"") | Q16: =IF($B16="","",HYPERLINK("https://kabutan.jp/stock/?code="&$B16,"📈"))
A17: 13 | B17: =IFERROR(INDEX(BB816判定!$B$6:$B$505,MATCH(LARGE(BB816判定!$Y$6:$Y$505,$A17),BB816判定!$Y$6:$Y$505,0)),"") | C17: =IFERROR(INDEX(BB816判定!$C$6:$C$505,MATCH(LARGE(BB816判定!$Y$6:$Y$505,$A17),BB816判定!$Y$6:$Y$505,0)),"") | D17: =IFERROR(INDEX(BB816判定!$D$6:$D$505,MATCH(LARGE(BB816判定!$Y$6:$Y$505,$A17),BB816判定!$Y$6:$Y$505,0)),"") | E17: =IFERROR(INDEX(BB816判定!$Q$6:$Q$505,MATCH(LARGE(BB816判定!$Y$6:$Y$505,$A17),BB816判定!$Y$6:$Y$505,0)),"") | F17: =IFERROR(INDEX(BB816判定!$S$6:$S$505,MATCH(LARGE(BB816判定!$Y$6:$Y$505,$A17),BB816判定!$Y$6:$Y$505,0)),"") | G17: =IFERROR(INDEX(BB816判定!$T$6:$T$505,MATCH(LARGE(BB816判定!$Y$6:$Y$505,$A17),BB816判定!$Y$6:$Y$505,0)),"") | H17: =IFERROR(INDEX(BB816判定!$U$6:$U$505,MATCH(LARGE(BB816判定!$Y$6:$Y$505,$A17),BB816判定!$Y$6:$Y$505,0)),"") | I17: =IFERROR(INDEX(BB816判定!$M$6:$M$505,MATCH(LARGE(BB816判定!$Y$6:$Y$505,$A17),BB816判定!$Y$6:$Y$505,0)),"") | J17: =IFERROR(INDEX(BB816判定!$N$6:$N$505,MATCH(LARGE(BB816判定!$Y$6:$Y$505,$A17),BB816判定!$Y$6:$Y$505,0)),"") | K17: =IFERROR(INDEX(BB816判定!$O$6:$O$505,MATCH(LARGE(BB816判定!$Y$6:$Y$505,$A17),BB816判定!$Y$6:$Y$505,0)),"") | L17: =IFERROR(INDEX(BB816判定!$P$6:$P$505,MATCH(LARGE(BB816判定!$Y$6:$Y$505,$A17),BB816判定!$Y$6:$Y$505,0)),"") | M17: =IFERROR(INDEX(BB816判定!$V$6:$V$505,MATCH(LARGE(BB816判定!$Y$6:$Y$505,$A17),BB816判定!$Y$6:$Y$505,0)),"") | N17: =IFERROR(INDEX(BB816判定!$W$6:$W$505,MATCH(LARGE(BB816判定!$Y$6:$Y$505,$A17),BB816判定!$Y$6:$Y$505,0)),"") | O17: =IFERROR(INDEX(BB816判定!$Z$6:$Z$505,MATCH(LARGE(BB816判定!$Y$6:$Y$505,$A17),BB816判定!$Y$6:$Y$505,0)),"") | P17: =IFERROR(INDEX(BB816判定!$AA$6:$AA$505,MATCH(LARGE(BB816判定!$Y$6:$Y$505,$A17),BB816判定!$Y$6:$Y$505,0)),"") | Q17: =IF($B17="","",HYPERLINK("https://kabutan.jp/stock/?code="&$B17,"📈"))
A18: 14 | B18: =IFERROR(INDEX(BB816判定!$B$6:$B$505,MATCH(LARGE(BB816判定!$Y$6:$Y$505,$A18),BB816判定!$Y$6:$Y$505,0)),"") | C18: =IFERROR(INDEX(BB816判定!$C$6:$C$505,MATCH(LARGE(BB816判定!$Y$6:$Y$505,$A18),BB816判定!$Y$6:$Y$505,0)),"") | D18: =IFERROR(INDEX(BB816判定!$D$6:$D$505,MATCH(LARGE(BB816判定!$Y$6:$Y$505,$A18),BB816判定!$Y$6:$Y$505,0)),"") | E18: =IFERROR(INDEX(BB816判定!$Q$6:$Q$505,MATCH(LARGE(BB816判定!$Y$6:$Y$505,$A18),BB816判定!$Y$6:$Y$505,0)),"") | F18: =IFERROR(INDEX(BB816判定!$S$6:$S$505,MATCH(LARGE(BB816判定!$Y$6:$Y$505,$A18),BB816判定!$Y$6:$Y$505,0)),"") | G18: =IFERROR(INDEX(BB816判定!$T$6:$T$505,MATCH(LARGE(BB816判定!$Y$6:$Y$505,$A18),BB816判定!$Y$6:$Y$505,0)),"") | H18: =IFERROR(INDEX(BB816判定!$U$6:$U$505,MATCH(LARGE(BB816判定!$Y$6:$Y$505,$A18),BB816判定!$Y$6:$Y$505,0)),"") | I18: =IFERROR(INDEX(BB816判定!$M$6:$M$505,MATCH(LARGE(BB816判定!$Y$6:$Y$505,$A18),BB816判定!$Y$6:$Y$505,0)),"") | J18: =IFERROR(INDEX(BB816判定!$N$6:$N$505,MATCH(LARGE(BB816判定!$Y$6:$Y$505,$A18),BB816判定!$Y$6:$Y$505,0)),"") | K18: =IFERROR(INDEX(BB816判定!$O$6:$O$505,MATCH(LARGE(BB816判定!$Y$6:$Y$505,$A18),BB816判定!$Y$6:$Y$505,0)),"") | L18: =IFERROR(INDEX(BB816判定!$P$6:$P$505,MATCH(LARGE(BB816判定!$Y$6:$Y$505,$A18),BB816判定!$Y$6:$Y$505,0)),"") | M18: =IFERROR(INDEX(BB816判定!$V$6:$V$505,MATCH(LARGE(BB816判定!$Y$6:$Y$505,$A18),BB816判定!$Y$6:$Y$505,0)),"") | N18: =IFERROR(INDEX(BB816判定!$W$6:$W$505,MATCH(LARGE(BB816判定!$Y$6:$Y$505,$A18),BB816判定!$Y$6:$Y$505,0)),"") | O18: =IFERROR(INDEX(BB816判定!$Z$6:$Z$505,MATCH(LARGE(BB816判定!$Y$6:$Y$505,$A18),BB816判定!$Y$6:$Y$505,0)),"") | P18: =IFERROR(INDEX(BB816判定!$AA$6:$AA$505,MATCH(LARGE(BB816判定!$Y$6:$Y$505,$A18),BB816判定!$Y$6:$Y$505,0)),"") | Q18: =IF($B18="","",HYPERLINK("https://kabutan.jp/stock/?code="&$B18,"📈"))
A19: 15 | B19: =IFERROR(INDEX(BB816判定!$B$6:$B$505,MATCH(LARGE(BB816判定!$Y$6:$Y$505,$A19),BB816判定!$Y$6:$Y$505,0)),"") | C19: =IFERROR(INDEX(BB816判定!$C$6:$C$505,MATCH(LARGE(BB816判定!$Y$6:$Y$505,$A19),BB816判定!$Y$6:$Y$505,0)),"") | D19: =IFERROR(INDEX(BB816判定!$D$6:$D$505,MATCH(LARGE(BB816判定!$Y$6:$Y$505,$A19),BB816判定!$Y$6:$Y$505,0)),"") | E19: =IFERROR(INDEX(BB816判定!$Q$6:$Q$505,MATCH(LARGE(BB816判定!$Y$6:$Y$505,$A19),BB816判定!$Y$6:$Y$505,0)),"") | F19: =IFERROR(INDEX(BB816判定!$S$6:$S$505,MATCH(LARGE(BB816判定!$Y$6:$Y$505,$A19),BB816判定!$Y$6:$Y$505,0)),"") | G19: =IFERROR(INDEX(BB816判定!$T$6:$T$505,MATCH(LARGE(BB816判定!$Y$6:$Y$505,$A19),BB816判定!$Y$6:$Y$505,0)),"") | H19: =IFERROR(INDEX(BB816判定!$U$6:$U$505,MATCH(LARGE(BB816判定!$Y$6:$Y$505,$A19),BB816判定!$Y$6:$Y$505,0)),"") | I19: =IFERROR(INDEX(BB816判定!$M$6:$M$505,MATCH(LARGE(BB816判定!$Y$6:$Y$505,$A19),BB816判定!$Y$6:$Y$505,0)),"") | J19: =IFERROR(INDEX(BB816判定!$N$6:$N$505,MATCH(LARGE(BB816判定!$Y$6:$Y$505,$A19),BB816判定!$Y$6:$Y$505,0)),"") | K19: =IFERROR(INDEX(BB816判定!$O$6:$O$505,MATCH(LARGE(BB816判定!$Y$6:$Y$505,$A19),BB816判定!$Y$6:$Y$505,0)),"") | L19: =IFERROR(INDEX(BB816判定!$P$6:$P$505,MATCH(LARGE(BB816判定!$Y$6:$Y$505,$A19),BB816判定!$Y$6:$Y$505,0)),"") | M19: =IFERROR(INDEX(BB816判定!$V$6:$V$505,MATCH(LARGE(BB816判定!$Y$6:$Y$505,$A19),BB816判定!$Y$6:$Y$505,0)),"") | N19: =IFERROR(INDEX(BB816判定!$W$6:$W$505,MATCH(LARGE(BB816判定!$Y$6:$Y$505,$A19),BB816判定!$Y$6:$Y$505,0)),"") | O19: =IFERROR(INDEX(BB816判定!$Z$6:$Z$505,MATCH(LARGE(BB816判定!$Y$6:$Y$505,$A19),BB816判定!$Y$6:$Y$505,0)),"") | P19: =IFERROR(INDEX(BB816判定!$AA$6:$AA$505,MATCH(LARGE(BB816判定!$Y$6:$Y$505,$A19),BB816判定!$Y$6:$Y$505,0)),"") | Q19: =IF($B19="","",HYPERLINK("https://kabutan.jp/stock/?code="&$B19,"📈"))
A21: ■ 発注の手順
A22: 1. 「総合判定」が ◎買い の銘柄を上から選ぶ。ただし
A23: ・空いている枠の数だけ（枠が埋まっていればその日は買わない）
A24: ・1日に建てるのは最大3件まで（枠が3〜4しかないときは1件まで）
A25: ・「資金枠に収まるか」が × の銘柄は飛ばして、次の候補を見る
A26: 2. 翌営業日の寄付（始値）で買う。指値にせず寄成でよい。
A27: 3. 買えたら、その場で損切り価格（N列）に逆指値を置く。
A28: 4. 10営業日たったら、損益に関わらず引けで手仕舞う。
A29: 5. 利確目標は置かない。含み益が伸びても途中で降りない（検証では利確を置くと期待値が6割落ちた）。
A31: ■ 1日に何件買うことになるのか
A32: 実測では250営業日で248件、つまり1日あたり平均1.0件でした。
A33: 0件の日が39.6%、1件が30.0%、2件が22.0%、3件buyできた日は8.4%（21日）だけです。
... A40: 2人とも「買い可」なら、条件としては最も堅い候補になる。

Sheet BB816判定
A1: 📊 BB816 判定 ― ボリンジャーバンド＋出来高による順張りスイング
A2: 終値シートの最新終値で自動計算。発注に使うのは「BB816候補」シート。ここは全銘柄の内訳を確認する場所です。
A3: 総合判定 ◎買い＝翌営業日の寄付で買う / ○監視＝条件待ち / ▲弱い＝買わない。守り分析官・攻め分析官の欄は、2人の分析官それぞれの基準での可否です。
A5: 🔗 | B5: コード | C5: 銘柄名 | D5: 現在値 | E5: SMA20 ミドル | F5: σ | G5: +2σ | H5: +1σ | I5: -1σ | J5: -2σ | K5: %B | L5: 帯幅% | M5: RSI14 | N5: MFI14 | O5: 出来高 倍率 | P5: 20日 騰落率 | Q5: BB816 スコア | R5: 買い条件 | S5: 総合判定 | T5: 守り分析官 | U5: 攻め分析官 | V5: エントリー 目安 | W5: 損切り 価格 | X5: 総資金への 最大損失% | Y5: sortkey
A6: =IF(終値!A6="","",HYPERLINK("https://kabutan.jp/stock/?code="&終値!A6,"📈")) | B6: =IF(終値!A6="","",終値!A6) | C6: =IF(終値!A6="","",終値!B6) | D6: =IF(終値!A6="","",終値!E6) | E6: =IF($D6="","",AVERAGE(終値!E6:X6)) | F6: =IF($D6="","",STDEVP(終値!E6:X6)) | G6: =IF($D6="","",$E6+BB816設定!$B$4*$F6) | H6: =IF($D6="","",$E6+BB816設定!$B$5*$F6) | I6: =IF($D6="","",$E6-BB816設定!$B$5*$F6) | J6: =IF($D6="","",$E6-BB816設定!$B$4*$F6) | K6: =IF($D6="","",IFERROR(($D6-$J6)/($G6-$J6),"")) | L6: =IF($D6="","",IFERROR(($G6-$J6)/$E6*100,"")) | M6: =IF($D6="","",IFERROR(100-100/(1+SUMPRODUCT((終値!E6:R6>終値!F6:S6)*(終値!E6:R6-終値!F6:S6))/SUMPRODUCT((終値!E6:R6<終値!F6:S6)*(終値!F6:S6-終値!E6:R6))),100)) | N6: =IF($D6="","",IFERROR(100-100/(1+SUMPRODUCT((((高値!E6:R6+安値!E6:R6+終値!E6:R6)/3)>((高値!F6:S6+安値!F6:S6+終値!F6:S6)/3))*((高値!E6:R6+安値!E6:R6+終値!E6:R6)/3)*出来高!E6:R6)/SUMPRODUCT((((高値!E6:R6+安値!E6:R6+終値!E6:R6)/3)<((高値!F6:S6+安値!F6:S6+終値!F6:S6)/3))*((高値!E6:R6+安値!E6:R6+終値!E6:R6)/3)*出来高!E6:R6)),50)) | O6: =IF($D6="","",IFERROR(出来高!E6/AVERAGE(出来高!E6:I6),"")) | P6: =IF($D6="","",IFERROR($D6/終値!Y6-1,"")) | Q6: =IF($D6="","",MAX(0,MIN(100,IF($D6>$G6,25,IF($D6>$H6,15,IF($D6>$E6,5,0)))+IF($O6>=2,20,IF($O6>=1.5,14,IF($O6>=1.2,8,0)))+IF($N6>=80,15,IF($N6>=60,18,IF($N6>=50,8,0)))+IF(AND($M6>70,$M6<=80),18,IF(AND($M6>60,$M6<=70),14,IF(AND($M6>50,$M6<=60),6,0)))+IF($P6>=0.1,14,IF($P6>=0.03,7,0))+IF($M6>80,-12,0)+IF($M6<40,-20,0)+IF($N6<40,-15,0)+IF($K6<0.2,-18,0)+IF($P6<=-0.1,-10,0)))) | R6: =IF($D6="","",IF(AND($D6>$G6,$O6>=BB816設定!$B$6,$N6>=BB816設定!$B$7,$M6<=BB816設定!$B$8),"○","－")) | S6: =IF($D6="","",IF(AND($R6="○",$Q6>=BB816設定!$B$9),"◎買い",IF($Q6>=BB816設定!$B$10,"○監視",IF(OR($M6<40,$K6<0.2),"▲弱い","－")))) | T6: =IF($D6="","",IF(AND($D6>$G6,$O6>=BB816設定!$B$14,$N6>=BB816設定!$B$15,$M6<=BB816設定!$B$16),"買い可","見送り")) | U6: =IF($D6="","",IF(AND($D6>$H6,$M6>=BB816設定!$B$17,$N6>=BB816設定!$B$18,$O6>=BB816設定!$B$19),"買い可","見送り")) | V6: =IF($S6="◎買い",$D6,"") | W6: =IF($S6="◎買い",ROUND($D6*(1-BB816設定!$B$11/100),1),"") | X6: =IF($S6="◎買い",BB816設定!$B$11/BB816設定!$B$13,"") | Y6: =IF($D6="","",$Q6+(10000-ROW())/100000) | Z6: =IF($D6="","",$D6*BB816設定!$B$21) | AA6: =IF($D6="","",IF($Z6<=BB816設定!$B$20/BB816設定!$B$13,"○","×（1枠に入らない）"))
A7: =IF(終値!A7="","",HYPERLINK("https://kabutan.jp/stock/?code="&終値!A7,"📈")) | B7: =IF(終値!A7="","",終値!A7) | C7: =IF(終値!A7="","",終値!B7) | D7: =IF(終値!A7="","",終値!E7) | E7: =IF($D7="","",AVERAGE(終値!E7:X7)) | F7: =IF($D7="","",STDEVP(終値!E7:X7)) | G7: =IF($D7="","",$E7+BB816設定!$B$4*$F7) | H7: =IF($D7="","",$E7+BB816設定!$B$5*$F7) | I7: =IF($D7="","",$E7-BB816設定!$B$5*$F7) | J7: =IF($D7="","",$E7-BB816設定!$B$4*$F7) | K7: =IF($D7="","",IFERROR(($D7-$J7)/($G7-$J7),"")) | L7: =IF($D7="","",IFERROR(($G7-$J7)/$E7*100,"")) | M7: =IF($D7="","",IFERROR(100-100/(1+SUMPRODUCT((終値!E7:R7>終値!F7:S7)*(終値!E7:R7-終値!F7:S7))/SUMPRODUCT((終値!E7:R7<終値!F7:S7)*(終値!F7:S7-終値!E7:R7))),100)) | N7: =IF($D7="","",IFERROR(100-100/(1+SUMPRODUCT((((高値!E7:R7+安値!E7:R7+終値!E7:R7)/3)>((高値!F7:S7+安値!F7:S7+終値!F7:S7)/3))*((高値!E7:R7+安値!E7:R7+終値!E7:R7)/3)*出来高!E7:R7)/SUMPRODUCT((((高値!E7:R7+安値!E7:R7+終値!E7:R7)/3)<((高値!F7:S7+安値!F7:S7+終値!F7:S7)/3))*((高値!E7:R7+安値!E7:R7+終値!E7:R7)/3)*出来高!E7:R7)),50)) | O7: =IF($D7="","",IFERROR(出来高!E7/AVERAGE(出来高!E7:I7),"")) | P7: =IF($D7="","",IFERROR($D7/終値!Y7-1,"")) | Q7: =IF($D7="","",MAX(0,MIN(100,IF($D7>$G7,25,IF($D7>$H7,15,IF($D7>$E7,5,0)))+IF($O7>=2,20,IF($O7>=1.5,14,IF($O7>=1.2,8,0)))+IF($N7>=80,15,IF($N7>=60,18,IF($N7>=50,8,0)))+IF(AND($M7>70,$M7<=80),18,IF(AND($M7>60,$M7<=70),14,IF(AND($M7>50,$M7<=60),6,0)))+IF($P7>=0.1,14,IF($P7>=0.03,7,0))+IF($M7>80,-12,0)+IF($M7<40,-20,0)+IF($N7<40,-15,0)+IF($K7<0.2,-18,0)+IF($P7<=-0.1,-10,0)))) | R7: =IF($D7="","",IF(AND($D7>$G7,$O7>=BB816設定!$B$6,$N7>=BB816設定!$B$7,$M7<=BB816設定!$B$8),"○","－")) | S7: =IF($D7="","",IF(AND($R7="○",$Q7>=BB816設定!$B$9),"◎買い",IF($Q7>=BB816設定!$B$10,"○監視",IF(OR($M7<40,$K7<0.2),"▲弱い","－")))) | T7: =IF($D7="","",IF(AND($D7>$G7,$O7>=BB816設定!$B$14,$N7>=BB816設定!$B$15,$M7<=BB816設定!$B$16),"買い可","見送り")) | U7: =IF($D7="","",IF(AND($D7>$H7,$M7>=BB816設定!$B$17,$N7>=BB816設定!$B$18,$O7>=BB816設定!$B$19),"買い可","見送り")) | V7: =IF($S7="◎買い",$D7,"") | W7: =IF($S7="◎買い",ROUND($D7*(1-BB816設定!$B$11/100),1),"") | X7: =IF($S7="◎買い",BB816設定!$B$11/BB816設定!$B$13,"") | Y7: =IF($D7="","",$Q7+(10000-ROW())/100000) | Z7: =IF($D7="","",$D7*BB816設定!$B$21) | AA7: =IF($D7="","",IF($Z7<=BB816設定!$B$20/BB816設定!$B$13,"○","×（1枠に入らない）"))
A8: =IF(終値!A8="","",HYPERLINK("https://kabutan.jp/stock/?code="&終値!A8,"📈")) | B8: =IF(終値!A8="","",終値!A8) | C8: =IF(終値!A8="","",終値!B8) | D8: =IF(終値!A8="","",終値!E8) | E8: =IF($D8="","",AVERAGE(終値!E8:X8)) | F8: =IF($D8="","",STDEVP(終値!E8:X8)) | G8: =IF($D8="","",$E8+BB816設定!$B$4*$F8) | H8: =IF($D8="","",$E8+BB816設定!$B$5*$F8) | I8: =IF($D8="","",$E8-BB816設定!$B$5*$F8) | J8: =IF($D8="","",$E8-BB816設定!$B$4*$F8) | K8: =IF($D8="","",IFERROR(($D8-$J8)/($G8-$J8),"")) | L8: =IF($D8="","",IFERROR(($G8-$J8)/$E8*100,"")) | M8: =IF($D8="","",IFERROR(100-100/(1+SUMPRODUCT((終値!E8:R8>終値!F8:S8)*(終値!E8:R8-終値!F8:S8))/SUMPRODUCT((終値!E8:R8<終値!F8:S8)*(終値!F8:S8-終値!E8:R8))),100)) | N8: =IF($D8="","",IFERROR(100-100/(1+SUMPRODUCT((((高値!E8:R8+安値!E8:R8+終値!E8:R8)/3)>((高値!F8:S8+安値!F8:S8+終値!F8:S8)/3))*((高値!E8:R8+安値!E8:R8+終値!E8:R8)/3)*出来高!E8:R8)/SUMPRODUCT((((高値!E8:R8+安値!E8:R8+終値!E8:R8)/3)<((高値!F8:S8+安値!F8:S8+終値!F8:S8)/3))*((高値!E8:R8+安値!E8:R8+終値!E8:R8)/3)*出来高!E8:R8)),50)) | O8: =IF($D8="","",IFERROR(出来高!E8/AVERAGE(出来高!E8:I8),"")) | P8: =IF($D8="","",IFERROR($D8/終値!Y8-1,"")) | Q8: =IF($D8="","",MAX(0,MIN(100,IF($D8>$G8,25,IF($D8>$H8,15,IF($D8>$E8,5,0)))+IF($O8>=2,20,IF($O8>=1.5,14,IF($O8>=1.2,8,0)))+IF($N8>=80,15,IF($N8>=60,18,IF($N8>=50,8,0)))+IF(AND($M8>70,$M8<=80),18,IF(AND($M8>60,$M8<=70),14,IF(AND($M8>50,$M8<=60),6,0)))+IF($P8>=0.1,14,IF($P8>=0.03,7,0))+IF($M8>80,-12,0)+IF($M8<40,-20,0)+IF($N8<40,-15,0)+IF($K8<0.2,-18,0)+IF($P8<=-0.1,-10,0)))) | R8: =IF($D8="","",IF(AND($D8>$G8,$O8>=BB816設定!$B$6,$N8>=BB816設定!$B$7,$M8<=BB816設定!$B$8),"○","－")) | S8: =IF($D8="","",IF(AND($R8="○",$Q8>=BB816設定!$B$9),"◎買い",IF($Q8>=BB816設定!$B$10,"○監視",IF(OR($M8<40,$K8<0.2),"▲弱い","－")))) | T8: =IF($D8="","",IF(AND($D8>$G8,$O8>=BB816設定!$B$14,$N8>=BB816設定!$B$15,$M8<=BB816設定!$B$16),"買い可","見送り")) | U8: =IF($D8="","",IF(AND($D8>$H8,$M8>=BB816設定!$B$17,$N8>=BB816設定!$B$18,$O8>=BB816設定!$B$19),"買い可","見送り")) | V8: =IF($S8="◎買い",$D8,"") | W8: =IF($S8="◎買い",ROUND($D8*(1-BB816設定!$B$11/100),1),"") | X8: =IF($S8="◎買い",BB816設定!$B$11/BB816設定!$B$13,"") | Y8: =IF($D8="","",$Q8+(10000-ROW())/100000) | Z8: =IF($D8="","",$D8*BB816設定!$B$21) | AA8: =IF($D8="","",IF($Z8<=BB816設定!$B$20/BB816設定!$B$13,"○","×（1枠に入らない）"))
A9: =IF(終値!A9="","",HYPERLINK("https://kabutan.jp/stock/?code="&終値!A9,"📈")) | B9: =IF(終値!A9="","",終値!A9) | C9: =IF(終値!A9="","",終値!B9) | D9: =IF(終値!A9="","",終値!E9) | E9: =IF($D9="","",AVERAGE(終値!E9:X9)) | F9: =IF($D9="","",STDEVP(終値!E9:X9)) | G9: =IF($D9="","",$E9+BB816設定!$B$4*$F9) | H9: =IF($D9="","",$E9+BB816設定!$B$5*$F9) | I9: =IF($D9="","",$E9-BB816設定!$B$5*$F9) | J9: =IF($D9="","",$E9-BB816設定!$B$4*$F9) | K9: =IF($D9="","",IFERROR(($D9-$J9)/($G9-$J9),"")) | L9: =IF($D9="","",IFERROR(($G9-$J9)/$E9*100,"")) | M9: =IF($D9="","",IFERROR(100-100/(1+SUMPRODUCT((終値!E9:R9>終値!F9:S9)*(終値!E9:R9-終値!F9:S9))/SUMPRODUCT((終値!E9:R9<終値!F9:S9)*(終値!F9:S9-終値!E9:R9))),100)) | N9: =IF($D9="","",IFERROR(100-100/(1+SUMPRODUCT((((高値!E9:R9+安値!E9:R9+終値!E9:R9)/3)>((高値!F9:S9+安値!F9:S9+終値!F9:S9)/3))*((高値!E9:R9+安値!E9:R9+終値!E9:R9)/3)*出来高!E9:R9)/SUMPRODUCT((((高値!E9:R9+安値!E9:R9+終値!E9:R9)/3)<((高値!F9:S9+安値!F9:S9+終値!F9:S9)/3))*((高値!E9:R9+安値!E9:R9+終値!E9:R9)/3)*出来高!E9:R9)),50)) | O9: =IF($D9="","",IFERROR(出来高!E9/AVERAGE(出来高!E9:I9),"")) | P9: =IF($D9="","",IFERROR($D9/終値!Y9-1,"")) | Q9: =IF($D9="","",MAX(0,MIN(100,IF($D9>$G9,25,IF($D9>$H9,15,IF($D9>$E9,5,0)))+IF($O9>=2,20,IF($O9>=1.5,14,IF($O9>=1.2,8,0)))+IF($N9>=80,15,IF($N9>=60,18,IF($N9>=50,8,0)))+IF(AND($M9>70,$M9<=80),18,IF(AND($M9>60,$M9<=70),14,IF(AND($M9>50,$M9<=60),6,0)))+IF($P9>=0.1,14,IF($P9>=0.03,7,0))+IF($M9>80,-12,0)+IF($M9<40,-20,0)+IF($N9<40,-15,0)+IF($K9<0.2,-18,0)+IF($P9<=-0.1,-10,0)))) | R9: =IF($D9="","",IF(AND($D9>$G9,$O9>=BB816設定!$B$6,$N9>=BB816設定!$B$7,$M9<=BB816設定!$B$8),"○","－")) | S9: =IF($D9="","",IF(AND($R9="○",$Q9>=BB816設定!$B$9),"◎買い",IF($Q9>=BB816設定!$B$10,"○監視",IF(OR($M9<40,$K9<0.2),"▲弱い","－")))) | T9: =IF($D9="","",IF(AND($D9>$G9,$O9>=BB816設定!$B$14,$N9>=BB816設定!$B$15,$M9<=BB816設定!$B$16),"買い可","見送り")) | U9: =IF($D9="","",IF(AND($D9>$H9,$M9>=BB816設定!$B$17,$N9>=BB816設定!$B$18,$O9>=BB816設定!$B$19),"買い可","見送り")) | V9: =IF($S9="◎買い",$D9,"") | W9: =IF($S9="◎買い",ROUND($D9*(1-BB816設定!$B$11/100),1),"") | X9: =IF($S9="◎買い",BB816設定!$B$11/BB816設定!$B$13,"") | Y9: =IF($D9="","",$Q9+(10000-ROW())/100000) | Z9: =IF($D9="","",$D9*BB816設定!$B$21) | AA9: =IF($D9="","",IF($Z9<=BB816設定!$B$20/BB816設定!$B$13,"○","×（1枠に入らない）"))
A10: =IF(終値!A10="","",HYPERLINK("https://kabutan.jp/stock/?code="&終値!A10,"📈")) | B10: =IF(終値!A10="","",終値!A10) | C10: =IF(終値!A10="","",終値!B10) | D10: =IF(終値!A10="","",終値!E10) | E10: =IF($D10="","",AVERAGE(終値!E10:X10)) | F10: =IF($D10="","",STDEVP(終値!E10:X10)) | G10: =IF($D10="","",$E10+BB816設定!$B$4*$F10) | H10: =IF($D10="","",$E10+BB816設定!$B$5*$F10) | I10: =IF($D10="","",$E10-BB816設定!$B$5*$F10) | J10: =IF($D10="","",$E10-BB816設定!$B$4*$F10) | K10: =IF($D10="","",IFERROR(($D10-$J10)/($G10-$J10),"")) | L10: =IF($D10="","",IFERROR(($G10-$J10)/$E10*100,"")) | M10: =IF($D10="","",IFERROR(100-100/(1+SUMPRODUCT((終値!E10:R10>終値!F10:S10)*(終値!E10:R10-終値!F10:S10))/SUMPRODUCT((終値!E10:R10<終値!F10:S10)*(終値!F10:S10-終値!E10:R10))),100)) | N10: =IF($D10="","",IFERROR(100-100/(1+SUMPRODUCT((((高値!E10:R10+安値!E10:R10+終値!E10:R10)/3)>((高値!F10:S10+安値!F10:S10+終値!F10:S10)/3))*((高値!E10:R10+安値!E10:R10+終値!E10:R10)/3)*出来高!E10:R10)/SUMPRODUCT((((高値!E10:R10+安値!E10:R10+終値!E10:R10)/3)<((高値!F10:S10+安値!F10:S10+終値!F10:S10)/3))*((高値!E10:R10+安値!E10:R10+終値!E10:R10)/3)*出来高!E10:R10)),50)) | O10: =IF($D10="","",IFERROR(出来高!E10/AVERAGE(出来高!E10:I10),"")) | P10: =IF($D10="","",IFERROR($D10/終値!Y10-1,"")) | Q10: =IF($D10="","",MAX(0,MIN(100,IF($D10>$G10,25,IF($D10>$H10,15,IF($D10>$E10,5,0)))+IF($O10>=2,20,IF($O10>=1.5,14,IF($O10>=1.2,8,0)))+IF($N10>=80,15,IF($N10>=60,18,IF($N10>=50,8,0)))+IF(AND($M10>70,$M10<=80),18,IF(AND($M10>60,$M10<=70),14,IF(AND($M10>50,$M10<=60),6,0)))+IF($P10>=0.1,14,IF($P10>=0.03,7,0))+IF($M10>80,-12,0)+IF($M10<40,-20,0)+IF($N10<40,-15,0)+IF($K10<0.2,-18,0)+IF($P10<=-0.1,-10,0)))) | R10: =IF($D10="","",IF(AND($D10>$G10,$O10>=BB816設定!$B$6,$N10>=BB816設定!$B$7,$M10<=BB816設定!$B$8),"○","－")) | S10: =IF($D10="","",IF(AND($R10="○",$Q10>=BB816設定!$B$9),"◎買い",IF($Q10>=BB816設定!$B$10,"○監視",IF(OR($M10<40,$K10<0.2),"▲弱い","－")))) | T10: =IF($D10="","",IF(AND($D10>$G10,$O10>=BB816設定!$B$14,$N10>=BB816設定!$B$15,$M10<=BB816設定!$B$16),"買い可","見送り")) | U10: =IF($D10="","",IF(AND($D10>$H10,$M10>=BB816設定!$B$17,$N10>=BB816設定!$B$18,$O10>=BB816設定!$B$19),"買い可","見送り")) | V10: =IF($S10="◎買い",$D10,"") | W10: =IF($S10="◎買い",ROUND($D10*(1-BB816設定!$B$11/100),1),"") | X10: =IF($S10="◎買い",BB816設定!$B$11/BB816設定!$B$13,"") | Y10: =IF($D10="","",$Q10+(10000-ROW())/100000) | Z10: =IF($D10="","",$D10*BB816設定!$B$21) | AA10: =IF($D10="","",IF($Z10<=BB816設定!$B$20/BB816設定!$B$13,"○","×（1枠に入らない）"))
A11: =IF(終値!A11="","",HYPERLINK("https://kabutan.jp/stock/?code="&終値!A11,"📈")) | B11: =IF(終値!A11="","",終値!A11) | C11: =IF(終値!A11="","",終値!B11) | D11: =IF(終値!A11="","",終値!E11) | E11: =IF($D11="","",AVERAGE(終値!E11:X11)) | F11: =IF($D11="","",STDEVP(終値!E11:X11)) | G11: =IF($D11="","",$E11+BB816設定!$B$4*$F11) | H11: =IF($D11="","",$E11+BB816設定!$B$5*$F11) | I11: =IF($D11="","",$E11-BB816設定!$B$5*$F11) | J11: =IF($D11="","",$E11-BB816設定!$B$4*$F11) | K11: =IF($D11="","",IFERROR(($D11-$J11)/($G11-$J11),"")) | L11: =IF($D11="","",IFERROR(($G11-$J11)/$E11*100,"")) | M11: =IF($D11="","",IFERROR(100-100/(1+SUMPRODUCT((終値!E11:R11>終値!F11:S11)*(終値!E11:R11-終値!F11:S11))/SUMPRODUCT((終値!E11:R11<終値!F11:S11)*(終値!F11:S11-終値!E11:R11))),100)) | N11: =IF($D11="","",IFERROR(100-100/(1+SUMPRODUCT((((高値!E11:R11+安値!E11:R11+終値!E11:R11)/3)>((高値!F11:S11+安値!F11:S11+終値!F11:S11)/3))*((高値!E11:R11+安値!E11:R11+終値!E11:R11)/3)*出来高!E11:R11)/SUMPRODUCT((((高値!E11:R11+安値!E11:R11+終値!E11:R11)/3)<((高値!F11:S11+安値!F11:S11+終値!F11:S11)/3))*((高値!E11:R11+安値!E11:R11+終値!E11:R11)/3)*出来高!E11:R11)),50)) | O11: =IF($D11="","",IFERROR(出来高!E11/AVERAGE(出来高!E11:I11),"")) | P11: =IF($D11="","",IFERROR($D11/終値!Y11-1,"")) | Q11: =IF($D11="","",MAX(0,MIN(100,IF($D11>$G11,25,IF($D11>$H11,15,IF($D11>$E11,5,0)))+IF($O11>=2,20,IF($O11>=1.5,14,IF($O11>=1.2,8,0)))+IF($N11>=80,15,IF($N11>=60,18,IF($N11>=50,8,0)))+IF(AND($M11>70,$M11<=80),18,IF(AND($M11>60,$M11<=70),14,IF(AND($M11>50,$M11<=60),6,0)))+IF($P11>=0.1,14,IF($P11>=0.03,7,0))+IF($M11>80,-12,0)+IF($M11<40,-20,0)+IF($N11<40,-15,0)+IF($K11<0.2,-18,0)+IF($P11<=-0.1,-10,0)))) | R11: =IF($D11="","",IF(AND($D11>$G11,$O11>=BB816設定!$B$6,$N11>=BB816設定!$B$7,$M11<=BB816設定!$B$8),"○","－")) | S11: =IF($D11="","",IF(AND($R11="○",$Q11>=BB816設定!$B$9),"◎買い",IF($Q11>=BB816設定!$B$10,"○監視",IF(OR($M11<40,$K11<0.2),"▲弱い","－")))) | T11: =IF($D11="","",IF(AND($D11>$G11,$O11>=BB816設定!$B$14,$N11>=BB816設定!$B$15,$M11<=BB816設定!$B$16),"買い可","見送り")) | U11: =IF($D11="","",IF(AND($D11>$H11,$M11>=BB816設定!$B$17,$N11>=BB816設定!$B$18,$O11>=BB816設定!$B$19),"買い可","見送り")) | V11: =IF($S11="◎買い",$D11,"") | W11: =IF($S11="◎買い",ROUND($D11*(1-BB816設定!$B$11/100),1),"") | X11: =IF($S11="◎買い",BB816設定!$B$11/BB816設定!$B$13,"") | Y11: =IF($D11="","",$Q11+(10000-ROW())/100000) | Z11: =IF($D11="","",$D11*BB816設定!$B$21) | AA11: =IF($D11="","",IF($Z11<=BB816設定!$B$20/BB816設定!$B$13,"○","×（1枠に入らない）"))
A12: =IF(終値!A12="","",HYPERLINK("https://kabutan.jp/stock/?code="&終値!A12,"📈")) | B12: =IF(終値!A12="","",終値!A12) | C12: =IF(終値!A12="","",終値!B12) | D12: =IF(終値!A12="","",終値!E12) | E12: =IF($D12="","",AVERAGE(終値!E12:X12)) | F12: =IF($D12="","",STDEVP(終値!E12:X12)) | G12: =IF($D12="","",$E12+BB816設定!$B$4*$F12) | H12: =IF($D12="","",$E12+BB816設定!$B$5*$F12) | I12: =IF($D12="","",$E12-BB816設定!$B$5*$F12) | J12: =IF($D12="","",$E12-BB816設定!$B$4*$F12) | K12: =IF($D12="","",IFERROR(($D12-$J12)/($G12-$J12),"")) | L12: =IF($D12="","",IFERROR(($G12-$J12)/$E12*100,"")) | M12: =IF($D12="","",IFERROR(100-100/(1+SUMPRODUCT((終値!E12:R12>終値!F12:S12)*(終値!E12:R12-終値!F12:S12))/SUMPRODUCT((終値!E12:R12<終値!F12:S12)*(終値!F12:S12-終値!E12:R12))),100)) | N12: =IF($D12="","",IFERROR(100-100/(1+SUMPRODUCT((((高値!E12:R12+安値!E12:R12+終値!E12:R12)/3)>((高値!F12:S12+安値!F12:S12+終値!F12:S12)/3))*((高値!E12:R12+安値!E12:R12+終値!E12:R12)/3)*出来高!E12:R12)/SUMPRODUCT((((高値!E12:R12+安値!E12:R12+終値!E12:R12)/3)<((高値!F12:S12+安値!F12:S12+終値!F12:S12)/3))*((高値!E12:R12+安値!E12:R12+終値!E12:R12)/3)*出来高!E12:R12)),50)) | O12: =IF($D12="","",IFERROR(出来高!E12/AVERAGE(出来高!E12:I12),"")) | P12: =IF($D12="","",IFERROR($D12/終値!Y12-1,"")) | Q12: =IF($D12="","",MAX(0,MIN(100,IF($D12>$G12,25,IF($D12>$H12,15,IF($D12>$E12,5,0)))+IF($O12>=2,20,IF($O12>=1.5,14,IF($O12>=1.2,8,0)))+IF($N12>=80,15,IF($N12>=60,18,IF($N12>=50,8,0)))+IF(AND($M12>70,$M12<=80),18,IF(AND($M12>60,$M12<=70),14,IF(AND($M12>50,$M12<=60),6,0)))+IF($P12>=0.1,14,IF($P12>=0.03,7,0))+IF($M12>80,-12,0)+IF($M12<40,-20,0)+IF($N12<40,-15,0)+IF($K12<0.2,-18,0)+IF($P12<=-0.1,-10,0)))) | R12: =IF($D12="","",IF(AND($D12>$G12,$O12>=BB816設定!$B$6,$N12>=BB816設定!$B$7,$M12<=BB816設定!$B$8),"○","－")) | S12: =IF($D12="","",IF(AND($R12="○",$Q12>=BB816設定!$B$9),"◎買い",IF($Q12>=BB816設定!$B$10,"○監視",IF(OR($M12<40,$K12<0.2),"▲弱い","－")))) | T12: =IF($D12="","",IF(AND($D12>$G12,$O12>=BB816設定!$B$14,$N12>=BB816設定!$B$15,$M12<=BB816設定!$B$16),"買い可","見送り")) | U12: =IF($D12="","",IF(AND($D12>$H12,$M12>=BB816設定!$B$17,$N12>=BB816設定!$B$18,$O12>=BB816設定!$B$19),"買い可","見送り")) | V12: =IF($S12="◎買い",$D12,"") | W12: =IF($S12="◎買い",ROUND($D12*(1-BB816設定!$B$11/100),1),"") | X12: =IF($S12="◎買い",BB816設定!$B$11/BB816設定!$B$13,"") | Y12: =IF($D12="","",$Q12+(10000-ROW())/100000) | Z12: =IF($D12="","",$D12*BB816設定!$B$21) | AA12: =IF($D12="","",IF($Z12<=BB816設定!$B$20/BB816設定!$B$13,"○","×（1枠に入らない）"))
A13: =IF(終値!A13="","",HYPERLINK("https://kabutan.jp/stock/?code="&終値!A13,"📈")) | B13: =IF(終値!A13="","",終値!A13) | C13: =IF(終値!A13="","",終値!B13) | D13: =IF(終値!A13="","",終値!E13) | E13: =IF($D13="","",AVERAGE(終値!E13:X13)) | F13: =IF($D13="","",STDEVP(終値!E13:X13)) | G13: =IF($D13="","",$E13+BB816設定!$B$4*$F13) | H13: =IF($D13="","",$E13+BB816設定!$B$5*$F13) | I13: =IF($D13="","",$E13-BB816設定!$B$5*$F13) | J13: =IF($D13="","",$E13-BB816設定!$B$4*$F13) | K13: =IF($D13="","",IFERROR(($D13-$J13)/($G13-$J13),"")) | L13: =IF($D13="","",IFERROR(($G13-$J13)/$E13*100,"")) | M13: =IF($D13="","",IFERROR(100-100/(1+SUMPRODUCT((終値!E13:R13>終値!F13:S13)*(終値!E13:R13-終値!F13:S13))/SUMPRODUCT((終値!E13:R13<終値!F13:S13)*(終値!F13:S13-終値!E13:R13))),100)) | N13: =IF($D13="","",IFERROR(100-100/(1+SUMPRODUCT((((高値!E13:R13+安値!E13:R13+終値!E13:R13)/3)>((高値!F13:S13+安値!F13:S13+終値!F13:S13)/3))*((高値!E13:R13+安値!E13:R13+終値!E13:R13)/3)*出来高!E13:R13)/SUMPRODUCT((((高値!E13:R13+安値!E13:R13+終値!E13:R13)/3)<((高値!F13:S13+安値!F13:S13+終値!F13:S13)/3))*((高値!E13:R13+安値!E13:R13+終値!E13:R13)/3)*出来高!E13:R13)),50)) | O13: =IF($D13="","",IFERROR(出来高!E13/AVERAGE(出来高!E13:I13),"")) | P13: =IF($D13="","",IFERROR($D13/終値!Y13-1,"")) | Q13: =IF($D13="","",MAX(0,MIN(100,IF($D13>$G13,25,IF($D13>$H13,15,IF($D13>$E13,5,0)))+IF($O13>=2,20,IF($O13>=1.5,14,IF($O13>=1.2,8,0)))+IF($N13>=80,15,IF($N13>=60,18,IF($N13>=50,8,0)))+IF(AND($M13>70,$M13<=80),18,IF(AND($M13>60,$M13<=70),14,IF(AND($M13>50,$M13<=60),6,0)))+IF($P13>=0.1,14,IF($P13>=0.03,7,0))+IF($M13>80,-12,0)+IF($M13<40,-20,0)+IF($N13<40,-15,0)+IF($K13<0.2,-18,0)+IF($P13<=-0.1,-10,0)))) | R13: =IF($D13="","",IF(AND($D13>$G13,$O13>=BB816設定!$B$6,$N13>=BB816設定!$B$7,$M13<=BB816設定!$B$8),"○","－")) | S13: =IF($D13="","",IF(AND($R13="○",$Q13>=BB816設定!$B$9),"◎買い",IF($Q13>=BB816設定!$B$10,"○監視",IF(OR($M13<40,$K13<0.2),"▲弱い","－")))) | T13: =IF($D13="","",IF(AND($D13>$G13,$O13>=BB816設定!$B$14,$N13>=BB816設定!$B$15,$M13<=BB816設定!$B$16),"買い可","見送り")) | U13: =IF($D13="","",IF(AND($D13>$H13,$M13>=BB816設定!$B$17,$N13>=BB816設定!$B$18,$O13>=BB816設定!$B$19),"買い可","見送り")) | V13: =IF($S13="◎買い",$D13,"") | W13: =IF($S13="◎買い",ROUND($D13*(1-BB816設定!$B$11/100),1),"") | X13: =IF($S13="◎買い",BB816設定!$B$11/BB816設定!$B$13,"") | Y13: =IF($D13="","",$Q13+(10000-ROW())/100000) | Z13: =IF($D13="","",$D13*BB816設定!$B$21) | AA13: =IF($D13="","",IF($Z13<=BB816設定!$B$20/BB816設定!$B$13,"○","×（1枠に入らない）"))
A14: =IF(終値!A14="","",HYPERLINK("https://kabutan.jp/stock/?code="&終値!A14,"📈")) | B14: =IF(終値!A14="","",終値!A14) | C14: =IF(終値!A14="","",終値!B14) | D14: =IF(終値!A14="","",終値!E14) | E14: =IF($D14="","",AVERAGE(終値!E14:X14)) | F14: =IF($D14="","",STDEVP(終値!E14:X14)) | G14: =IF($D14="","",$E14+BB816設定!$B$4*$F14) | H14: =IF($D14="","",$E14+BB816設定!$B$5*$F14) | I14: =IF($D14="","",$E14-BB816設定!$B$5*$F14) | J14: =IF($D14="","",$E14-BB816設定!$B$4*$F14) | K14: =IF($D14="","",IFERROR(($D14-$J14)/($G14-$J14),"")) | L14: =IF($D14="","",IFERROR(($G14-$J14)/$E14*100,"")) | M14: =IF($D14="","",IFERROR(100-100/(1+SUMPRODUCT((終値!E14:R14>終値!F14:S14)*(終値!E14:R14-終値!F14:S14))/SUMPRODUCT((終値!E14:R14<終値!F14:S14)*(終値!F14:S14-終値!E14:R14))),100)) | N14: =IF($D14="","",IFERROR(100-100/(1+SUMPRODUCT((((高値!E14:R14+安値!E14:R14+終値!E14:R14)/3)>((高値!F14:S14+安値!F14:S14+終値!F14:S14)/3))*((高値!E14:R14+安値!E14:R14+終値!E14:R14)/3)*出来高!E14:R14)/SUMPRODUCT((((高値!E14:R14+安値!E14:R14+終値!E14:R14)/3)<((高値!F14:S14+安値!F14:S14+終値!F14:S14)/3))*((高値!E14:R14+安値!E14:R14+終値!E14:R14)/3)*出来高!E14:R14)),50)) | O14: =IF($D14="","",IFERROR(出来高!E14/AVERAGE(出来高!E14:I14),"")) | P14: =IF($D14="","",IFERROR($D14/終値!Y14-1,"")) | Q14: =IF($D14="","",MAX(0,MIN(100,IF($D14>$G14,25,IF($D14>$H14,15,IF($D14>$E14,5,0)))+IF($O14>=2,20,IF($O14>=1.5,14,IF($O14>=1.2,8,0)))+IF($N14>=80,15,IF($N14>=60,18,IF($N14>=50,8,0)))+IF(AND($M14>70,$M14<=80),18,IF(AND($M14>60,$M14<=70),14,IF(AND($M14>50,$M14<=60),6,0)))+IF($P14>=0.1,14,IF($P14>=0.03,7,0))+IF($M14>80,-12,0)+IF($M14<40,-20,0)+IF($N14<40,-15,0)+IF($K14<0.2,-18,0)+IF($P14<=-0.1,-10,0)))) | R14: =IF($D14="","",IF(AND($D14>$G14,$O14>=BB816設定!$B$6,$N14>=BB816設定!$B$7,$M14<=BB816設定!$B$8),"○","－")) | S14: =IF($D14="","",IF(AND($R14="○",$Q14>=BB816設定!$B$9),"◎買い",IF($Q14>=BB816設定!$B$10,"○監視",IF(OR($M14<40,$K14<0.2),"▲弱い","－")))) | T14: =IF($D14="","",IF(AND($D14>$G14,$O14>=BB816設定!$B$14,$N14>=BB816設定!$B$15,$M14<=BB816設定!$B$16),"買い可","見送り")) | U14: =IF($D14="","",IF(AND($D14>$H14,$M14>=BB816設定!$B$17,$N14>=BB816設定!$B$18,$O14>=BB816設定!$B$19),"買い可","見送り")) | V14: =IF($S14="◎買い",$D14,"") | W14: =IF($S14="◎買い",ROUND($D14*(1-BB816設定!$B$11/100),1),"") | X14: =IF($S14="◎買い",BB816設定!$B$11/BB816設定!$B$13,"") | Y14: =IF($D14="","",$Q14+(10000-ROW())/100000) | Z14: =IF($D14="","",$D14*BB816設定!$B$21) | AA14: =IF($D14="","",IF($Z14<=BB816設定!$B$20/BB816設定!$B$13,"○","×（1枠に入らない）"))
A15: =IF(終値!A15="","",HYPERLINK("https://kabutan.jp/stock/?code="&終値!A15,"📈")) | B15: =IF(終値!A15="","",終値!A15) | C15: =IF(終値!A15="","",終値!B15) | D15: =IF(終値!A15="","",終値!E15) | E15: =IF($D15="","",AVERAGE(終値!E15:X15)) | F15: =IF($D15="","",STDEVP(終値!E15:X15)) | G15: =IF($D15="","",$E15+BB816設定!$B$4*$F15) | H15: =IF($D15="","",$E15+BB816設定!$B$5*$F15) | I15: =IF($D15="","",$E15-BB816設定!$B$5*$F15) | J15: =IF($D15="","",$E15-BB816設定!$B$4*$F15) | K15: =IF($D15="","",IFERROR(($D15-$J15)/($G15-$J15),"")) | L15: =IF($D15="","",IFERROR(($G15-$J15)/$E15*100,"")) | M15: =IF($D15="","",IFERROR(100-100/(1+SUMPRODUCT((終値!E15:R15>終値!F15:S15)*(終値!E15:R15-終値!F15:S15))/SUMPRODUCT((終値!E15:R15<終値!F15:S15)*(終値!F15:S15-終値!E15:R15))),100)) | N15: =IF($D15="","",IFERROR(100-100/(1+SUMPRODUCT((((高値!E15:R15+安値!E15:R15+終値!E15:R15)/3)>((高値!F15:S15+安値!F15:S15+終値!F15:S15)/3))*((高値!E15:R15+安値!E15:R15+終値!E15:R15)/3)*出来高!E15:R15)/SUMPRODUCT((((高値!E15:R15+安値!E15:R15+終値!E15:R15)/3)<((高値!F15:S15+安値!F15:S15+終値!F15:S15)/3))*((高値!E15:R15+安値!E15:R15+終値!E15:R15)/3)*出来高!E15:R15)),50)) | O15: =IF($D15="","",IFERROR(出来高!E15/AVERAGE(出来高!E15:I15),"")) | P15: =IF($D15="","",IFERROR($D15/終値!Y15-1,"")) | Q15: =IF($D15="","",MAX(0,MIN(100,IF($D15>$G15,25,IF($D15>$H15,15,IF($D15>$E15,5,0)))+IF($O15>=2,20,IF($O15>=1.5,14,IF($O15>=1.2,8,0)))+IF($N15>=80,15,IF($N15>=60,18,IF($N15>=50,8,0)))+IF(AND($M15>70,$M15<=80),18,IF(AND($M15>60,$M15<=70),14,IF(AND($M15>50,$M15<=60),6,0)))+IF($P15>=0.1,14,IF($P15>=0.03,7,0))+IF($M15>80,-12,0)+IF($M15<40,-20,0)+IF($N15<40,-15,0)+IF($K15<0.2,-18,0)+IF($P15<=-0.1,-10,0)))) | R15: =IF($D15="","",IF(AND($D15>$G15,$O15>=BB816設定!$B$6,$N15>=BB816設定!$B$7,$M15<=BB816設定!$B$8),"○","－")) | S15: =IF($D15="","",IF(AND($R15="○",$Q15>=BB816設定!$B$9),"◎買い",IF($Q15>=BB816設定!$B$10,"○監視",IF(OR($M15<40,$K15<0.2),"▲弱い","－")))) | T15: =IF($D15="","",IF(AND($D15>$G15,$O15>=BB816設定!$B$14,$N15>=BB816設定!$B$15,$M15<=BB816設定!$B$16),"買い可","見送り")) | U15: =IF($D15="","",IF(AND($D15>$H15,$M15>=BB816設定!$B$17,$N15>=BB816設定!$B$18,$O15>=BB816設定!$B$19),"買い可","見送り")) | V15: =IF($S15="◎買い",$D15,"") | W15: =IF($S15="◎買い",ROUND($D15*(1-BB816設定!$B$11/100),1),"") | X15: =IF($S15="◎買い",BB816設定!$B$11/BB816設定!$B$13,"") | Y15: =IF($D15="","",$Q15+(10000-ROW())/100000) | Z15: =IF($D15="","",$D15*BB816設定!$B$21) | AA15: =IF($D15="","",IF($Z15<=BB816設定!$B$20/BB816設定!$B$13,"○","×（1枠に入らない）"))
A16: =IF(終値!A16="","",HYPERLINK("https://kabutan.jp/stock/?code="&終値!A16,"📈")) | B16: =IF(終値!A16="","",終値!A16) | C16: =IF(終値!A16="","",終値!B16) | D16: =IF(終値!A16="","",終値!E16) | E16: =IF($D16="","",AVERAGE(終値!E16:X16)) | F16: =IF($D16="","",STDEVP(終値!E16:X16)) | G16: =IF($D16="","",$E16+BB816設定!$B$4*$F16) | H16: =IF($D16="","",$E16+BB816設定!$B$5*$F16) | I16: =IF($D16="","",$E16-BB816設定!$B$5*$F16) | J16: =IF($D16="","",$E16-BB816設定!$B$4*$F16) | K16: =IF($D16="","",IFERROR(($D16-$J16)/($G16-$J16),"")) | L16: =IF($D16="","",IFERROR(($G16-$J16)/$E16*100,"")) | M16: =IF($D16="","",IFERROR(100-100/(1+SUMPRODUCT((終値!E16:R16>終値!F16:S16)*(終値!E16:R16-終値!F16:S16))/SUMPRODUCT((終値!E16:R16<終値!F16:S16)*(終値!F16:S16-終値!E16:R16))),100)) | N16: =IF($D16="","",IFERROR(100-100/(1+SUMPRODUCT((((高値!E16:R16+安値!E16:R16+終値!E16:R16)/3)>((高値!F16:S16+安値!F16:S16+終値!F16:S16)/3))*((高値!E16:R16+安値!E16:R16+終値!E16:R16)/3)*出来高!E16:R16)/SUMPRODUCT((((高値!E16:R16+安値!E16:R16+終値!E16:R16)/3)<((高値!F16:S16+安値!F16:S16+終値!F16:S16)/3))*((高値!E16:R16+安値!E16:R16+終値!E16:R16)/3)*出来高!E16:R16)),50)) | O16: =IF($D16="","",IFERROR(出来高!E16/AVERAGE(出来高!E16:I16),"")) | P16: =IF($D16="","",IFERROR($D16/終値!Y16-1,"")) | Q16: =IF($D16="","",MAX(0,MIN(100,IF($D16>$G16,25,IF($D16>$H16,15,IF($D16>$E16,5,0)))+IF($O16>=2,20,IF($O16>=1.5,14,IF($O16>=1.2,8,0)))+IF($N16>=80,15,IF($N16>=60,18,IF($N16>=50,8,0)))+IF(AND($M16>70,$M16<=80),18,IF(AND($M16>60,$M16<=70),14,IF(AND($M16>50,$M16<=60),6,0)))+IF($P16>=0.1,14,IF($P16>=0.03,7,0))+IF($M16>80,-12,0)+IF($M16<40,-20,0)+IF($N16<40,-15,0)+IF($K16<0.2,-18,0)+IF($P16<=-0.1,-10,0)))) | R16: =IF($D16="","",IF(AND($D16>$G16,$O16>=BB816設定!$B$6,$N16>=BB816設定!$B$7,$M16<=BB816設定!$B$8),"○","－")) | S16: =IF($D16="","",IF(AND($R16="○",$Q16>=BB816設定!$B$9),"◎買い",IF($Q16>=BB816設定!$B$10,"○監視",IF(OR($M16<40,$K16<0.2),"▲弱い","－")))) | T16: =IF($D16="","",IF(AND($D16>$G16,$O16>=BB816設定!$B$14,$N16>=BB816設定!$B$15,$M16<=BB816設定!$B$16),"買い可","見送り")) | U16: =IF($D16="","",IF(AND($D16>$H16,$M16>=BB816設定!$B$17,$N16>=BB816設定!$B$18,$O16>=BB816設定!$B$19),"買い可","見送り")) | V16: =IF($S16="◎買い",$D16,"") | W16: =IF($S16="◎買い",ROUND($D16*(1-BB816設定!$B$11/100),1),"") | X16: =IF($S16="◎買い",BB816設定!$B$11/BB816設定!$B$13,"") | Y16: =IF($D16="","",$Q16+(10000-ROW())/100000) | Z16: =IF($D16="","",$D16*BB816設定!$B$21) | AA16: =IF($D16="","",IF($Z16<=BB816設定!$B$20/BB816設定!$B$13,"○","×（1枠に入らない）"))
A17: =IF(終値!A17="","",HYPERLINK("https://kabutan.jp/stock/?code="&終値!A17,"📈")) | B17: =IF(終値!A17="","",終値!A17) | C17: =IF(終値!A17="","",終値!B17) | D17: =IF(終値!A17="","",終値!E17) | E17: =IF($D17="","",AVERAGE(終値!E17:X17)) | F17: =IF($D17="","",STDEVP(終値!E17:X17)) | G17: =IF($D17="","",$E17+BB816設定!$B$4*$F17) | H17: =IF($D17="","",$E17+BB816設定!$B$5*$F17) | I17: =IF($D17="","",$E17-BB816設定!$B$5*$F17) | J17: =IF($D17="","",$E17-BB816設定!$B$4*$F17) | K17: =IF($D17="","",IFERROR(($D17-$J17)/($G17-$J17),"")) | L17: =IF($D17="","",IFERROR(($G17-$J17)/$E17*100,"")) | M17: =IF($D17="","",IFERROR(100-100/(1+SUMPRODUCT((終値!E17:R17>終値!F17:S17)*(終値!E17:R17-終値!F17:S17))/SUMPRODUCT((終値!E17:R17<終値!F17:S17)*(終値!F17:S17-終値!E17:R17))),100)) | N17: =IF($D17="","",IFERROR(100-100/(1+SUMPRODUCT((((高値!E17:R17+安値!E17:R17+終値!E17:R17)/3)>((高値!F17:S17+安値!F17:S17+終値!F17:S17)/3))*((高値!E17:R17+安値!E17:R17+終値!E17:R17)/3)*出来高!E17:R17)/SUMPRODUCT((((高値!E17:R17+安値!E17:R17+終値!E17:R17)/3)<((高値!F17:S17+安値!F17:S17+終値!F17:S17)/3))*((高値!E17:R17+安値!E17:R17+終値!E17:R17)/3)*出来高!E17:R17)),50)) | O17: =IF($D17="","",IFERROR(出来高!E17/AVERAGE(出来高!E17:I17),"")) | P17: =IF($D17="","",IFERROR($D17/終値!Y17-1,"")) | Q17: =IF($D17="","",MAX(0,MIN(100,IF($D17>$G17,25,IF($D17>$H17,15,IF($D17>$E17,5,0)))+IF($O17>=2,20,IF($O17>=1.5,14,IF($O17>=1.2,8,0)))+IF($N17>=80,15,IF($N17>=60,18,IF($N17>=50,8,0)))+IF(AND($M17>70,$M17<=80),18,IF(AND($M17>60,$M17<=70),14,IF(AND($M17>50,$M17<=60),6,0)))+IF($P17>=0.1,14,IF($P17>=0.03,7,0))+IF($M17>80,-12,0)+IF($M17<40,-20,0)+IF($N17<40,-15,0)+IF($K17<0.2,-18,0)+IF($P17<=-0.1,-10,0)))) | R17: =IF($D17="","",IF(AND($D17>$G17,$O17>=BB816設定!$B$6,$N17>=BB816設定!$B$7,$M17<=BB816設定!$B$8),"○","－")) | S17: =IF($D17="","",IF(AND($R17="○",$Q17>=BB816設定!$B$9),"◎買い",IF($Q17>=BB816設定!$B$10,"○監視",IF(OR($M17<40,$K17<0.2),"▲弱い","－")))) | T17: =IF($D17="","",IF(AND($D17>$G17,$O17>=BB816設定!$B$14,$N17>=BB816設定!$B$15,$M17<=BB816設定!$B$16),"買い可","見送り")) | U17: =IF($D17="","",IF(AND($D17>$H17,$M17>=BB816設定!$B$17,$N17>=BB816設定!$B$18,$O17>=BB816設定!$B$19),"買い可","見送り")) | V17: =IF($S17="◎買い",$D17,"") | W17: =IF($S17="◎買い",ROUND($D17*(1-BB816設定!$B$11/100),1),"") | X17: =IF($S17="◎買い",BB816設定!$B$11/BB816設定!$B$13,"") | Y17: =IF($D17="","",$Q17+(10000-ROW())/100000) | Z17: =IF($D17="","",$D17*BB816設定!$B$21) | AA17: =IF($D17="","",IF($Z17<=BB816設定!$B$20/BB816設定!$B$13,"○","×（1枠に入らない）"))
A18: =IF(終値!A18="","",HYPERLINK("https://kabutan.jp/stock/?code="&終値!A18,"📈")) | B18: =IF(終値!A18="","",終値!A18) | C18: =IF(終値!A18="","",終値!B18) | D18: =IF(終値!A18="","",終値!E18) | E18: =IF($D18="","",AVERAGE(終値!E18:X18)) | F18: =IF($D18="","",STDEVP(終値!E18:X18)) | G18: =IF($D18="","",$E18+BB816設定!$B$4*$F18) | H18: =IF($D18="","",$E18+BB816設定!$B$5*$F18) | I18: =IF($D18="","",$E18-BB816設定!$B$5*$F18) | J18: =IF($D18="","",$E18-BB816設定!$B$4*$F18) | K18: =IF($D18="","",IFERROR(($D18-$J18)/($G18-$J18),"")) | L18: =IF($D18="","",IFERROR(($G18-$J18)/$E18*100,"")) | M18: =IF($D18="","",IFERROR(100-100/(1+SUMPRODUCT((終値!E18:R18>終値!F18:S18)*(終値!E18:R18-終値!F18:S18))/SUMPRODUCT((終値!E18:R18<終値!F18:S18)*(終値!F18:S18-終値!E18:R18))),100)) | N18: =IF($D18="","",IFERROR(100-100/(1+SUMPRODUCT((((高値!E18:R18+安値!E18:R18+終値!E18:R18)/3)>((高値!F18:S18+安値!F18:S18+終値!F18:S18)/3))*((高値!E18:R18+安値!E18:R18+終値!E18:R18)/3)*出来高!E18:R18)/SUMPRODUCT((((高値!E18:R18+安値!E18:R18+終値!E18:R18)/3)<((高値!F18:S18+安値!F18:S18+終値!F18:S18)/3))*((高値!E18:R18+安値!E18:R18+終値!E18:R18)/3)*出来高!E18:R18)),50)) | O18: =IF($D18="","",IFERROR(出来高!E18/AVERAGE(出来高!E18:I18),"")) | P18: =IF($D18="","",IFERROR($D18/終値!Y18-1,"")) | Q18: =IF($D18="","",MAX(0,MIN(100,IF($D18>$G18,25,IF($D18>$H18,15,IF($D18>$E18,5,0)))+IF($O18>=2,20,IF($O18>=1.5,14,IF($O18>=1.2,8,0)))+IF($N18>=80,15,IF($N18>=60,18,IF($N18>=50,8,0)))+IF(AND($M18>70,$M18<=80),18,IF(AND($M18>60,$M18<=70),14,IF(AND($M18>50,$M18<=60),6,0)))+IF($P18>=0.1,14,IF($P18>=0.03,7,0))+IF($M18>80,-12,0)+IF($M18<40,-20,0)+IF($N18<40,-15,0)+IF($K18<0.2,-18,0)+IF($P18<=-0.1,-10,0)))) | R18: =IF($D18="","",IF(AND($D18>$G18,$O18>=BB816設定!$B$6,$N18>=BB816設定!$B$7,$M18<=BB816設定!$B$8),"○","－")) | S18: =IF($D18="","",IF(AND($R18="○",$Q18>=BB816設定!$B$9),"◎買い",IF($Q18>=BB816設定!$B$10,"○監視",IF(OR($M18<40,$K18<0.2),"▲弱い","－")))) | T18: =IF($D18="","",IF(AND($D18>$G18,$O18>=BB816設定!$B$14,$N18>=BB816設定!$B$15,$M18<=BB816設定!$B$16),"買い可","見送り")) | U18: =IF($D18="","",IF(AND($D18>$H18,$M18>=BB816設定!$B$17,$N18>=BB816設定!$B$18,$O18>=BB816設定!$B$19),"買い可","見送り")) | V18: =IF($S18="◎買い",$D18,"") | W18: =IF($S18="◎買い",ROUND($D18*(1-BB816設定!$B$11/100),1),"") | X18: =IF($S18="◎買い",BB816設定!$B$11/BB816設定!$B$13,"") | Y18: =IF($D18="","",$Q18+(10000-ROW())/100000) | Z18: =IF($D18="","",$D18*BB816設定!$B$21) | AA18: =IF($D18="","",IF($Z18<=BB816設定!$B$20/BB816設定!$B$13,"○","×（1枠に入らない）"))
A19: =IF(終値!A19="","",HYPERLINK("https://kabutan.jp/stock/?code="&終値!A19,"📈")) | B19: =IF(終値!A19="","",終値!A19) | C19: =IF(終値!A19="","",終値!B19) | D19: =IF(終値!A19="","",終値!E19) | E19: =IF($D19="","",AVERAGE(終値!E19:X19)) | F19: =IF($D19="","",STDEVP(終値!E19:X19)) | G19: =IF($D19="","",$E19+BB816設定!$B$4*$F19) | H19: =IF($D19="","",$E19+BB816設定!$B$5*$F19) | I19: =IF($D19="","",$E19-BB816設定!$B$5*$F19) | J19: =IF($D19="","",$E19-BB816設定!$B$4*$F19) | K19: =IF($D19="","",IFERROR(($D19-$J19)/($G19-$J19),"")) | L19: =IF($D19="","",IFERROR(($G19-$J19)/$E19*100,"")) | M19: =IF($D19="","",IFERROR(100-100/(1+SUMPRODUCT((終値!E19:R19>終値!F19:S19)*(終値!E19:R19-終値!F19:S19))/SUMPRODUCT((終値!E19:R19<終値!F19:S19)*(終値!F19:S19-終値!E19:R19))),100)) | N19: =IF($D19="","",IFERROR(100-100/(1+SUMPRODUCT((((高値!E19:R19+安値!E19:R19+終値!E19:R19)/3)>((高値!F19:S19+安値!F19:S19+終値!F19:S19)/3))*((高値!E19:R19+安値!E19:R19+終値!E19:R19)/3)*出来高!E19:R19)/SUMPRODUCT((((高値!E19:R19+安値!E19:R19+終値!E19:R19)/3)<((高値!F19:S19+安値!F19:S19+終値!F19:S19)/3))*((高値!E19:R19+安値!E19:R19+終値!E19:R19)/3)*出来高!E19:R19)),50)) | O19: =IF($D19="","",IFERROR(出来高!E19/AVERAGE(出来高!E19:I19),"")) | P19: =IF($D19="","",IFERROR($D19/終値!Y19-1,"")) | Q19: =IF($D19="","",MAX(0,MIN(100,IF($D19>$G19,25,IF($D19>$H19,15,IF($D19>$E19,5,0)))+IF($O19>=2,20,IF($O19>=1.5,14,IF($O19>=1.2,8,0)))+IF($N19>=80,15,IF($N19>=60,18,IF($N19>=50,8,0)))+IF(AND($M19>70,$M19<=80),18,IF(AND($M19>60,$M19<=70),14,IF(AND($M19>50,$M19<=60),6,0)))+IF($P19>=0.1,14,IF($P19>=0.03,7,0))+IF($M19>80,-12,0)+IF($M19<40,-20,0)+IF($N19<40,-15,0)+IF($K19<0.2,-18,0)+IF($P19<=-0.1,-10,0)))) | R19: =IF($D19="","",IF(AND($D19>$G19,$O19>=BB816設定!$B$6,$N19>=BB816設定!$B$7,$M19<=BB816設定!$B$8),"○","－")) | S19: =IF($D19="","",IF(AND($R19="○",$Q19>=BB816設定!$B$9),"◎買い",IF($Q19>=BB816設定!$B$10,"○監視",IF(OR($M19<40,$K19<0.2),"▲弱い","－")))) | T19: =IF($D19="","",IF(AND($D19>$G19,$O19>=BB816設定!$B$14,$N19>=BB816設定!$B$15,$M19<=BB816設定!$B$16),"買い可","見送り")) | U19: =IF($D19="","",IF(AND($D19>$H19,$M19>=BB816設定!$B$17,$N19>=BB816設定!$B$18,$O19>=BB816設定!$B$19),"買い可","見送り")) | V19: =IF($S19="◎買い",$D19,"") | W19: =IF($S19="◎買い",ROUND($D19*(1-BB816設定!$B$11/100),1),"") | X19: =IF($S19="◎買い",BB816設定!$B$11/BB816設定!$B$13,"") | Y19: =IF($D19="","",$Q19+(10000-ROW())/100000) | Z19: =IF($D19="","",$D19*BB816設定!$B$21) | AA19: =IF($D19="","",IF($Z19<=BB816設定!$B$20/BB816設定!$B$13,"○","×（1枠に入らない）"))
