Workbook

Sheet BB使い方
B1: 📘 ボリンジャーバンド投資シート ― 使い方と戦略
B2: このブックは既存の楽天RSS株価管理システムに「ボリンジャーバンド(SMA20・±1σ/±2σ)」の
B3: 買い候補スクリーニング／バックテストを追加したものです。既存シートは一切変更していません。
B5: ■ シートの使い方
B6: ① 楽天RSS(マーケットスピードII RSS)を起動し、いつも通り「終値/高値/安値/出来高」シートを最新化する。
B7: ② 自動再計算(F9)後、「BBスクリーニング」シートを開く。全銘柄のバンド・シグナルが自動計算される。
B8: ③ 「スコア」列で降順に並べ替え、または「BB買い候補TOP」シートで上位30銘柄を確認する。
B9: ④ 「戦略シグナル」列が ◎○△ の銘柄を候補とし、利確(+1σ)・損切り(ミドル)ラインを確認する。
B10: ⑤ 「BBバックテスト」シートに銘柄コードを入れると、その銘柄の過去検証(勝率・損益)が出る。
B11: ⑥ 数値のしきい値は「BB設定」シートの青字セルで変更できる。
B13: ■ 戦略サマリー表（動画の手法をシート化）
B14: 戦略 | C14: エントリー条件 | D14: 確認フィルター | E14: 利確 | F14: 損切り | G14: 使用指標
B15: ①スクイーズブレイク | C15: 帯幅が歴史的低水準→終値が+2σを実体で突破 | D15: 帯幅が拡大に転換／ダマシ回避 | E15: +1σを実体割れ | F15: ミドル(SMA)割れ | G15: 帯幅・SMA・±2σ
B16: ②トレンドフォロー (バンドウォーク) | C16: 終値が+1σ以上を上方に歩く | D16: MFI≥80(資金流入強)。逆らわず押し目買い | E16: +1σ実体割れ | F16: ミドル／直近安値割れ | G16: ±1σ・MFI・SMA
B17: ③ダブルトップ/ボトム (厳密スイング検出) | C17: フラクタル(前後2本)で2つの谷/山を検出 →同水準＋間に戻り＝W/M型 | D17: 1回目バンド外→2回目バンド内を自動判定 ネックライン上抜け/下抜けで「確」 | E17: ネックライン到達 | F17: 直近安値割れ | G17: スイング・±2σ
B18: ④ダイバージェンス | C18: 価格は安値更新もRSIは切上げ | D18: ミドルライン上抜けでエントリー | E18: +1σ／+2σ目標 | F18: 直近安値割れ | G18: RSI・SMA
B19: 利確・損切り原則 | C19: 強いトレンドは+1σ〜+2σを歩く(バンドウォーク) | D19: +1σを実体で割ったら「宴の終わり」 | E19: +1σ割れで決済 | F19: ミドル or 直近安値割れ | G19: ±1σ・SMA
B21: ※ 移動平均は必ず SMA（単純移動平均）を使用しています（期間20日）。σは母標準偏差(STDEVP)。
B22: ※ スクイーズ=帯幅が過去40日の最小付近。ダイバージェンス=10日前とRSIを比較して逆行を検出。
B23: ※ データはすべて既存の終値/高値/安値/出来高シート（楽天RSS取得）を参照。二重入力は不要です。
B24: ※ バックテストは履歴の範囲（最大100日、履歴が増えるほど自動で検証期間も延びます）。
B25: ※ 本シートは投資助言ではありません。最終判断はご自身で行ってください。

Sheet BB設定
A1: ⚙ ボリンジャーバンド設定（青字セル＝変更可）
A3: 項目 | B3: 値 | C3: 説明
A4: 外側バンド σ倍率 | B4: 2 | C4: ±2σ。ボリンジャーバンドの外側。ブレイク判定に使用
A5: 内側バンド σ倍率 | B5: 1 | C5: ±1σ。利確ライン・バンドウォーク判定に使用
A6: SMA期間（固定20） | B6: 20 | C6: 単純移動平均SMAの期間。式はE:X=20日で固定 ※SMA使用
A7: スクイーズ許容係数 | B7: 1.1 | C7: 帯幅 ≤ 過去40日最小×この値 でスクイーズ判定
A8: スクイーズ履歴（固定40） | B8: 40 | C8: 帯幅の最小を探す期間（式で固定）
A9: RSI/MFI期間（固定14） | B9: 14 | C9: RSI・MFIの期間。式はE:R=14で固定
A10: MFI強気しきい値 | B10: 80 | C10: MFIがこの値以上＝資金流入が強い→順張り継続
A11: ダイバージェンス比較（固定10） | B11: 10 | C11: 10日前とRSIを比較して逆行を検出
A12: 二番底/天井 価格許容 | B12: 0.05 | C12: 2つのスイング安値(高値)の価格差がこの割合以内なら「同水準」
A13: ネックライン戻り | B13: 0.03 | C13: 2つの谷(山)の間の戻りがこの割合以上でW/M型と判定
A15: ■ シグナル凡例
A16: ◎スクイーズブレイク買 | B16: → | C16: スクイーズ★または収縮状態から+2σ突破＆帯3日連続拡大。最も強い買いサイン
A17: ○順張り継続(walk) | B17: → | C17: +1σ以上でMFI≥80。トレンドに乗る
A18: ○反発(ダイバ)買 | B18: → | C18: 強気ダイバージェンス＆-1σ回復。二番天井時は抑制
A19: △二番底買(確) | B19: → | C19: 厳密スイング検出のW型＋ネックライン上抜け/バンド内復帰。反転狙い
A20: △二番底形成 | B20: → | C20: W型は成立、ネックライン未上抜け。ブレイク待ち
A21: ☆スクイーズ監視 | B21: → | C21: 帯幅が最小圏。ブレイク待ちの監視銘柄
A22: ・押し目注目 | B22: → | C22: ミドル上で%B<0.6・MFI≥50。押し目買い候補
A23: ▼-2σ割れ危険 | B23: → | C23: -2σ割れ。下落継続の警戒
A24: ▼二番天井警戒 | B24: → | C24: 二番天井M形成中。買いシグナル抑制＆-15点ペナルティ

Sheet BB買い候補TOP
A1: 🏆 本日の買い候補 TOP30（スコア上位・自動抽出）
A2: 「BBスクリーニング」のスコア上位を自動表示。◎○△のシグナルを優先的にチェック。 | Q2: 最終更新 | R2: =終値!E3 -> 46240
A4: 順位 | B4: コード | C4: 銘柄名 | D4: 現在値 | E4: スクイーズ | F4: ブレイク | G4: RSI | H4: MFI | I4: ダイバ | J4: 戦略シグナル | K4: スコア | L4: 利確+1σ | M4: 損切り | N4: R:R | O4: 株探 | Q4: Ctrl+Shift+F9（全シート強制再計算）
A5: 1 | B5: =IFERROR(INDEX(BBスクリーニング!$B$6:$B$405,MATCH(LARGE(BBスクリーニング!$AE$6:$AE$405,$A5),BBスクリーニング!$AE$6:$AE$405,0)),"") -> 5243 | C5: =IFERROR(INDEX(BBスクリーニング!$C$6:$C$405,MATCH(LARGE(BBスクリーニング!$AE$6:$AE$405,$A5),BBスクリーニング!$AE$6:$AE$405,0)),"") -> ＮＯＴＥ | D5: =IFERROR(INDEX(BBスクリーニング!$D$6:$D$405,MATCH(LARGE(BBスクリーニング!$AE$6:$AE$405,$A5),BBスクリーニング!$AE$6:$AE$405,0)),"") -> 2314 | E5: =IFERROR(INDEX(BBスクリーニング!$N$6:$N$405,MATCH(LARGE(BBスクリーニング!$AE$6:$AE$405,$A5),BBスクリーニング!$AE$6:$AE$405,0)),"") -> スクイーズ★ | F5: =IFERROR(INDEX(BBスクリーニング!$P$6:$P$405,MATCH(LARGE(BBスクリーニング!$AE$6:$AE$405,$A5),BBスクリーニング!$AE$6:$AE$405,0)),"") -> ↑+2σ突破 | G5: =IFERROR(INDEX(BBスクリーニング!$Q$6:$Q$405,MATCH(LARGE(BBスクリーニング!$AE$6:$AE$405,$A5),BBスクリーニング!$AE$6:$AE$405,0)),"") -> 55.288889 | H5: =IFERROR(INDEX(BBスクリーニング!$R$6:$R$405,MATCH(LARGE(BBスクリーニング!$AE$6:$AE$405,$A5),BBスクリーニング!$AE$6:$AE$405,0)),"") -> 62.145217 | I5: =IFERROR(INDEX(BBスクリーニング!$S$6:$S$405,MATCH(LARGE(BBスクリーニング!$AE$6:$AE$405,$A5),BBスクリーニング!$AE$6:$AE$405,0)),"") -> － | J5: =IFERROR(INDEX(BBスクリーニング!$W$6:$W$405,MATCH(LARGE(BBスクリーニング!$AE$6:$AE$405,$A5),BBスクリーニング!$AE$6:$AE$405,0)),"") -> ◎スクイーズブレイク買 | K5: =IFERROR(INDEX(BBスクリーニング!$X$6:$X$405,MATCH(LARGE(BBスクリーニング!$AE$6:$AE$405,$A5),BBスクリーニング!$AE$6:$AE$405,0)),"") -> 75 | L5: =IFERROR(INDEX(BBスクリーニング!$Z$6:$Z$405,MATCH(LARGE(BBスクリーニング!$AE$6:$AE$405,$A5),BBスクリーニング!$AE$6:$AE$405,0)),"") -> 2198.5011 | M5: =IFERROR(INDEX(BBスクリーニング!$AA$6:$AA$405,MATCH(LARGE(BBスクリーニング!$AE$6:$AE$405,$A5),BBスクリーニング!$AE$6:$AE$405,0)),"") -> 2098.4 | N5: =IFERROR(INDEX(BBスクリーニング!$AC$6:$AC$405,MATCH(LARGE(BBスクリーニング!$AE$6:$AE$405,$A5),BBスクリーニング!$AE$6:$AE$405,0)),"") -> 0.39 | O5: =IF($B5="","",HYPERLINK("https://kabutan.jp/stock/?code="&$B5,"株探")) -> 株探
A6: 2 | B6: =IFERROR(INDEX(BBスクリーニング!$B$6:$B$405,MATCH(LARGE(BBスクリーニング!$AE$6:$AE$405,$A6),BBスクリーニング!$AE$6:$AE$405,0)),"") -> 4704 | C6: =IFERROR(INDEX(BBスクリーニング!$C$6:$C$405,MATCH(LARGE(BBスクリーニング!$AE$6:$AE$405,$A6),BBスクリーニング!$AE$6:$AE$405,0)),"") -> トレンドマイクロ | D6: =IFERROR(INDEX(BBスクリーニング!$D$6:$D$405,MATCH(LARGE(BBスクリーニング!$AE$6:$AE$405,$A6),BBスクリーニング!$AE$6:$AE$405,0)),"") -> 6720 | E6: =IFERROR(INDEX(BBスクリーニング!$N$6:$N$405,MATCH(LARGE(BBスクリーニング!$AE$6:$AE$405,$A6),BBスクリーニング!$AE$6:$AE$405,0)),"") -> 収縮 | F6: =IFERROR(INDEX(BBスクリーニング!$P$6:$P$405,MATCH(LARGE(BBスクリーニング!$AE$6:$AE$405,$A6),BBスクリーニング!$AE$6:$AE$405,0)),"") -> +1σ上 | G6: =IFERROR(INDEX(BBスクリーニング!$Q$6:$Q$405,MATCH(LARGE(BBスクリーニング!$AE$6:$AE$405,$A6),BBスクリーニング!$AE$6:$AE$405,0)),"") -> 56.684492 | H6: =IFERROR(INDEX(BBスクリーニング!$R$6:$R$405,MATCH(LARGE(BBスクリーニング!$AE$6:$AE$405,$A6),BBスクリーニング!$AE$6:$AE$405,0)),"") -> 73.03391 | I6: =IFERROR(INDEX(BBスクリーニング!$S$6:$S$405,MATCH(LARGE(BBスクリーニング!$AE$6:$AE$405,$A6),BBスクリーニング!$AE$6:$AE$405,0)),"") -> － | J6: =IFERROR(INDEX(BBスクリーニング!$W$6:$W$405,MATCH(LARGE(BBスクリーニング!$AE$6:$AE$405,$A6),BBスクリーニング!$AE$6:$AE$405,0)),"") -> △二番底形成 | K6: =IFERROR(INDEX(BBスクリーニング!$X$6:$X$405,MATCH(LARGE(BBスクリーニング!$AE$6:$AE$405,$A6),BBスクリーニング!$AE$6:$AE$405,0)),"") -> 67 | L6: =IFERROR(INDEX(BBスクリーニング!$Z$6:$Z$405,MATCH(LARGE(BBスクリーニング!$AE$6:$AE$405,$A6),BBスクリーニング!$AE$6:$AE$405,0)),"") -> 6594.5846 | M6: =IFERROR(INDEX(BBスクリーニング!$AA$6:$AA$405,MATCH(LARGE(BBスクリーニング!$AE$6:$AE$405,$A6),BBスクリーニング!$AE$6:$AE$405,0)),"") -> 6423.65 | N6: =IFERROR(INDEX(BBスクリーニング!$AC$6:$AC$405,MATCH(LARGE(BBスクリーニング!$AE$6:$AE$405,$A6),BBスクリーニング!$AE$6:$AE$405,0)),"") -> 0.15 | O6: =IF($B6="","",HYPERLINK("https://kabutan.jp/stock/?code="&$B6,"株探")) -> 株探 | V6: 8002の値 | W6: 意味・見方
A7: 3 | B7: =IFERROR(INDEX(BBスクリーニング!$B$6:$B$405,MATCH(LARGE(BBスクリーニング!$AE$6:$AE$405,$A7),BBスクリーニング!$AE$6:$AE$405,0)),"") -> 5711 | C7: =IFERROR(INDEX(BBスクリーニング!$C$6:$C$405,MATCH(LARGE(BBスクリーニング!$AE$6:$AE$405,$A7),BBスクリーニング!$AE$6:$AE$405,0)),"") -> 三菱マテリアル | D7: =IFERROR(INDEX(BBスクリーニング!$D$6:$D$405,MATCH(LARGE(BBスクリーニング!$AE$6:$AE$405,$A7),BBスクリーニング!$AE$6:$AE$405,0)),"") -> 4457 | E7: =IFERROR(INDEX(BBスクリーニング!$N$6:$N$405,MATCH(LARGE(BBスクリーニング!$AE$6:$AE$405,$A7),BBスクリーニング!$AE$6:$AE$405,0)),"") -> 収縮 | F7: =IFERROR(INDEX(BBスクリーニング!$P$6:$P$405,MATCH(LARGE(BBスクリーニング!$AE$6:$AE$405,$A7),BBスクリーニング!$AE$6:$AE$405,0)),"") -> ↑+2σ突破 | G7: =IFERROR(INDEX(BBスクリーニング!$Q$6:$Q$405,MATCH(LARGE(BBスクリーニング!$AE$6:$AE$405,$A7),BBスクリーニング!$AE$6:$AE$405,0)),"") -> 58.128079 | H7: =IFERROR(INDEX(BBスクリーニング!$R$6:$R$405,MATCH(LARGE(BBスクリーニング!$AE$6:$AE$405,$A7),BBスクリーニング!$AE$6:$AE$405,0)),"") -> 65.117569 | I7: =IFERROR(INDEX(BBスクリーニング!$S$6:$S$405,MATCH(LARGE(BBスクリーニング!$AE$6:$AE$405,$A7),BBスクリーニング!$AE$6:$AE$405,0)),"") -> － | J7: =IFERROR(INDEX(BBスクリーニング!$W$6:$W$405,MATCH(LARGE(BBスクリーニング!$AE$6:$AE$405,$A7),BBスクリーニング!$AE$6:$AE$405,0)),"") -> ◎スクイーズブレイク買 | K7: =IFERROR(INDEX(BBスクリーニング!$X$6:$X$405,MATCH(LARGE(BBスクリーニング!$AE$6:$AE$405,$A7),BBスクリーニング!$AE$6:$AE$405,0)),"") -> 65 | L7: =IFERROR(INDEX(BBスクリーニング!$Z$6:$Z$405,MATCH(LARGE(BBスクリーニング!$AE$6:$AE$405,$A7),BBスクリーニング!$AE$6:$AE$405,0)),"") -> 4281.7566 | M7: =IFERROR(INDEX(BBスクリーニング!$AA$6:$AA$405,MATCH(LARGE(BBスクリーニング!$AE$6:$AE$405,$A7),BBスクリーニング!$AE$6:$AE$405,0)),"") -> 4147.35 | N7: =IFERROR(INDEX(BBスクリーニング!$AC$6:$AC$405,MATCH(LARGE(BBスクリーニング!$AE$6:$AE$405,$A7),BBスクリーニング!$AE$6:$AE$405,0)),"") -> 0.3 | O7: =IF($B7="","",HYPERLINK("https://kabutan.jp/stock/?code="&$B7,"株探")) -> 株探 | V7: 3 | W7: スコアの高い順。上ほど条件がそろった銘柄
A8: 4 | B8: =IFERROR(INDEX(BBスクリーニング!$B$6:$B$405,MATCH(LARGE(BBスクリーニング!$AE$6:$AE$405,$A8),BBスクリーニング!$AE$6:$AE$405,0)),"") -> 8344 | C8: =IFERROR(INDEX(BBスクリーニング!$C$6:$C$405,MATCH(LARGE(BBスクリーニング!$AE$6:$AE$405,$A8),BBスクリーニング!$AE$6:$AE$405,0)),"") -> 山形銀行 | D8: =IFERROR(INDEX(BBスクリーニング!$D$6:$D$405,MATCH(LARGE(BBスクリーニング!$AE$6:$AE$405,$A8),BBスクリーニング!$AE$6:$AE$405,0)),"") -> 4235 | E8: =IFERROR(INDEX(BBスクリーニング!$N$6:$N$405,MATCH(LARGE(BBスクリーニング!$AE$6:$AE$405,$A8),BBスクリーニング!$AE$6:$AE$405,0)),"") -> 収縮 | F8: =IFERROR(INDEX(BBスクリーニング!$P$6:$P$405,MATCH(LARGE(BBスクリーニング!$AE$6:$AE$405,$A8),BBスクリーニング!$AE$6:$AE$405,0)),"") -> ↑+2σ突破 | G8: =IFERROR(INDEX(BBスクリーニング!$Q$6:$Q$405,MATCH(LARGE(BBスクリーニング!$AE$6:$AE$405,$A8),BBスクリーニング!$AE$6:$AE$405,0)),"") -> 58.530184 | H8: =IFERROR(INDEX(BBスクリーニング!$R$6:$R$405,MATCH(LARGE(BBスクリーニング!$AE$6:$AE$405,$A8),BBスクリーニング!$AE$6:$AE$405,0)),"") -> 63.260242 | I8: =IFERROR(INDEX(BBスクリーニング!$S$6:$S$405,MATCH(LARGE(BBスクリーニング!$AE$6:$AE$405,$A8),BBスクリーニング!$AE$6:$AE$405,0)),"") -> － | J8: =IFERROR(INDEX(BBスクリーニング!$W$6:$W$405,MATCH(LARGE(BBスクリーニング!$AE$6:$AE$405,$A8),BBスクリーニング!$AE$6:$AE$405,0)),"") -> ◎スクイーズブレイク買 | K8: =IFERROR(INDEX(BBスクリーニング!$X$6:$X$405,MATCH(LARGE(BBスクリーニング!$AE$6:$AE$405,$A8),BBスクリーニング!$AE$6:$AE$405,0)),"") -> 65 | L8: =IFERROR(INDEX(BBスクリーニング!$Z$6:$Z$405,MATCH(LARGE(BBスクリーニング!$AE$6:$AE$405,$A8),BBスクリーニング!$AE$6:$AE$405,0)),"") -> 4033.0327 | M8: =IFERROR(INDEX(BBスクリーニング!$AA$6:$AA$405,MATCH(LARGE(BBスクリーニング!$AE$6:$AE$405,$A8),BBスクリーニング!$AE$6:$AE$405,0)),"") -> 3870.75 | N8: =IFERROR(INDEX(BBスクリーニング!$AC$6:$AC$405,MATCH(LARGE(BBスクリーニング!$AE$6:$AE$405,$A8),BBスクリーニング!$AE$6:$AE$405,0)),"") -> 0.34 | O8: =IF($B8="","",HYPERLINK("https://kabutan.jp/stock/?code="&$B8,"株探")) -> 株探 | V8: 8002 | W8: 証券コード（4桁）
A9: 5 | B9: =IFERROR(INDEX(BBスクリーニング!$B$6:$B$405,MATCH(LARGE(BBスクリーニング!$AE$6:$AE$405,$A9),BBスクリーニング!$AE$6:$AE$405,0)),"") -> 3984 | C9: =IFERROR(INDEX(BBスクリーニング!$C$6:$C$405,MATCH(LARGE(BBスクリーニング!$AE$6:$AE$405,$A9),BBスクリーニング!$AE$6:$AE$405,0)),"") -> ユーザーローカル | D9: =IFERROR(INDEX(BBスクリーニング!$D$6:$D$405,MATCH(LARGE(BBスクリーニング!$AE$6:$AE$405,$A9),BBスクリーニング!$AE$6:$AE$405,0)),"") -> 1836 | E9: =IFERROR(INDEX(BBスクリーニング!$N$6:$N$405,MATCH(LARGE(BBスクリーニング!$AE$6:$AE$405,$A9),BBスクリーニング!$AE$6:$AE$405,0)),"") -> 収縮 | F9: =IFERROR(INDEX(BBスクリーニング!$P$6:$P$405,MATCH(LARGE(BBスクリーニング!$AE$6:$AE$405,$A9),BBスクリーニング!$AE$6:$AE$405,0)),"") -> +1σ上 | G9: =IFERROR(INDEX(BBスクリーニング!$Q$6:$Q$405,MATCH(LARGE(BBスクリーニング!$AE$6:$AE$405,$A9),BBスクリーニング!$AE$6:$AE$405,0)),"") -> 51.083591 | H9: =IFERROR(INDEX(BBスクリーニング!$R$6:$R$405,MATCH(LARGE(BBスクリーニング!$AE$6:$AE$405,$A9),BBスクリーニング!$AE$6:$AE$405,0)),"") -> 53.665458 | I9: =IFERROR(INDEX(BBスクリーニング!$S$6:$S$405,MATCH(LARGE(BBスクリーニング!$AE$6:$AE$405,$A9),BBスクリーニング!$AE$6:$AE$405,0)),"") -> － | J9: =IFERROR(INDEX(BBスクリーニング!$W$6:$W$405,MATCH(LARGE(BBスクリーニング!$AE$6:$AE$405,$A9),BBスクリーニング!$AE$6:$AE$405,0)),"") -> △二番底買(確) | K9: =IFERROR(INDEX(BBスクリーニング!$X$6:$X$405,MATCH(LARGE(BBスクリーニング!$AE$6:$AE$405,$A9),BBスクリーニング!$AE$6:$AE$405,0)),"") -> 62 | L9: =IFERROR(INDEX(BBスクリーニング!$Z$6:$Z$405,MATCH(LARGE(BBスクリーニング!$AE$6:$AE$405,$A9),BBスクリーニング!$AE$6:$AE$405,0)),"") -> 1827.2009 | M9: =IFERROR(INDEX(BBスクリーニング!$AA$6:$AA$405,MATCH(LARGE(BBスクリーニング!$AE$6:$AE$405,$A9),BBスクリーニング!$AE$6:$AE$405,0)),"") -> 1794.5 | N9: =IFERROR(INDEX(BBスクリーニング!$AC$6:$AC$405,MATCH(LARGE(BBスクリーニング!$AE$6:$AE$405,$A9),BBスクリーニング!$AE$6:$AE$405,0)),"") -> 0.58 | O9: =IF($B9="","",HYPERLINK("https://kabutan.jp/stock/?code="&$B9,"株探")) -> 株探 | V9: 丸紅 | W9: 会社名
A10: 6 | B10: =IFERROR(INDEX(BBスクリーニング!$B$6:$B$405,MATCH(LARGE(BBスクリーニング!$AE$6:$AE$405,$A10),BBスクリーニング!$AE$6:$AE$405,0)),"") -> 6965 | C10: =IFERROR(INDEX(BBスクリーニング!$C$6:$C$405,MATCH(LARGE(BBスクリーニング!$AE$6:$AE$405,$A10),BBスクリーニング!$AE$6:$AE$405,0)),"") -> 浜松ホトニクス | D10: =IFERROR(INDEX(BBスクリーニング!$D$6:$D$405,MATCH(LARGE(BBスクリーニング!$AE$6:$AE$405,$A10),BBスクリーニング!$AE$6:$AE$405,0)),"") -> 2505.5 | E10: =IFERROR(INDEX(BBスクリーニング!$N$6:$N$405,MATCH(LARGE(BBスクリーニング!$AE$6:$AE$405,$A10),BBスクリーニング!$AE$6:$AE$405,0)),"") -> スクイーズ★ | F10: =IFERROR(INDEX(BBスクリーニング!$P$6:$P$405,MATCH(LARGE(BBスクリーニング!$AE$6:$AE$405,$A10),BBスクリーニング!$AE$6:$AE$405,0)),"") -> +1σ上 | G10: =IFERROR(INDEX(BBスクリーニング!$Q$6:$Q$405,MATCH(LARGE(BBスクリーニング!$AE$6:$AE$405,$A10),BBスクリーニング!$AE$6:$AE$405,0)),"") -> 55.660874 | H10: =IFERROR(INDEX(BBスクリーニング!$R$6:$R$405,MATCH(LARGE(BBスクリーニング!$AE$6:$AE$405,$A10),BBスクリーニング!$AE$6:$AE$405,0)),"") -> 52.708572 | I10: =IFERROR(INDEX(BBスクリーニング!$S$6:$S$405,MATCH(LARGE(BBスクリーニング!$AE$6:$AE$405,$A10),BBスクリーニング!$AE$6:$AE$405,0)),"") -> － | J10: =IFERROR(INDEX(BBスクリーニング!$W$6:$W$405,MATCH(LARGE(BBスクリーニング!$AE$6:$AE$405,$A10),BBスクリーニング!$AE$6:$AE$405,0)),"") -> ☆スクイーズ監視 | K10: =IFERROR(INDEX(BBスクリーニング!$X$6:$X$405,MATCH(LARGE(BBスクリーニング!$AE$6:$AE$405,$A10),BBスクリーニング!$AE$6:$AE$405,0)),"") -> 62 | L10: =IFERROR(INDEX(BBスクリーニング!$Z$6:$Z$405,MATCH(LARGE(BBスクリーニング!$AE$6:$AE$405,$A10),BBスクリーニング!$AE$6:$AE$405,0)),"") -> 2486.7024 | M10: =IFERROR(INDEX(BBスクリーニング!$AA$6:$AA$405,MATCH(LARGE(BBスクリーニング!$AE$6:$AE$405,$A10),BBスクリーニング!$AE$6:$AE$405,0)),"") -> 2376.475 | N10: =IFERROR(INDEX(BBスクリーニング!$AC$6:$AC$405,MATCH(LARGE(BBスクリーニング!$AE$6:$AE$405,$A10),BBスクリーニング!$AE$6:$AE$405,0)),"") -> 0.71 | O10: =IF($B10="","",HYPERLINK("https://kabutan.jp/stock/?code="&$B10,"株探")) -> 株探 | V10: 4988 | W10: 最新の終値
A11: 7 | B11: =IFERROR(INDEX(BBスクリーニング!$B$6:$B$405,MATCH(LARGE(BBスクリーニング!$AE$6:$AE$405,$A11),BBスクリーニング!$AE$6:$AE$405,0)),"") -> 3402 | C11: =IFERROR(INDEX(BBスクリーニング!$C$6:$C$405,MATCH(LARGE(BBスクリーニング!$AE$6:$AE$405,$A11),BBスクリーニング!$AE$6:$AE$405,0)),"") -> 東レ | D11: =IFERROR(INDEX(BBスクリーニング!$D$6:$D$405,MATCH(LARGE(BBスクリーニング!$AE$6:$AE$405,$A11),BBスクリーニング!$AE$6:$AE$405,0)),"") -> 1299.5 | E11: =IFERROR(INDEX(BBスクリーニング!$N$6:$N$405,MATCH(LARGE(BBスクリーニング!$AE$6:$AE$405,$A11),BBスクリーニング!$AE$6:$AE$405,0)),"") -> － | F11: =IFERROR(INDEX(BBスクリーニング!$P$6:$P$405,MATCH(LARGE(BBスクリーニング!$AE$6:$AE$405,$A11),BBスクリーニング!$AE$6:$AE$405,0)),"") -> ↑+2σ突破 | G11: =IFERROR(INDEX(BBスクリーニング!$Q$6:$Q$405,MATCH(LARGE(BBスクリーニング!$AE$6:$AE$405,$A11),BBスクリーニング!$AE$6:$AE$405,0)),"") -> 69.054441 | H11: =IFERROR(INDEX(BBスクリーニング!$R$6:$R$405,MATCH(LARGE(BBスクリーニング!$AE$6:$AE$405,$A11),BBスクリーニング!$AE$6:$AE$405,0)),"") -> 67.01797 | I11: =IFERROR(INDEX(BBスクリーニング!$S$6:$S$405,MATCH(LARGE(BBスクリーニング!$AE$6:$AE$405,$A11),BBスクリーニング!$AE$6:$AE$405,0)),"") -> － | J11: =IFERROR(INDEX(BBスクリーニング!$W$6:$W$405,MATCH(LARGE(BBスクリーニング!$AE$6:$AE$405,$A11),BBスクリーニング!$AE$6:$AE$405,0)),"") -> △二番底買(確) | K11: =IFERROR(INDEX(BBスクリーニング!$X$6:$X$405,MATCH(LARGE(BBスクリーニング!$AE$6:$AE$405,$A11),BBスクリーニング!$AE$6:$AE$405,0)),"") -> 60 | L11: =IFERROR(INDEX(BBスクリーニング!$Z$6:$Z$405,MATCH(LARGE(BBスクリーニング!$AE$6:$AE$405,$A11),BBスクリーニング!$AE$6:$AE$405,0)),"") -> 1199.291 | M11: =IFERROR(INDEX(BBスクリーニング!$AA$6:$AA$405,MATCH(LARGE(BBスクリーニング!$AE$6:$AE$405,$A11),BBスクリーニング!$AE$6:$AE$405,0)),"") -> 1165.25 | N11: =IFERROR(INDEX(BBスクリーニング!$AC$6:$AC$405,MATCH(LARGE(BBスクリーニング!$AE$6:$AE$405,$A11),BBスクリーニング!$AE$6:$AE$405,0)),"") -> -0.24 | O11: =IF($B11="","",HYPERLINK("https://kabutan.jp/stock/?code="&$B11,"株探")) -> 株探 | V11: 収縮 | W11: バンドの幅の状態。スクイーズ★＝過去最小圏（大きく動く前兆）／収縮＝狭まり気味／－＝通常
A12: 8 | B12: =IFERROR(INDEX(BBスクリーニング!$B$6:$B$405,MATCH(LARGE(BBスクリーニング!$AE$6:$AE$405,$A12),BBスクリーニング!$AE$6:$AE$405,0)),"") -> 3103 | C12: =IFERROR(INDEX(BBスクリーニング!$C$6:$C$405,MATCH(LARGE(BBスクリーニング!$AE$6:$AE$405,$A12),BBスクリーニング!$AE$6:$AE$405,0)),"") -> ユニチカ | D12: =IFERROR(INDEX(BBスクリーニング!$D$6:$D$405,MATCH(LARGE(BBスクリーニング!$AE$6:$AE$405,$A12),BBスクリーニング!$AE$6:$AE$405,0)),"") -> 1258 | E12: =IFERROR(INDEX(BBスクリーニング!$N$6:$N$405,MATCH(LARGE(BBスクリーニング!$AE$6:$AE$405,$A12),BBスクリーニング!$AE$6:$AE$405,0)),"") -> － | F12: =IFERROR(INDEX(BBスクリーニング!$P$6:$P$405,MATCH(LARGE(BBスクリーニング!$AE$6:$AE$405,$A12),BBスクリーニング!$AE$6:$AE$405,0)),"") -> ↑+2σ突破 | G12: =IFERROR(INDEX(BBスクリーニング!$Q$6:$Q$405,MATCH(LARGE(BBスクリーニング!$AE$6:$AE$405,$A12),BBスクリーニング!$AE$6:$AE$405,0)),"") -> 68.69773 | H12: =IFERROR(INDEX(BBスクリーニング!$R$6:$R$405,MATCH(LARGE(BBスクリーニング!$AE$6:$AE$405,$A12),BBスクリーニング!$AE$6:$AE$405,0)),"") -> 75.47515 | I12: =IFERROR(INDEX(BBスクリーニング!$S$6:$S$405,MATCH(LARGE(BBスクリーニング!$AE$6:$AE$405,$A12),BBスクリーニング!$AE$6:$AE$405,0)),"") -> － | J12: =IFERROR(INDEX(BBスクリーニング!$W$6:$W$405,MATCH(LARGE(BBスクリーニング!$AE$6:$AE$405,$A12),BBスクリーニング!$AE$6:$AE$405,0)),"") -> 様子見 | K12: =IFERROR(INDEX(BBスクリーニング!$X$6:$X$405,MATCH(LARGE(BBスクリーニング!$AE$6:$AE$405,$A12),BBスクリーニング!$AE$6:$AE$405,0)),"") -> 60 | L12: =IFERROR(INDEX(BBスクリーニング!$Z$6:$Z$405,MATCH(LARGE(BBスクリーニング!$AE$6:$AE$405,$A12),BBスクリーニング!$AE$6:$AE$405,0)),"") -> 1000.4522 | M12: =IFERROR(INDEX(BBスクリーニング!$AA$6:$AA$405,MATCH(LARGE(BBスクリーニング!$AE$6:$AE$405,$A12),BBスクリーニング!$AE$6:$AE$405,0)),"") -> 898.45 | N12: =IFERROR(INDEX(BBスクリーニング!$AC$6:$AC$405,MATCH(LARGE(BBスクリーニング!$AE$6:$AE$405,$A12),BBスクリーニング!$AE$6:$AE$405,0)),"") -> -0.15 | O12: =IF($B12="","",HYPERLINK("https://kabutan.jp/stock/?code="&$B12,"株探")) -> 株探 | V12: +1σ上 | W12: 現在値がバンドのどこにいるか。↑+2σ突破＝強い上抜け／+1σ上＝上寄り／バンド内／−1σ下／↓−2σ割れ
A13: 9 | B13: =IFERROR(INDEX(BBスクリーニング!$B$6:$B$405,MATCH(LARGE(BBスクリーニング!$AE$6:$AE$405,$A13),BBスクリーニング!$AE$6:$AE$405,0)),"") -> 5801 | C13: =IFERROR(INDEX(BBスクリーニング!$C$6:$C$405,MATCH(LARGE(BBスクリーニング!$AE$6:$AE$405,$A13),BBスクリーニング!$AE$6:$AE$405,0)),"") -> 古河電工 | D13: =IFERROR(INDEX(BBスクリーニング!$D$6:$D$405,MATCH(LARGE(BBスクリーニング!$AE$6:$AE$405,$A13),BBスクリーニング!$AE$6:$AE$405,0)),"") -> 3909 | E13: =IFERROR(INDEX(BBスクリーニング!$N$6:$N$405,MATCH(LARGE(BBスクリーニング!$AE$6:$AE$405,$A13),BBスクリーニング!$AE$6:$AE$405,0)),"") -> 収縮 | F13: =IFERROR(INDEX(BBスクリーニング!$P$6:$P$405,MATCH(LARGE(BBスクリーニング!$AE$6:$AE$405,$A13),BBスクリーニング!$AE$6:$AE$405,0)),"") -> +1σ上 | G13: =IFERROR(INDEX(BBスクリーニング!$Q$6:$Q$405,MATCH(LARGE(BBスクリーニング!$AE$6:$AE$405,$A13),BBスクリーニング!$AE$6:$AE$405,0)),"") -> 59.123322 | H13: =IFERROR(INDEX(BBスクリーニング!$R$6:$R$405,MATCH(LARGE(BBスクリーニング!$AE$6:$AE$405,$A13),BBスクリーニング!$AE$6:$AE$405,0)),"") -> 40.233516 | I13: =IFERROR(INDEX(BBスクリーニング!$S$6:$S$405,MATCH(LARGE(BBスクリーニング!$AE$6:$AE$405,$A13),BBスクリーニング!$AE$6:$AE$405,0)),"") -> － | J13: =IFERROR(INDEX(BBスクリーニング!$W$6:$W$405,MATCH(LARGE(BBスクリーニング!$AE$6:$AE$405,$A13),BBスクリーニング!$AE$6:$AE$405,0)),"") -> 様子見 | K13: =IFERROR(INDEX(BBスクリーニング!$X$6:$X$405,MATCH(LARGE(BBスクリーニング!$AE$6:$AE$405,$A13),BBスクリーニング!$AE$6:$AE$405,0)),"") -> 60 | L13: =IFERROR(INDEX(BBスクリーニング!$Z$6:$Z$405,MATCH(LARGE(BBスクリーニング!$AE$6:$AE$405,$A13),BBスクリーニング!$AE$6:$AE$405,0)),"") -> 3728.7637 | M13: =IFERROR(INDEX(BBスクリーニング!$AA$6:$AA$405,MATCH(LARGE(BBスクリーニング!$AE$6:$AE$405,$A13),BBスクリーニング!$AE$6:$AE$405,0)),"") -> 3414.9 | N13: =IFERROR(INDEX(BBスクリーニング!$AC$6:$AC$405,MATCH(LARGE(BBスクリーニング!$AE$6:$AE$405,$A13),BBスクリーニング!$AE$6:$AE$405,0)),"") -> 0.27 | O13: =IF($B13="","",HYPERLINK("https://kabutan.jp/stock/?code="&$B13,"株探")) -> 株探 | V13: 68.3 | W13: 買われすぎ/売られすぎ。70以上=過熱、30以下=売られすぎ、50前後=中立
A14: 10 | B14: =IFERROR(INDEX(BBスクリーニング!$B$6:$B$405,MATCH(LARGE(BBスクリーニング!$AE$6:$AE$405,$A14),BBスクリーニング!$AE$6:$AE$405,0)),"") -> 6482 | C14: =IFERROR(INDEX(BBスクリーニング!$C$6:$C$405,MATCH(LARGE(BBスクリーニング!$AE$6:$AE$405,$A14),BBスクリーニング!$AE$6:$AE$405,0)),"") -> ＹＵＳＨＩＮ | D14: =IFERROR(INDEX(BBスクリーニング!$D$6:$D$405,MATCH(LARGE(BBスクリーニング!$AE$6:$AE$405,$A14),BBスクリーニング!$AE$6:$AE$405,0)),"") -> 682 | E14: =IFERROR(INDEX(BBスクリーニング!$N$6:$N$405,MATCH(LARGE(BBスクリーニング!$AE$6:$AE$405,$A14),BBスクリーニング!$AE$6:$AE$405,0)),"") -> スクイーズ★ | F14: =IFERROR(INDEX(BBスクリーニング!$P$6:$P$405,MATCH(LARGE(BBスクリーニング!$AE$6:$AE$405,$A14),BBスクリーニング!$AE$6:$AE$405,0)),"") -> バンド内 | G14: =IFERROR(INDEX(BBスクリーニング!$Q$6:$Q$405,MATCH(LARGE(BBスクリーニング!$AE$6:$AE$405,$A14),BBスクリーニング!$AE$6:$AE$405,0)),"") -> 56.666667 | H14: =IFERROR(INDEX(BBスクリーニング!$R$6:$R$405,MATCH(LARGE(BBスクリーニング!$AE$6:$AE$405,$A14),BBスクリーニング!$AE$6:$AE$405,0)),"") -> 70.219735 | I14: =IFERROR(INDEX(BBスクリーニング!$S$6:$S$405,MATCH(LARGE(BBスクリーニング!$AE$6:$AE$405,$A14),BBスクリーニング!$AE$6:$AE$405,0)),"") -> 強気div▲ | J14: =IFERROR(INDEX(BBスクリーニング!$W$6:$W$405,MATCH(LARGE(BBスクリーニング!$AE$6:$AE$405,$A14),BBスクリーニング!$AE$6:$AE$405,0)),"") -> ○反発(ダイバ)買 | K14: =IFERROR(INDEX(BBスクリーニング!$X$6:$X$405,MATCH(LARGE(BBスクリーニング!$AE$6:$AE$405,$A14),BBスクリーニング!$AE$6:$AE$405,0)),"") -> 60 | L14: =IFERROR(INDEX(BBスクリーニング!$Z$6:$Z$405,MATCH(LARGE(BBスクリーニング!$AE$6:$AE$405,$A14),BBスクリーニング!$AE$6:$AE$405,0)),"") -> 685.99894 | M14: =IFERROR(INDEX(BBスクリーニング!$AA$6:$AA$405,MATCH(LARGE(BBスクリーニング!$AE$6:$AE$405,$A14),BBスクリーニング!$AE$6:$AE$405,0)),"") -> 676.6 | N14: =IFERROR(INDEX(BBスクリーニング!$AC$6:$AC$405,MATCH(LARGE(BBスクリーニング!$AE$6:$AE$405,$A14),BBスクリーニング!$AE$6:$AE$405,0)),"") -> 2.48 | O14: =IF($B14="","",HYPERLINK("https://kabutan.jp/stock/?code="&$B14,"株探")) -> 株探 | V14: 59.4 | W14: お金の流入の強さ（出来高込みのRSI）。80以上=資金流入が強い、20以下=流出
A15: 11 | B15: =IFERROR(INDEX(BBスクリーニング!$B$6:$B$405,MATCH(LARGE(BBスクリーニング!$AE$6:$AE$405,$A15),BBスクリーニング!$AE$6:$AE$405,0)),"") -> 5714 | C15: =IFERROR(INDEX(BBスクリーニング!$C$6:$C$405,MATCH(LARGE(BBスクリーニング!$AE$6:$AE$405,$A15),BBスクリーニング!$AE$6:$AE$405,0)),"") -> ＤＯＷＡホールディングス | D15: =IFERROR(INDEX(BBスクリーニング!$D$6:$D$405,MATCH(LARGE(BBスクリーニング!$AE$6:$AE$405,$A15),BBスクリーニング!$AE$6:$AE$405,0)),"") -> 8907 | E15: =IFERROR(INDEX(BBスクリーニング!$N$6:$N$405,MATCH(LARGE(BBスクリーニング!$AE$6:$AE$405,$A15),BBスクリーニング!$AE$6:$AE$405,0)),"") -> 収縮 | F15: =IFERROR(INDEX(BBスクリーニング!$P$6:$P$405,MATCH(LARGE(BBスクリーニング!$AE$6:$AE$405,$A15),BBスクリーニング!$AE$6:$AE$405,0)),"") -> ↑+2σ突破 | G15: =IFERROR(INDEX(BBスクリーニング!$Q$6:$Q$405,MATCH(LARGE(BBスクリーニング!$AE$6:$AE$405,$A15),BBスクリーニング!$AE$6:$AE$405,0)),"") -> 59.00581 | H15: =IFERROR(INDEX(BBスクリーニング!$R$6:$R$405,MATCH(LARGE(BBスクリーニング!$AE$6:$AE$405,$A15),BBスクリーニング!$AE$6:$AE$405,0)),"") -> 65.398996 | I15: =IFERROR(INDEX(BBスクリーニング!$S$6:$S$405,MATCH(LARGE(BBスクリーニング!$AE$6:$AE$405,$A15),BBスクリーニング!$AE$6:$AE$405,0)),"") -> － | J15: =IFERROR(INDEX(BBスクリーニング!$W$6:$W$405,MATCH(LARGE(BBスクリーニング!$AE$6:$AE$405,$A15),BBスクリーニング!$AE$6:$AE$405,0)),"") -> △二番底買(確) | K15: =IFERROR(INDEX(BBスクリーニング!$X$6:$X$405,MATCH(LARGE(BBスクリーニング!$AE$6:$AE$405,$A15),BBスクリーニング!$AE$6:$AE$405,0)),"") -> 58 | L15: =IFERROR(INDEX(BBスクリーニング!$Z$6:$Z$405,MATCH(LARGE(BBスクリーニング!$AE$6:$AE$405,$A15),BBスクリーニング!$AE$6:$AE$405,0)),"") -> 8528.7918 | M15: =IFERROR(INDEX(BBスクリーニング!$AA$6:$AA$405,MATCH(LARGE(BBスクリーニング!$AE$6:$AE$405,$A15),BBスクリーニング!$AE$6:$AE$405,0)),"") -> 8302.05 | N15: =IFERROR(INDEX(BBスクリーニング!$AC$6:$AC$405,MATCH(LARGE(BBスクリーニング!$AE$6:$AE$405,$A15),BBスクリーニング!$AE$6:$AE$405,0)),"") -> 0.12 | O15: =IF($B15="","",HYPERLINK("https://kabutan.jp/stock/?code="&$B15,"株探")) -> 株探 | V15: なし | W15: ダイバージェンス。強気div▲＝価格は下でもRSIは上向き（反転の芽）／弱気div▼＝逆
A16: 12 | B16: =IFERROR(INDEX(BBスクリーニング!$B$6:$B$405,MATCH(LARGE(BBスクリーニング!$AE$6:$AE$405,$A16),BBスクリーニング!$AE$6:$AE$405,0)),"") -> 300A | C16: =IFERROR(INDEX(BBスクリーニング!$C$6:$C$405,MATCH(LARGE(BBスクリーニング!$AE$6:$AE$405,$A16),BBスクリーニング!$AE$6:$AE$405,0)),"") -> ＭＩＣ | D16: =IFERROR(INDEX(BBスクリーニング!$D$6:$D$405,MATCH(LARGE(BBスクリーニング!$AE$6:$AE$405,$A16),BBスクリーニング!$AE$6:$AE$405,0)),"") -> 3070 | E16: =IFERROR(INDEX(BBスクリーニング!$N$6:$N$405,MATCH(LARGE(BBスクリーニング!$AE$6:$AE$405,$A16),BBスクリーニング!$AE$6:$AE$405,0)),"") -> － | F16: =IFERROR(INDEX(BBスクリーニング!$P$6:$P$405,MATCH(LARGE(BBスクリーニング!$AE$6:$AE$405,$A16),BBスクリーニング!$AE$6:$AE$405,0)),"") -> ↑+2σ突破 | G16: =IFERROR(INDEX(BBスクリーニング!$Q$6:$Q$405,MATCH(LARGE(BBスクリーニング!$AE$6:$AE$405,$A16),BBスクリーニング!$AE$6:$AE$405,0)),"") -> 67.088608 | H16: =IFERROR(INDEX(BBスクリーニング!$R$6:$R$405,MATCH(LARGE(BBスクリーニング!$AE$6:$AE$405,$A16),BBスクリーニング!$AE$6:$AE$405,0)),"") -> 79.703525 | I16: =IFERROR(INDEX(BBスクリーニング!$S$6:$S$405,MATCH(LARGE(BBスクリーニング!$AE$6:$AE$405,$A16),BBスクリーニング!$AE$6:$AE$405,0)),"") -> － | J16: =IFERROR(INDEX(BBスクリーニング!$W$6:$W$405,MATCH(LARGE(BBスクリーニング!$AE$6:$AE$405,$A16),BBスクリーニング!$AE$6:$AE$405,0)),"") -> △二番底買(確) | K16: =IFERROR(INDEX(BBスクリーニング!$X$6:$X$405,MATCH(LARGE(BBスクリーニング!$AE$6:$AE$405,$A16),BBスクリーニング!$AE$6:$AE$405,0)),"") -> 58 | L16: =IFERROR(INDEX(BBスクリーニング!$Z$6:$Z$405,MATCH(LARGE(BBスクリーニング!$AE$6:$AE$405,$A16),BBスクリーニング!$AE$6:$AE$405,0)),"") -> 3003.5767 | M16: =IFERROR(INDEX(BBスクリーニング!$AA$6:$AA$405,MATCH(LARGE(BBスクリーニング!$AE$6:$AE$405,$A16),BBスクリーニング!$AE$6:$AE$405,0)),"") -> 2937.2 | N16: =IFERROR(INDEX(BBスクリーニング!$AC$6:$AC$405,MATCH(LARGE(BBスクリーニング!$AE$6:$AE$405,$A16),BBスクリーニング!$AE$6:$AE$405,0)),"") -> 0.5 | O16: =IF($B16="","",HYPERLINK("https://kabutan.jp/stock/?code="&$B16,"株探")) -> 株探 | V16: △二番底形成 | W16: 一番の要注目列（下に凡例）
A17: 13 | B17: =IFERROR(INDEX(BBスクリーニング!$B$6:$B$405,MATCH(LARGE(BBスクリーニング!$AE$6:$AE$405,$A17),BBスクリーニング!$AE$6:$AE$405,0)),"") -> 8570 | C17: =IFERROR(INDEX(BBスクリーニング!$C$6:$C$405,MATCH(LARGE(BBスクリーニング!$AE$6:$AE$405,$A17),BBスクリーニング!$AE$6:$AE$405,0)),"") -> イオンフィナンシャルサービス | D17: =IFERROR(INDEX(BBスクリーニング!$D$6:$D$405,MATCH(LARGE(BBスクリーニング!$AE$6:$AE$405,$A17),BBスクリーニング!$AE$6:$AE$405,0)),"") -> 1594.5 | E17: =IFERROR(INDEX(BBスクリーニング!$N$6:$N$405,MATCH(LARGE(BBスクリーニング!$AE$6:$AE$405,$A17),BBスクリーニング!$AE$6:$AE$405,0)),"") -> スクイーズ★ | F17: =IFERROR(INDEX(BBスクリーニング!$P$6:$P$405,MATCH(LARGE(BBスクリーニング!$AE$6:$AE$405,$A17),BBスクリーニング!$AE$6:$AE$405,0)),"") -> +1σ上 | G17: =IFERROR(INDEX(BBスクリーニング!$Q$6:$Q$405,MATCH(LARGE(BBスクリーニング!$AE$6:$AE$405,$A17),BBスクリーニング!$AE$6:$AE$405,0)),"") -> 61.693548 | H17: =IFERROR(INDEX(BBスクリーニング!$R$6:$R$405,MATCH(LARGE(BBスクリーニング!$AE$6:$AE$405,$A17),BBスクリーニング!$AE$6:$AE$405,0)),"") -> 61.095421 | I17: =IFERROR(INDEX(BBスクリーニング!$S$6:$S$405,MATCH(LARGE(BBスクリーニング!$AE$6:$AE$405,$A17),BBスクリーニング!$AE$6:$AE$405,0)),"") -> 弱気div▼ | J17: =IFERROR(INDEX(BBスクリーニング!$W$6:$W$405,MATCH(LARGE(BBスクリーニング!$AE$6:$AE$405,$A17),BBスクリーニング!$AE$6:$AE$405,0)),"") -> ☆スクイーズ監視 | K17: =IFERROR(INDEX(BBスクリーニング!$X$6:$X$405,MATCH(LARGE(BBスクリーニング!$AE$6:$AE$405,$A17),BBスクリーニング!$AE$6:$AE$405,0)),"") -> 57 | L17: =IFERROR(INDEX(BBスクリーニング!$Z$6:$Z$405,MATCH(LARGE(BBスクリーニング!$AE$6:$AE$405,$A17),BBスクリーニング!$AE$6:$AE$405,0)),"") -> 1577.1698 | M17: =IFERROR(INDEX(BBスクリーニング!$AA$6:$AA$405,MATCH(LARGE(BBスクリーニング!$AE$6:$AE$405,$A17),BBスクリーニング!$AE$6:$AE$405,0)),"") -> 1556.05 | N17: =IFERROR(INDEX(BBスクリーニング!$AC$6:$AC$405,MATCH(LARGE(BBスクリーニング!$AE$6:$AE$405,$A17),BBスクリーニング!$AE$6:$AE$405,0)),"") -> 0.1 | O17: =IF($B17="","",HYPERLINK("https://kabutan.jp/stock/?code="&$B17,"株探")) -> 株探 | V17: 62 | W17: 各条件の合致度を0〜100点で合計。高いほど条件がそろう
A18: 14 | B18: =IFERROR(INDEX(BBスクリーニング!$B$6:$B$405,MATCH(LARGE(BBスクリーニング!$AE$6:$AE$405,$A18),BBスクリーニング!$AE$6:$AE$405,0)),"") -> 9501 | C18: =IFERROR(INDEX(BBスクリーニング!$C$6:$C$405,MATCH(LARGE(BBスクリーニング!$AE$6:$AE$405,$A18),BBスクリーニング!$AE$6:$AE$405,0)),"") -> 東京電力ＨＤ | D18: =IFERROR(INDEX(BBスクリーニング!$D$6:$D$405,MATCH(LARGE(BBスクリーニング!$AE$6:$AE$405,$A18),BBスクリーニング!$AE$6:$AE$405,0)),"") -> 537 | E18: =IFERROR(INDEX(BBスクリーニング!$N$6:$N$405,MATCH(LARGE(BBスクリーニング!$AE$6:$AE$405,$A18),BBスクリーニング!$AE$6:$AE$405,0)),"") -> スクイーズ★ | F18: =IFERROR(INDEX(BBスクリーニング!$P$6:$P$405,MATCH(LARGE(BBスクリーニング!$AE$6:$AE$405,$A18),BBスクリーニング!$AE$6:$AE$405,0)),"") -> +1σ上 | G18: =IFERROR(INDEX(BBスクリーニング!$Q$6:$Q$405,MATCH(LARGE(BBスクリーニング!$AE$6:$AE$405,$A18),BBスクリーニング!$AE$6:$AE$405,0)),"") -> 67.251462 | H18: =IFERROR(INDEX(BBスクリーニング!$R$6:$R$405,MATCH(LARGE(BBスクリーニング!$AE$6:$AE$405,$A18),BBスクリーニング!$AE$6:$AE$405,0)),"") -> 60.765493 | I18: =IFERROR(INDEX(BBスクリーニング!$S$6:$S$405,MATCH(LARGE(BBスクリーニング!$AE$6:$AE$405,$A18),BBスクリーニング!$AE$6:$AE$405,0)),"") -> 弱気div▼ | J18: =IFERROR(INDEX(BBスクリーニング!$W$6:$W$405,MATCH(LARGE(BBスクリーニング!$AE$6:$AE$405,$A18),BBスクリーニング!$AE$6:$AE$405,0)),"") -> △二番底形成 | K18: =IFERROR(INDEX(BBスクリーニング!$X$6:$X$405,MATCH(LARGE(BBスクリーニング!$AE$6:$AE$405,$A18),BBスクリーニング!$AE$6:$AE$405,0)),"") -> 57 | L18: =IFERROR(INDEX(BBスクリーニング!$Z$6:$Z$405,MATCH(LARGE(BBスクリーニング!$AE$6:$AE$405,$A18),BBスクリーニング!$AE$6:$AE$405,0)),"") -> 529.79673 | M18: =IFERROR(INDEX(BBスクリーニング!$AA$6:$AA$405,MATCH(LARGE(BBスクリーニング!$AE$6:$AE$405,$A18),BBスクリーニング!$AE$6:$AE$405,0)),"") -> 512.85 | N18: =IFERROR(INDEX(BBスクリーニング!$AC$6:$AC$405,MATCH(LARGE(BBスクリーニング!$AE$6:$AE$405,$A18),BBスクリーニング!$AE$6:$AE$405,0)),"") -> 0.4 | O18: =IF($B18="","",HYPERLINK("https://kabutan.jp/stock/?code="&$B18,"株探")) -> 株探 | V18: 4987 | W18: 利確の目安ライン。現在値がここを実体で割ったら手仕舞い（＝+1σ）
A19: 15 | B19: =IFERROR(INDEX(BBスクリーニング!$B$6:$B$405,MATCH(LARGE(BBスクリーニング!$AE$6:$AE$405,$A19),BBスクリーニング!$AE$6:$AE$405,0)),"") -> 8704 | C19: =IFERROR(INDEX(BBスクリーニング!$C$6:$C$405,MATCH(LARGE(BBスクリーニング!$AE$6:$AE$405,$A19),BBスクリーニング!$AE$6:$AE$405,0)),"") -> トレイダーズＨＬＤＧＳ | D19: =IFERROR(INDEX(BBスクリーニング!$D$6:$D$405,MATCH(LARGE(BBスクリーニング!$AE$6:$AE$405,$A19),BBスクリーニング!$AE$6:$AE$405,0)),"") -> 1323 | E19: =IFERROR(INDEX(BBスクリーニング!$N$6:$N$405,MATCH(LARGE(BBスクリーニング!$AE$6:$AE$405,$A19),BBスクリーニング!$AE$6:$AE$405,0)),"") -> 収縮 | F19: =IFERROR(INDEX(BBスクリーニング!$P$6:$P$405,MATCH(LARGE(BBスクリーニング!$AE$6:$AE$405,$A19),BBスクリーニング!$AE$6:$AE$405,0)),"") -> +1σ上 | G19: =IFERROR(INDEX(BBスクリーニング!$Q$6:$Q$405,MATCH(LARGE(BBスクリーニング!$AE$6:$AE$405,$A19),BBスクリーニング!$AE$6:$AE$405,0)),"") -> 53.395785 | H19: =IFERROR(INDEX(BBスクリーニング!$R$6:$R$405,MATCH(LARGE(BBスクリーニング!$AE$6:$AE$405,$A19),BBスクリーニング!$AE$6:$AE$405,0)),"") -> 61.072707 | I19: =IFERROR(INDEX(BBスクリーニング!$S$6:$S$405,MATCH(LARGE(BBスクリーニング!$AE$6:$AE$405,$A19),BBスクリーニング!$AE$6:$AE$405,0)),"") -> 弱気div▼ | J19: =IFERROR(INDEX(BBスクリーニング!$W$6:$W$405,MATCH(LARGE(BBスクリーニング!$AE$6:$AE$405,$A19),BBスクリーニング!$AE$6:$AE$405,0)),"") -> △二番底買(確) | K19: =IFERROR(INDEX(BBスクリーニング!$X$6:$X$405,MATCH(LARGE(BBスクリーニング!$AE$6:$AE$405,$A19),BBスクリーニング!$AE$6:$AE$405,0)),"") -> 57 | L19: =IFERROR(INDEX(BBスクリーニング!$Z$6:$Z$405,MATCH(LARGE(BBスクリーニング!$AE$6:$AE$405,$A19),BBスクリーニング!$AE$6:$AE$405,0)),"") -> 1306.5797 | M19: =IFERROR(INDEX(BBスクリーニング!$AA$6:$AA$405,MATCH(LARGE(BBスクリーニング!$AE$6:$AE$405,$A19),BBスクリーニング!$AE$6:$AE$405,0)),"") -> 1268.75 | N19: =IFERROR(INDEX(BBスクリーニング!$AC$6:$AC$405,MATCH(LARGE(BBスクリーニング!$AE$6:$AE$405,$A19),BBスクリーニング!$AE$6:$AE$405,0)),"") -> 0.39 | O19: =IF($B19="","",HYPERLINK("https://kabutan.jp/stock/?code="&$B19,"株探")) -> 株探 | V19: 4852 | W19: 損切りの目安ライン（＝ミドル/SMA20割れ）
A20: 16 | B20: =IFERROR(INDEX(BBスクリーニング!$B$6:$B$405,MATCH(LARGE(BBスクリーニング!$AE$6:$AE$405,$A20),BBスクリーニング!$AE$6:$AE$405,0)),"") -> 7011 | C20: =IFERROR(INDEX(BBスクリーニング!$C$6:$C$405,MATCH(LARGE(BBスクリーニング!$AE$6:$AE$405,$A20),BBスクリーニング!$AE$6:$AE$405,0)),"") -> 三菱重工業 | D20: =IFERROR(INDEX(BBスクリーニング!$D$6:$D$405,MATCH(LARGE(BBスクリーニング!$AE$6:$AE$405,$A20),BBスクリーニング!$AE$6:$AE$405,0)),"") -> 3998 | E20: =IFERROR(INDEX(BBスクリーニング!$N$6:$N$405,MATCH(LARGE(BBスクリーニング!$AE$6:$AE$405,$A20),BBスクリーニング!$AE$6:$AE$405,0)),"") -> スクイーズ★ | F20: =IFERROR(INDEX(BBスクリーニング!$P$6:$P$405,MATCH(LARGE(BBスクリーニング!$AE$6:$AE$405,$A20),BBスクリーニング!$AE$6:$AE$405,0)),"") -> +1σ上 | G20: =IFERROR(INDEX(BBスクリーニング!$Q$6:$Q$405,MATCH(LARGE(BBスクリーニング!$AE$6:$AE$405,$A20),BBスクリーニング!$AE$6:$AE$405,0)),"") -> 58.231421 | H20: =IFERROR(INDEX(BBスクリーニング!$R$6:$R$405,MATCH(LARGE(BBスクリーニング!$AE$6:$AE$405,$A20),BBスクリーニング!$AE$6:$AE$405,0)),"") -> 71.015229 | I20: =IFERROR(INDEX(BBスクリーニング!$S$6:$S$405,MATCH(LARGE(BBスクリーニング!$AE$6:$AE$405,$A20),BBスクリーニング!$AE$6:$AE$405,0)),"") -> － | J20: =IFERROR(INDEX(BBスクリーニング!$W$6:$W$405,MATCH(LARGE(BBスクリーニング!$AE$6:$AE$405,$A20),BBスクリーニング!$AE$6:$AE$405,0)),"") -> △二番底買(確) | K20: =IFERROR(INDEX(BBスクリーニング!$X$6:$X$405,MATCH(LARGE(BBスクリーニング!$AE$6:$AE$405,$A20),BBスクリーニング!$AE$6:$AE$405,0)),"") -> 57 | L20: =IFERROR(INDEX(BBスクリーニング!$Z$6:$Z$405,MATCH(LARGE(BBスクリーニング!$AE$6:$AE$405,$A20),BBスクリーニング!$AE$6:$AE$405,0)),"") -> 3947.5939 | M20: =IFERROR(INDEX(BBスクリーニング!$AA$6:$AA$405,MATCH(LARGE(BBスクリーニング!$AE$6:$AE$405,$A20),BBスクリーニング!$AE$6:$AE$405,0)),"") -> 3845.1 | N20: =IFERROR(INDEX(BBスクリーニング!$AC$6:$AC$405,MATCH(LARGE(BBスクリーニング!$AE$6:$AE$405,$A20),BBスクリーニング!$AE$6:$AE$405,0)),"") -> 0.34 | O20: =IF($B20="","",HYPERLINK("https://kabutan.jp/stock/?code="&$B20,"株探")) -> 株探 | V20: 0.99倍 | W20: リスクリワード。1倍超なら利益幅>損失幅で有利、1未満は妙味小
A21: 17 | B21: =IFERROR(INDEX(BBスクリーニング!$B$6:$B$405,MATCH(LARGE(BBスクリーニング!$AE$6:$AE$405,$A21),BBスクリーニング!$AE$6:$AE$405,0)),"") -> 6135 | C21: =IFERROR(INDEX(BBスクリーニング!$C$6:$C$405,MATCH(LARGE(BBスクリーニング!$AE$6:$AE$405,$A21),BBスクリーニング!$AE$6:$AE$405,0)),"") -> 牧野フライス | D21: =IFERROR(INDEX(BBスクリーニング!$D$6:$D$405,MATCH(LARGE(BBスクリーニング!$AE$6:$AE$405,$A21),BBスクリーニング!$AE$6:$AE$405,0)),"") -> 15070 | E21: =IFERROR(INDEX(BBスクリーニング!$N$6:$N$405,MATCH(LARGE(BBスクリーニング!$AE$6:$AE$405,$A21),BBスクリーニング!$AE$6:$AE$405,0)),"") -> 収縮 | F21: =IFERROR(INDEX(BBスクリーニング!$P$6:$P$405,MATCH(LARGE(BBスクリーニング!$AE$6:$AE$405,$A21),BBスクリーニング!$AE$6:$AE$405,0)),"") -> +1σ上 | G21: =IFERROR(INDEX(BBスクリーニング!$Q$6:$Q$405,MATCH(LARGE(BBスクリーニング!$AE$6:$AE$405,$A21),BBスクリーニング!$AE$6:$AE$405,0)),"") -> 57.183908 | H21: =IFERROR(INDEX(BBスクリーニング!$R$6:$R$405,MATCH(LARGE(BBスクリーニング!$AE$6:$AE$405,$A21),BBスクリーニング!$AE$6:$AE$405,0)),"") -> 60.271007 | I21: =IFERROR(INDEX(BBスクリーニング!$S$6:$S$405,MATCH(LARGE(BBスクリーニング!$AE$6:$AE$405,$A21),BBスクリーニング!$AE$6:$AE$405,0)),"") -> － | J21: =IFERROR(INDEX(BBスクリーニング!$W$6:$W$405,MATCH(LARGE(BBスクリーニング!$AE$6:$AE$405,$A21),BBスクリーニング!$AE$6:$AE$405,0)),"") -> 様子見 | K21: =IFERROR(INDEX(BBスクリーニング!$X$6:$X$405,MATCH(LARGE(BBスクリーニング!$AE$6:$AE$405,$A21),BBスクリーニング!$AE$6:$AE$405,0)),"") -> 57 | L21: =IFERROR(INDEX(BBスクリーニング!$Z$6:$Z$405,MATCH(LARGE(BBスクリーニング!$AE$6:$AE$405,$A21),BBスクリーニング!$AE$6:$AE$405,0)),"") -> 14977.458 | M21: =IFERROR(INDEX(BBスクリーニング!$AA$6:$AA$405,MATCH(LARGE(BBスクリーニング!$AE$6:$AE$405,$A21),BBスクリーニング!$AE$6:$AE$405,0)),"") -> 14625.5 | N21: =IFERROR(INDEX(BBスクリーニング!$AC$6:$AC$405,MATCH(LARGE(BBスクリーニング!$AE$6:$AE$405,$A21),BBスクリーニング!$AE$6:$AE$405,0)),"") -> 0.58 | O21: =IF($B21="","",HYPERLINK("https://kabutan.jp/stock/?code="&$B21,"株探")) -> 株探
A22: 18 | B22: =IFERROR(INDEX(BBスクリーニング!$B$6:$B$405,MATCH(LARGE(BBスクリーニング!$AE$6:$AE$405,$A22),BBスクリーニング!$AE$6:$AE$405,0)),"") -> 186A | C22: =IFERROR(INDEX(BBスクリーニング!$C$6:$C$405,MATCH(LARGE(BBスクリーニング!$AE$6:$AE$405,$A22),BBスクリーニング!$AE$6:$AE$405,0)),"") -> アストロスケールホールディンク | D22: =IFERROR(INDEX(BBスクリーニング!$D$6:$D$405,MATCH(LARGE(BBスクリーニング!$AE$6:$AE$405,$A22),BBスクリーニング!$AE$6:$AE$405,0)),"") -> 1176 | E22: =IFERROR(INDEX(BBスクリーニング!$N$6:$N$405,MATCH(LARGE(BBスクリーニング!$AE$6:$AE$405,$A22),BBスクリーニング!$AE$6:$AE$405,0)),"") -> 収縮 | F22: =IFERROR(INDEX(BBスクリーニング!$P$6:$P$405,MATCH(LARGE(BBスクリーニング!$AE$6:$AE$405,$A22),BBスクリーニング!$AE$6:$AE$405,0)),"") -> +1σ上 | G22: =IFERROR(INDEX(BBスクリーニング!$Q$6:$Q$405,MATCH(LARGE(BBスクリーニング!$AE$6:$AE$405,$A22),BBスクリーニング!$AE$6:$AE$405,0)),"") -> 64.473684 | H22: =IFERROR(INDEX(BBスクリーニング!$R$6:$R$405,MATCH(LARGE(BBスクリーニング!$AE$6:$AE$405,$A22),BBスクリーニング!$AE$6:$AE$405,0)),"") -> 64.573001 | I22: =IFERROR(INDEX(BBスクリーニング!$S$6:$S$405,MATCH(LARGE(BBスクリーニング!$AE$6:$AE$405,$A22),BBスクリーニング!$AE$6:$AE$405,0)),"") -> － | J22: =IFERROR(INDEX(BBスクリーニング!$W$6:$W$405,MATCH(LARGE(BBスクリーニング!$AE$6:$AE$405,$A22),BBスクリーニング!$AE$6:$AE$405,0)),"") -> 様子見 | K22: =IFERROR(INDEX(BBスクリーニング!$X$6:$X$405,MATCH(LARGE(BBスクリーニング!$AE$6:$AE$405,$A22),BBスクリーニング!$AE$6:$AE$405,0)),"") -> 57 | L22: =IFERROR(INDEX(BBスクリーニング!$Z$6:$Z$405,MATCH(LARGE(BBスクリーニング!$AE$6:$AE$405,$A22),BBスクリーニング!$AE$6:$AE$405,0)),"") -> 1118.0232 | M22: =IFERROR(INDEX(BBスクリーニング!$AA$6:$AA$405,MATCH(LARGE(BBスクリーニング!$AE$6:$AE$405,$A22),BBスクリーニング!$AE$6:$AE$405,0)),"") -> 1048.7 | N22: =IFERROR(INDEX(BBスクリーニング!$AC$6:$AC$405,MATCH(LARGE(BBスクリーニング!$AE$6:$AE$405,$A22),BBスクリーニング!$AE$6:$AE$405,0)),"") -> 0.09 | O22: =IF($B22="","",HYPERLINK("https://kabutan.jp/stock/?code="&$B22,"株探")) -> 株探
A23: 19 | B23: =IFERROR(INDEX(BBスクリーニング!$B$6:$B$405,MATCH(LARGE(BBスクリーニング!$AE$6:$AE$405,$A23),BBスクリーニング!$AE$6:$AE$405,0)),"") -> 5713 | C23: =IFERROR(INDEX(BBスクリーニング!$C$6:$C$405,MATCH(LARGE(BBスクリーニング!$AE$6:$AE$405,$A23),BBスクリーニング!$AE$6:$AE$405,0)),"") -> 住友鉱山 | D23: =IFERROR(INDEX(BBスクリーニング!$D$6:$D$405,MATCH(LARGE(BBスクリーニング!$AE$6:$AE$405,$A23),BBスクリーニング!$AE$6:$AE$405,0)),"") -> 9088 | E23: =IFERROR(INDEX(BBスクリーニング!$N$6:$N$405,MATCH(LARGE(BBスクリーニング!$AE$6:$AE$405,$A23),BBスクリーニング!$AE$6:$AE$405,0)),"") -> － | F23: =IFERROR(INDEX(BBスクリーニング!$P$6:$P$405,MATCH(LARGE(BBスクリーニング!$AE$6:$AE$405,$A23),BBスクリーニング!$AE$6:$AE$405,0)),"") -> ↑+2σ突破 | G23: =IFERROR(INDEX(BBスクリーニング!$Q$6:$Q$405,MATCH(LARGE(BBスクリーニング!$AE$6:$AE$405,$A23),BBスクリーニング!$AE$6:$AE$405,0)),"") -> 67.947702 | H23: =IFERROR(INDEX(BBスクリーニング!$R$6:$R$405,MATCH(LARGE(BBスクリーニング!$AE$6:$AE$405,$A23),BBスクリーニング!$AE$6:$AE$405,0)),"") -> 67.781042 | I23: =IFERROR(INDEX(BBスクリーニング!$S$6:$S$405,MATCH(LARGE(BBスクリーニング!$AE$6:$AE$405,$A23),BBスクリーニング!$AE$6:$AE$405,0)),"") -> － | J23: =IFERROR(INDEX(BBスクリーニング!$W$6:$W$405,MATCH(LARGE(BBスクリーニング!$AE$6:$AE$405,$A23),BBスクリーニング!$AE$6:$AE$405,0)),"") -> 様子見 | K23: =IFERROR(INDEX(BBスクリーニング!$X$6:$X$405,MATCH(LARGE(BBスクリーニング!$AE$6:$AE$405,$A23),BBスクリーニング!$AE$6:$AE$405,0)),"") -> 55 | L23: =IFERROR(INDEX(BBスクリーニング!$Z$6:$Z$405,MATCH(LARGE(BBスクリーニング!$AE$6:$AE$405,$A23),BBスクリーニング!$AE$6:$AE$405,0)),"") -> 8145.498 | M23: =IFERROR(INDEX(BBスクリーニング!$AA$6:$AA$405,MATCH(LARGE(BBスクリーニング!$AE$6:$AE$405,$A23),BBスクリーニング!$AE$6:$AE$405,0)),"") -> 7618.65 | N23: =IFERROR(INDEX(BBスクリーニング!$AC$6:$AC$405,MATCH(LARGE(BBスクリーニング!$AE$6:$AE$405,$A23),BBスクリーニング!$AE$6:$AE$405,0)),"") -> 0.08 | O23: =IF($B23="","",HYPERLINK("https://kabutan.jp/stock/?code="&$B23,"株探")) -> 株探
A24: 20 | B24: =IFERROR(INDEX(BBスクリーニング!$B$6:$B$405,MATCH(LARGE(BBスクリーニング!$AE$6:$AE$405,$A24),BBスクリーニング!$AE$6:$AE$405,0)),"") -> 5703 | C24: =IFERROR(INDEX(BBスクリーニング!$C$6:$C$405,MATCH(LARGE(BBスクリーニング!$AE$6:$AE$405,$A24),BBスクリーニング!$AE$6:$AE$405,0)),"") -> 日本軽金属ＨＤ | D24: =IFERROR(INDEX(BBスクリーニング!$D$6:$D$405,MATCH(LARGE(BBスクリーニング!$AE$6:$AE$405,$A24),BBスクリーニング!$AE$6:$AE$405,0)),"") -> 2936 | E24: =IFERROR(INDEX(BBスクリーニング!$N$6:$N$405,MATCH(LARGE(BBスクリーニング!$AE$6:$AE$405,$A24),BBスクリーニング!$AE$6:$AE$405,0)),"") -> － | F24: =IFERROR(INDEX(BBスクリーニング!$P$6:$P$405,MATCH(LARGE(BBスクリーニング!$AE$6:$AE$405,$A24),BBスクリーニング!$AE$6:$AE$405,0)),"") -> ↑+2σ突破 | G24: =IFERROR(INDEX(BBスクリーニング!$Q$6:$Q$405,MATCH(LARGE(BBスクリーニング!$AE$6:$AE$405,$A24),BBスクリーニング!$AE$6:$AE$405,0)),"") -> 62.139423 | H24: =IFERROR(INDEX(BBスクリーニング!$R$6:$R$405,MATCH(LARGE(BBスクリーニング!$AE$6:$AE$405,$A24),BBスクリーニング!$AE$6:$AE$405,0)),"") -> 60.290027 | I24: =IFERROR(INDEX(BBスクリーニング!$S$6:$S$405,MATCH(LARGE(BBスクリーニング!$AE$6:$AE$405,$A24),BBスクリーニング!$AE$6:$AE$405,0)),"") -> － | J24: =IFERROR(INDEX(BBスクリーニング!$W$6:$W$405,MATCH(LARGE(BBスクリーニング!$AE$6:$AE$405,$A24),BBスクリーニング!$AE$6:$AE$405,0)),"") -> △二番底買(確) | K24: =IFERROR(INDEX(BBスクリーニング!$X$6:$X$405,MATCH(LARGE(BBスクリーニング!$AE$6:$AE$405,$A24),BBスクリーニング!$AE$6:$AE$405,0)),"") -> 55 | L24: =IFERROR(INDEX(BBスクリーニング!$Z$6:$Z$405,MATCH(LARGE(BBスクリーニング!$AE$6:$AE$405,$A24),BBスクリーニング!$AE$6:$AE$405,0)),"") -> 2810.742 | M24: =IFERROR(INDEX(BBスクリーニング!$AA$6:$AA$405,MATCH(LARGE(BBスクリーニング!$AE$6:$AE$405,$A24),BBスクリーニング!$AE$6:$AE$405,0)),"") -> 2717.3 | N24: =IFERROR(INDEX(BBスクリーニング!$AC$6:$AC$405,MATCH(LARGE(BBスクリーニング!$AE$6:$AE$405,$A24),BBスクリーニング!$AE$6:$AE$405,0)),"") -> 0.28 | O24: =IF($B24="","",HYPERLINK("https://kabutan.jp/stock/?code="&$B24,"株探")) -> 株探
A25: 21 | B25: =IFERROR(INDEX(BBスクリーニング!$B$6:$B$405,MATCH(LARGE(BBスクリーニング!$AE$6:$AE$405,$A25),BBスクリーニング!$AE$6:$AE$405,0)),"") -> 8053 | C25: =IFERROR(INDEX(BBスクリーニング!$C$6:$C$405,MATCH(LARGE(BBスクリーニング!$AE$6:$AE$405,$A25),BBスクリーニング!$AE$6:$AE$405,0)),"") -> 住友商事 | D25: =IFERROR(INDEX(BBスクリーニング!$D$6:$D$405,MATCH(LARGE(BBスクリーニング!$AE$6:$AE$405,$A25),BBスクリーニング!$AE$6:$AE$405,0)),"") -> 1748.5 | E25: =IFERROR(INDEX(BBスクリーニング!$N$6:$N$405,MATCH(LARGE(BBスクリーニング!$AE$6:$AE$405,$A25),BBスクリーニング!$AE$6:$AE$405,0)),"") -> － | F25: =IFERROR(INDEX(BBスクリーニング!$P$6:$P$405,MATCH(LARGE(BBスクリーニング!$AE$6:$AE$405,$A25),BBスクリーニング!$AE$6:$AE$405,0)),"") -> ↑+2σ突破 | G25: =IFERROR(INDEX(BBスクリーニング!$Q$6:$Q$405,MATCH(LARGE(BBスクリーニング!$AE$6:$AE$405,$A25),BBスクリーニング!$AE$6:$AE$405,0)),"") -> 69.40211 | H25: =IFERROR(INDEX(BBスクリーニング!$R$6:$R$405,MATCH(LARGE(BBスクリーニング!$AE$6:$AE$405,$A25),BBスクリーニング!$AE$6:$AE$405,0)),"") -> 74.55349 | I25: =IFERROR(INDEX(BBスクリーニング!$S$6:$S$405,MATCH(LARGE(BBスクリーニング!$AE$6:$AE$405,$A25),BBスクリーニング!$AE$6:$AE$405,0)),"") -> － | J25: =IFERROR(INDEX(BBスクリーニング!$W$6:$W$405,MATCH(LARGE(BBスクリーニング!$AE$6:$AE$405,$A25),BBスクリーニング!$AE$6:$AE$405,0)),"") -> △二番底買(確) | K25: =IFERROR(INDEX(BBスクリーニング!$X$6:$X$405,MATCH(LARGE(BBスクリーニング!$AE$6:$AE$405,$A25),BBスクリーニング!$AE$6:$AE$405,0)),"") -> 55 | L25: =IFERROR(INDEX(BBスクリーニング!$Z$6:$Z$405,MATCH(LARGE(BBスクリーニング!$AE$6:$AE$405,$A25),BBスクリーニング!$AE$6:$AE$405,0)),"") -> 1665.9199 | M25: =IFERROR(INDEX(BBスクリーニング!$AA$6:$AA$405,MATCH(LARGE(BBスクリーニング!$AE$6:$AE$405,$A25),BBスクリーニング!$AE$6:$AE$405,0)),"") -> 1609.65 | N25: =IFERROR(INDEX(BBスクリーニング!$AC$6:$AC$405,MATCH(LARGE(BBスクリーニング!$AE$6:$AE$405,$A25),BBスクリーニング!$AE$6:$AE$405,0)),"") -> 0.22 | O25: =IF($B25="","",HYPERLINK("https://kabutan.jp/stock/?code="&$B25,"株探")) -> 株探
A26: 22 | B26: =IFERROR(INDEX(BBスクリーニング!$B$6:$B$405,MATCH(LARGE(BBスクリーニング!$AE$6:$AE$405,$A26),BBスクリーニング!$AE$6:$AE$405,0)),"") -> 8750 | C26: =IFERROR(INDEX(BBスクリーニング!$C$6:$C$405,MATCH(LARGE(BBスクリーニング!$AE$6:$AE$405,$A26),BBスクリーニング!$AE$6:$AE$405,0)),"") -> 第一ライフグループ | D26: =IFERROR(INDEX(BBスクリーニング!$D$6:$D$405,MATCH(LARGE(BBスクリーニング!$AE$6:$AE$405,$A26),BBスクリーニング!$AE$6:$AE$405,0)),"") -> 1921 | E26: =IFERROR(INDEX(BBスクリーニング!$N$6:$N$405,MATCH(LARGE(BBスクリーニング!$AE$6:$AE$405,$A26),BBスクリーニング!$AE$6:$AE$405,0)),"") -> スクイーズ★ | F26: =IFERROR(INDEX(BBスクリーニング!$P$6:$P$405,MATCH(LARGE(BBスクリーニング!$AE$6:$AE$405,$A26),BBスクリーニング!$AE$6:$AE$405,0)),"") -> バンド内 | G26: =IFERROR(INDEX(BBスクリーニング!$Q$6:$Q$405,MATCH(LARGE(BBスクリーニング!$AE$6:$AE$405,$A26),BBスクリーニング!$AE$6:$AE$405,0)),"") -> 59.976387 | H26: =IFERROR(INDEX(BBスクリーニング!$R$6:$R$405,MATCH(LARGE(BBスクリーニング!$AE$6:$AE$405,$A26),BBスクリーニング!$AE$6:$AE$405,0)),"") -> 69.012583 | I26: =IFERROR(INDEX(BBスクリーニング!$S$6:$S$405,MATCH(LARGE(BBスクリーニング!$AE$6:$AE$405,$A26),BBスクリーニング!$AE$6:$AE$405,0)),"") -> 弱気div▼ | J26: =IFERROR(INDEX(BBスクリーニング!$W$6:$W$405,MATCH(LARGE(BBスクリーニング!$AE$6:$AE$405,$A26),BBスクリーニング!$AE$6:$AE$405,0)),"") -> △二番底形成 | K26: =IFERROR(INDEX(BBスクリーニング!$X$6:$X$405,MATCH(LARGE(BBスクリーニング!$AE$6:$AE$405,$A26),BBスクリーニング!$AE$6:$AE$405,0)),"") -> 55 | L26: =IFERROR(INDEX(BBスクリーニング!$Z$6:$Z$405,MATCH(LARGE(BBスクリーニング!$AE$6:$AE$405,$A26),BBスクリーニング!$AE$6:$AE$405,0)),"") -> 1925.8433 | M26: =IFERROR(INDEX(BBスクリーニング!$AA$6:$AA$405,MATCH(LARGE(BBスクリーニング!$AE$6:$AE$405,$A26),BBスクリーニング!$AE$6:$AE$405,0)),"") -> 1888.225 | N26: =IFERROR(INDEX(BBスクリーニング!$AC$6:$AC$405,MATCH(LARGE(BBスクリーニング!$AE$6:$AE$405,$A26),BBスクリーニング!$AE$6:$AE$405,0)),"") -> 1.3 | O26: =IF($B26="","",HYPERLINK("https://kabutan.jp/stock/?code="&$B26,"株探")) -> 株探
A27: 23 | B27: =IFERROR(INDEX(BBスクリーニング!$B$6:$B$405,MATCH(LARGE(BBスクリーニング!$AE$6:$AE$405,$A27),BBスクリーニング!$AE$6:$AE$405,0)),"") -> 5901 | C27: =IFERROR(INDEX(BBスクリーニング!$C$6:$C$405,MATCH(LARGE(BBスクリーニング!$AE$6:$AE$405,$A27),BBスクリーニング!$AE$6:$AE$405,0)),"") -> 東洋製罐グループＨＤ | D27: =IFERROR(INDEX(BBスクリーニング!$D$6:$D$405,MATCH(LARGE(BBスクリーニング!$AE$6:$AE$405,$A27),BBスクリーニング!$AE$6:$AE$405,0)),"") -> 4250 | E27: =IFERROR(INDEX(BBスクリーニング!$N$6:$N$405,MATCH(LARGE(BBスクリーニング!$AE$6:$AE$405,$A27),BBスクリーニング!$AE$6:$AE$405,0)),"") -> － | F27: =IFERROR(INDEX(BBスクリーニング!$P$6:$P$405,MATCH(LARGE(BBスクリーニング!$AE$6:$AE$405,$A27),BBスクリーニング!$AE$6:$AE$405,0)),"") -> ↑+2σ突破 | G27: =IFERROR(INDEX(BBスクリーニング!$Q$6:$Q$405,MATCH(LARGE(BBスクリーニング!$AE$6:$AE$405,$A27),BBスクリーニング!$AE$6:$AE$405,0)),"") -> 63.948498 | H27: =IFERROR(INDEX(BBスクリーニング!$R$6:$R$405,MATCH(LARGE(BBスクリーニング!$AE$6:$AE$405,$A27),BBスクリーニング!$AE$6:$AE$405,0)),"") -> 67.94622 | I27: =IFERROR(INDEX(BBスクリーニング!$S$6:$S$405,MATCH(LARGE(BBスクリーニング!$AE$6:$AE$405,$A27),BBスクリーニング!$AE$6:$AE$405,0)),"") -> － | J27: =IFERROR(INDEX(BBスクリーニング!$W$6:$W$405,MATCH(LARGE(BBスクリーニング!$AE$6:$AE$405,$A27),BBスクリーニング!$AE$6:$AE$405,0)),"") -> △二番底買(確) | K27: =IFERROR(INDEX(BBスクリーニング!$X$6:$X$405,MATCH(LARGE(BBスクリーニング!$AE$6:$AE$405,$A27),BBスクリーニング!$AE$6:$AE$405,0)),"") -> 55 | L27: =IFERROR(INDEX(BBスクリーニング!$Z$6:$Z$405,MATCH(LARGE(BBスクリーニング!$AE$6:$AE$405,$A27),BBスクリーニング!$AE$6:$AE$405,0)),"") -> 4162.4218 | M27: =IFERROR(INDEX(BBスクリーニング!$AA$6:$AA$405,MATCH(LARGE(BBスクリーニング!$AE$6:$AE$405,$A27),BBスクリーニング!$AE$6:$AE$405,0)),"") -> 4088 | N27: =IFERROR(INDEX(BBスクリーニング!$AC$6:$AC$405,MATCH(LARGE(BBスクリーニング!$AE$6:$AE$405,$A27),BBスクリーニング!$AE$6:$AE$405,0)),"") -> 0.38 | O27: =IF($B27="","",HYPERLINK("https://kabutan.jp/stock/?code="&$B27,"株探")) -> 株探
A28: 24 | B28: =IFERROR(INDEX(BBスクリーニング!$B$6:$B$405,MATCH(LARGE(BBスクリーニング!$AE$6:$AE$405,$A28),BBスクリーニング!$AE$6:$AE$405,0)),"") -> 5857 | C28: =IFERROR(INDEX(BBスクリーニング!$C$6:$C$405,MATCH(LARGE(BBスクリーニング!$AE$6:$AE$405,$A28),BBスクリーニング!$AE$6:$AE$405,0)),"") -> ＡＲＥホールディングス | D28: =IFERROR(INDEX(BBスクリーニング!$D$6:$D$405,MATCH(LARGE(BBスクリーニング!$AE$6:$AE$405,$A28),BBスクリーニング!$AE$6:$AE$405,0)),"") -> 3460 | E28: =IFERROR(INDEX(BBスクリーニング!$N$6:$N$405,MATCH(LARGE(BBスクリーニング!$AE$6:$AE$405,$A28),BBスクリーニング!$AE$6:$AE$405,0)),"") -> － | F28: =IFERROR(INDEX(BBスクリーニング!$P$6:$P$405,MATCH(LARGE(BBスクリーニング!$AE$6:$AE$405,$A28),BBスクリーニング!$AE$6:$AE$405,0)),"") -> ↑+2σ突破 | G28: =IFERROR(INDEX(BBスクリーニング!$Q$6:$Q$405,MATCH(LARGE(BBスクリーニング!$AE$6:$AE$405,$A28),BBスクリーニング!$AE$6:$AE$405,0)),"") -> 66.723116 | H28: =IFERROR(INDEX(BBスクリーニング!$R$6:$R$405,MATCH(LARGE(BBスクリーニング!$AE$6:$AE$405,$A28),BBスクリーニング!$AE$6:$AE$405,0)),"") -> 60.433012 | I28: =IFERROR(INDEX(BBスクリーニング!$S$6:$S$405,MATCH(LARGE(BBスクリーニング!$AE$6:$AE$405,$A28),BBスクリーニング!$AE$6:$AE$405,0)),"") -> － | J28: =IFERROR(INDEX(BBスクリーニング!$W$6:$W$405,MATCH(LARGE(BBスクリーニング!$AE$6:$AE$405,$A28),BBスクリーニング!$AE$6:$AE$405,0)),"") -> △二番底買(確) | K28: =IFERROR(INDEX(BBスクリーニング!$X$6:$X$405,MATCH(LARGE(BBスクリーニング!$AE$6:$AE$405,$A28),BBスクリーニング!$AE$6:$AE$405,0)),"") -> 55 | L28: =IFERROR(INDEX(BBスクリーニング!$Z$6:$Z$405,MATCH(LARGE(BBスクリーニング!$AE$6:$AE$405,$A28),BBスクリーニング!$AE$6:$AE$405,0)),"") -> 3193.4422 | M28: =IFERROR(INDEX(BBスクリーニング!$AA$6:$AA$405,MATCH(LARGE(BBスクリーニング!$AE$6:$AE$405,$A28),BBスクリーニング!$AE$6:$AE$405,0)),"") -> 3074.25 | N28: =IFERROR(INDEX(BBスクリーニング!$AC$6:$AC$405,MATCH(LARGE(BBスクリーニング!$AE$6:$AE$405,$A28),BBスクリーニング!$AE$6:$AE$405,0)),"") -> -0.07 | O28: =IF($B28="","",HYPERLINK("https://kabutan.jp/stock/?code="&$B28,"株探")) -> 株探
A29: 25 | B29: =IFERROR(INDEX(BBスクリーニング!$B$6:$B$405,MATCH(LARGE(BBスクリーニング!$AE$6:$AE$405,$A29),BBスクリーニング!$AE$6:$AE$405,0)),"") -> 7167 | C29: =IFERROR(INDEX(BBスクリーニング!$C$6:$C$405,MATCH(LARGE(BBスクリーニング!$AE$6:$AE$405,$A29),BBスクリーニング!$AE$6:$AE$405,0)),"") -> めぶきフィナンシャルＧ | D29: =IFERROR(INDEX(BBスクリーニング!$D$6:$D$405,MATCH(LARGE(BBスクリーニング!$AE$6:$AE$405,$A29),BBスクリーニング!$AE$6:$AE$405,0)),"") -> 1628 | E29: =IFERROR(INDEX(BBスクリーニング!$N$6:$N$405,MATCH(LARGE(BBスクリーニング!$AE$6:$AE$405,$A29),BBスクリーニング!$AE$6:$AE$405,0)),"") -> － | F29: =IFERROR(INDEX(BBスクリーニング!$P$6:$P$405,MATCH(LARGE(BBスクリーニング!$AE$6:$AE$405,$A29),BBスクリーニング!$AE$6:$AE$405,0)),"") -> ↑+2σ突破 | G29: =IFERROR(INDEX(BBスクリーニング!$Q$6:$Q$405,MATCH(LARGE(BBスクリーニング!$AE$6:$AE$405,$A29),BBスクリーニング!$AE$6:$AE$405,0)),"") -> 62.295082 | H29: =IFERROR(INDEX(BBスクリーニング!$R$6:$R$405,MATCH(LARGE(BBスクリーニング!$AE$6:$AE$405,$A29),BBスクリーニング!$AE$6:$AE$405,0)),"") -> 67.002091 | I29: =IFERROR(INDEX(BBスクリーニング!$S$6:$S$405,MATCH(LARGE(BBスクリーニング!$AE$6:$AE$405,$A29),BBスクリーニング!$AE$6:$AE$405,0)),"") -> － | J29: =IFERROR(INDEX(BBスクリーニング!$W$6:$W$405,MATCH(LARGE(BBスクリーニング!$AE$6:$AE$405,$A29),BBスクリーニング!$AE$6:$AE$405,0)),"") -> △二番底買(確) | K29: =IFERROR(INDEX(BBスクリーニング!$X$6:$X$405,MATCH(LARGE(BBスクリーニング!$AE$6:$AE$405,$A29),BBスクリーニング!$AE$6:$AE$405,0)),"") -> 55 | L29: =IFERROR(INDEX(BBスクリーニング!$Z$6:$Z$405,MATCH(LARGE(BBスクリーニング!$AE$6:$AE$405,$A29),BBスクリーニング!$AE$6:$AE$405,0)),"") -> 1555.6154 | M29: =IFERROR(INDEX(BBスクリーニング!$AA$6:$AA$405,MATCH(LARGE(BBスクリーニング!$AE$6:$AE$405,$A29),BBスクリーニング!$AE$6:$AE$405,0)),"") -> 1515.575 | N29: =IFERROR(INDEX(BBスクリーニング!$AC$6:$AC$405,MATCH(LARGE(BBスクリーニング!$AE$6:$AE$405,$A29),BBスクリーニング!$AE$6:$AE$405,0)),"") -> 0.07 | O29: =IF($B29="","",HYPERLINK("https://kabutan.jp/stock/?code="&$B29,"株探")) -> 株探
A30: 26 | B30: =IFERROR(INDEX(BBスクリーニング!$B$6:$B$405,MATCH(LARGE(BBスクリーニング!$AE$6:$AE$405,$A30),BBスクリーニング!$AE$6:$AE$405,0)),"") -> 6809 | C30: =IFERROR(INDEX(BBスクリーニング!$C$6:$C$405,MATCH(LARGE(BBスクリーニング!$AE$6:$AE$405,$A30),BBスクリーニング!$AE$6:$AE$405,0)),"") -> ＴＯＡ | D30: =IFERROR(INDEX(BBスクリーニング!$D$6:$D$405,MATCH(LARGE(BBスクリーニング!$AE$6:$AE$405,$A30),BBスクリーニング!$AE$6:$AE$405,0)),"") -> 1669 | E30: =IFERROR(INDEX(BBスクリーニング!$N$6:$N$405,MATCH(LARGE(BBスクリーニング!$AE$6:$AE$405,$A30),BBスクリーニング!$AE$6:$AE$405,0)),"") -> － | F30: =IFERROR(INDEX(BBスクリーニング!$P$6:$P$405,MATCH(LARGE(BBスクリーニング!$AE$6:$AE$405,$A30),BBスクリーニング!$AE$6:$AE$405,0)),"") -> ↑+2σ突破 | G30: =IFERROR(INDEX(BBスクリーニング!$Q$6:$Q$405,MATCH(LARGE(BBスクリーニング!$AE$6:$AE$405,$A30),BBスクリーニング!$AE$6:$AE$405,0)),"") -> 69.811321 | H30: =IFERROR(INDEX(BBスクリーニング!$R$6:$R$405,MATCH(LARGE(BBスクリーニング!$AE$6:$AE$405,$A30),BBスクリーニング!$AE$6:$AE$405,0)),"") -> 63.738088 | I30: =IFERROR(INDEX(BBスクリーニング!$S$6:$S$405,MATCH(LARGE(BBスクリーニング!$AE$6:$AE$405,$A30),BBスクリーニング!$AE$6:$AE$405,0)),"") -> － | J30: =IFERROR(INDEX(BBスクリーニング!$W$6:$W$405,MATCH(LARGE(BBスクリーニング!$AE$6:$AE$405,$A30),BBスクリーニング!$AE$6:$AE$405,0)),"") -> 様子見 | K30: =IFERROR(INDEX(BBスクリーニング!$X$6:$X$405,MATCH(LARGE(BBスクリーニング!$AE$6:$AE$405,$A30),BBスクリーニング!$AE$6:$AE$405,0)),"") -> 55 | L30: =IFERROR(INDEX(BBスクリーニング!$Z$6:$Z$405,MATCH(LARGE(BBスクリーニング!$AE$6:$AE$405,$A30),BBスクリーニング!$AE$6:$AE$405,0)),"") -> 1641.2768 | M30: =IFERROR(INDEX(BBスクリーニング!$AA$6:$AA$405,MATCH(LARGE(BBスクリーニング!$AE$6:$AE$405,$A30),BBスクリーニング!$AE$6:$AE$405,0)),"") -> 1617.65 | N30: =IFERROR(INDEX(BBスクリーニング!$AC$6:$AC$405,MATCH(LARGE(BBスクリーニング!$AE$6:$AE$405,$A30),BBスクリーニング!$AE$6:$AE$405,0)),"") -> 0.38 | O30: =IF($B30="","",HYPERLINK("https://kabutan.jp/stock/?code="&$B30,"株探")) -> 株探
A31: 27 | B31: =IFERROR(INDEX(BBスクリーニング!$B$6:$B$405,MATCH(LARGE(BBスクリーニング!$AE$6:$AE$405,$A31),BBスクリーニング!$AE$6:$AE$405,0)),"") -> 7609 | C31: =IFERROR(INDEX(BBスクリーニング!$C$6:$C$405,MATCH(LARGE(BBスクリーニング!$AE$6:$AE$405,$A31),BBスクリーニング!$AE$6:$AE$405,0)),"") -> ダイトロン | D31: =IFERROR(INDEX(BBスクリーニング!$D$6:$D$405,MATCH(LARGE(BBスクリーニング!$AE$6:$AE$405,$A31),BBスクリーニング!$AE$6:$AE$405,0)),"") -> 4215 | E31: =IFERROR(INDEX(BBスクリーニング!$N$6:$N$405,MATCH(LARGE(BBスクリーニング!$AE$6:$AE$405,$A31),BBスクリーニング!$AE$6:$AE$405,0)),"") -> － | F31: =IFERROR(INDEX(BBスクリーニング!$P$6:$P$405,MATCH(LARGE(BBスクリーニング!$AE$6:$AE$405,$A31),BBスクリーニング!$AE$6:$AE$405,0)),"") -> ↑+2σ突破 | G31: =IFERROR(INDEX(BBスクリーニング!$Q$6:$Q$405,MATCH(LARGE(BBスクリーニング!$AE$6:$AE$405,$A31),BBスクリーニング!$AE$6:$AE$405,0)),"") -> 67.19457 | H31: =IFERROR(INDEX(BBスクリーニング!$R$6:$R$405,MATCH(LARGE(BBスクリーニング!$AE$6:$AE$405,$A31),BBスクリーニング!$AE$6:$AE$405,0)),"") -> 70.687012 | I31: =IFERROR(INDEX(BBスクリーニング!$S$6:$S$405,MATCH(LARGE(BBスクリーニング!$AE$6:$AE$405,$A31),BBスクリーニング!$AE$6:$AE$405,0)),"") -> － | J31: =IFERROR(INDEX(BBスクリーニング!$W$6:$W$405,MATCH(LARGE(BBスクリーニング!$AE$6:$AE$405,$A31),BBスクリーニング!$AE$6:$AE$405,0)),"") -> △二番底買(確) | K31: =IFERROR(INDEX(BBスクリーニング!$X$6:$X$405,MATCH(LARGE(BBスクリーニング!$AE$6:$AE$405,$A31),BBスクリーニング!$AE$6:$AE$405,0)),"") -> 55 | L31: =IFERROR(INDEX(BBスクリーニング!$Z$6:$Z$405,MATCH(LARGE(BBスクリーニング!$AE$6:$AE$405,$A31),BBスクリーニング!$AE$6:$AE$405,0)),"") -> 3850.8617 | M31: =IFERROR(INDEX(BBスクリーニング!$AA$6:$AA$405,MATCH(LARGE(BBスクリーニング!$AE$6:$AE$405,$A31),BBスクリーニング!$AE$6:$AE$405,0)),"") -> 3527.75 | N31: =IFERROR(INDEX(BBスクリーニング!$AC$6:$AC$405,MATCH(LARGE(BBスクリーニング!$AE$6:$AE$405,$A31),BBスクリーニング!$AE$6:$AE$405,0)),"") -> 0.41 | O31: =IF($B31="","",HYPERLINK("https://kabutan.jp/stock/?code="&$B31,"株探")) -> 株探
A32: 28 | B32: =IFERROR(INDEX(BBスクリーニング!$B$6:$B$405,MATCH(LARGE(BBスクリーニング!$AE$6:$AE$405,$A32),BBスクリーニング!$AE$6:$AE$405,0)),"") -> 5632 | C32: =IFERROR(INDEX(BBスクリーニング!$C$6:$C$405,MATCH(LARGE(BBスクリーニング!$AE$6:$AE$405,$A32),BBスクリーニング!$AE$6:$AE$405,0)),"") -> 三菱製鋼 | D32: =IFERROR(INDEX(BBスクリーニング!$D$6:$D$405,MATCH(LARGE(BBスクリーニング!$AE$6:$AE$405,$A32),BBスクリーニング!$AE$6:$AE$405,0)),"") -> 2307 | E32: =IFERROR(INDEX(BBスクリーニング!$N$6:$N$405,MATCH(LARGE(BBスクリーニング!$AE$6:$AE$405,$A32),BBスクリーニング!$AE$6:$AE$405,0)),"") -> － | F32: =IFERROR(INDEX(BBスクリーニング!$P$6:$P$405,MATCH(LARGE(BBスクリーニング!$AE$6:$AE$405,$A32),BBスクリーニング!$AE$6:$AE$405,0)),"") -> ↑+2σ突破 | G32: =IFERROR(INDEX(BBスクリーニング!$Q$6:$Q$405,MATCH(LARGE(BBスクリーニング!$AE$6:$AE$405,$A32),BBスクリーニング!$AE$6:$AE$405,0)),"") -> 68.957346 | H32: =IFERROR(INDEX(BBスクリーニング!$R$6:$R$405,MATCH(LARGE(BBスクリーニング!$AE$6:$AE$405,$A32),BBスクリーニング!$AE$6:$AE$405,0)),"") -> 61.352306 | I32: =IFERROR(INDEX(BBスクリーニング!$S$6:$S$405,MATCH(LARGE(BBスクリーニング!$AE$6:$AE$405,$A32),BBスクリーニング!$AE$6:$AE$405,0)),"") -> － | J32: =IFERROR(INDEX(BBスクリーニング!$W$6:$W$405,MATCH(LARGE(BBスクリーニング!$AE$6:$AE$405,$A32),BBスクリーニング!$AE$6:$AE$405,0)),"") -> △二番底買(確) | K32: =IFERROR(INDEX(BBスクリーニング!$X$6:$X$405,MATCH(LARGE(BBスクリーニング!$AE$6:$AE$405,$A32),BBスクリーニング!$AE$6:$AE$405,0)),"") -> 55 | L32: =IFERROR(INDEX(BBスクリーニング!$Z$6:$Z$405,MATCH(LARGE(BBスクリーニング!$AE$6:$AE$405,$A32),BBスクリーニング!$AE$6:$AE$405,0)),"") -> 2212.1832 | M32: =IFERROR(INDEX(BBスクリーニング!$AA$6:$AA$405,MATCH(LARGE(BBスクリーニング!$AE$6:$AE$405,$A32),BBスクリーニング!$AE$6:$AE$405,0)),"") -> 2158.1 | N32: =IFERROR(INDEX(BBスクリーニング!$AC$6:$AC$405,MATCH(LARGE(BBスクリーニング!$AE$6:$AE$405,$A32),BBスクリーニング!$AE$6:$AE$405,0)),"") -> 0.09 | O32: =IF($B32="","",HYPERLINK("https://kabutan.jp/stock/?code="&$B32,"株探")) -> 株探
... A34: 30 | B34: =IFERROR(INDEX(BBスクリーニング!$B$6:$B$405,MATCH(LARGE(BBスクリーニング!$AE$6:$AE$405,$A34),BBスクリーニング!$AE$6:$AE$405,0)),"") -> 6366 | C34: =IFERROR(INDEX(BBスクリーニング!$C$6:$C$405,MATCH(LARGE(BBスクリーニング!$AE$6:$AE$405,$A34),BBスクリーニング!$AE$6:$AE$405,0)),"") -> 千代田化工建 | D34: =IFERROR(INDEX(BBスクリーニング!$D$6:$D$405,MATCH(LARGE(BBスクリーニング!$AE$6:$AE$405,$A34),BBスクリーニング!$AE$6:$AE$405,0)),"") -> 695 | E34: =IFERROR(INDEX(BBスクリーニング!$N$6:$N$405,MATCH(LARGE(BBスクリーニング!$AE$6:$AE$405,$A34),BBスクリーニング!$AE$6:$AE$405,0)),"") -> スクイーズ★ | F34: =IFERROR(INDEX(BBスクリーニング!$P$6:$P$405,MATCH(LARGE(BBスクリーニング!$AE$6:$AE$405,$A34),BBスクリーニング!$AE$6:$AE$405,0)),"") -> バンド内 | G34: =IFERROR(INDEX(BBスクリーニング!$Q$6:$Q$405,MATCH(LARGE(BBスクリーニング!$AE$6:$AE$405,$A34),BBスクリーニング!$AE$6:$AE$405,0)),"") -> 53.636364 | H34: =IFERROR(INDEX(BBスクリーニング!$R$6:$R$405,MATCH(LARGE(BBスクリーニング!$AE$6:$AE$405,$A34),BBスクリーニング!$AE$6:$AE$405,0)),"") -> 56.532528 | I34: =IFERROR(INDEX(BBスクリーニング!$S$6:$S$405,MATCH(LARGE(BBスクリーニング!$AE$6:$AE$405,$A34),BBスクリーニング!$AE$6:$AE$405,0)),"") -> 強気div▲ | J34: =IFERROR(INDEX(BBスクリーニング!$W$6:$W$405,MATCH(LARGE(BBスクリーニング!$AE$6:$AE$405,$A34),BBスクリーニング!$AE$6:$AE$405,0)),"") -> ○反発(ダイバ)買 | K34: =IFERROR(INDEX(BBスクリーニング!$X$6:$X$405,MATCH(LARGE(BBスクリーニング!$AE$6:$AE$405,$A34),BBスクリーニング!$AE$6:$AE$405,0)),"") -> 55 | L34: =IFERROR(INDEX(BBスクリーニング!$Z$6:$Z$405,MATCH(LARGE(BBスクリーニング!$AE$6:$AE$405,$A34),BBスクリーニング!$AE$6:$AE$405,0)),"") -> 706.02242 | M34: =IFERROR(INDEX(BBスクリーニング!$AA$6:$AA$405,MATCH(LARGE(BBスクリーニング!$AE$6:$AE$405,$A34),BBスクリーニング!$AE$6:$AE$405,0)),"") -> 678.8 | N34: =IFERROR(INDEX(BBスクリーニング!$AC$6:$AC$405,MATCH(LARGE(BBスクリーニング!$AE$6:$AE$405,$A34),BBスクリーニング!$AE$6:$AE$405,0)),"") -> 2.36 | O34: =IF($B34="","",HYPERLINK("https://kabutan.jp/stock/?code="&$B34,"株探")) -> 株探

Sheet BBスクリーニング
A1: 📊 ボリンジャーバンド 買い候補スクリーニング（SMA20・±1σ/±2σ）
A2: 終値シートの最新終値を基準に自動計算。スコア降順に並べ替え、または「BB買い候補TOP」を参照。
A3: ◎スクイーズブレイク ○順張り/反発 △二番底 ☆スクイーズ監視 ・押し目 ▼危険（凡例はBB設定シート）
A5: 🔗 | B5: コード | C5: 銘柄名 | D5: 現在値 | E5: SMA20 ミドル | F5: σ | G5: +2σ | H5: +1σ | I5: -1σ | J5: -2σ | K5: %B | L5: 帯幅% | M5: 帯幅25日 最小% | N5: スクイーズ | O5: 帯拡大 | P5: ブレイク | Q5: RSI14 | R5: MFI14 | S5: ダイバー ジェンス | T5: バンド ウォーク | U5: 二番底/天井 | V5: 出来高 倍率 | W5: 戦略シグナル | X5: スコア | Y5: エントリー 目安 | Z5: 利確 (+1σ) | AA5: 損切り (ミドル) | AB5: 目標 (+2σ) | AC5: R:R | AD5: 直近5日 安値 | AE5: sortkey
A6: =IF(終値!A6="","",HYPERLINK("https://kabutan.jp/stock/?code="&終値!A6,"📈")) -> 📈 | B6: =IF(終値!A6="","",終値!A6) -> 5706 | C6: =IF(終値!A6="","",終値!B6) -> 三井金属 | D6: =IF(終値!A6="","",終値!E6) -> 31970 | E6: =IF($D6="","",AVERAGE(終値!E6:X6)) -> 32112.5 | F6: =IF($D6="","",STDEVP(終値!E6:X6)) -> 2827.1242 | G6: =IF($D6="","",$E6+BB設定!$B$4*$F6) -> 37766.748 | H6: =IF($D6="","",$E6+BB設定!$B$5*$F6) -> 34939.624 | I6: =IF($D6="","",$E6-BB設定!$B$5*$F6) -> 29285.376 | J6: =IF($D6="","",$E6-BB設定!$B$4*$F6) -> 26458.252 | K6: =IF($D6="","",IFERROR(($D6-$J6)/($G6-$J6),"")) -> 0.48739886 | L6: =IF($D6="","",IFERROR(($G6-$J6)/$E6*100,"")) -> 35.215249 | M6: =IF($D6="","",IFERROR(MIN(BB_帯幅!B6:AP6)*100,"")) -> 34.851626 | N6: =IF($L6="","",IF($L6<=$M6*BB設定!$B$7,"スクイーズ★",IF($L6<=$M6*1.3,"収縮","－"))) -> スクイーズ★ | O6: =IF($D6="","",IF(AND(BB_帯幅!B6>BB_帯幅!C6,BB_帯幅!C6>BB_帯幅!D6),"拡大↑","縮小↓")) -> 縮小↓ | P6: =IF($D6="","",IF($D6>$G6,"↑+2σ突破",IF($D6<$J6,"↓-2σ割れ",IF($D6>$H6,"+1σ上",IF($D6<$I6,"-1σ下","バンド内"))))) -> バンド内 | Q6: =IF($D6="","",IFERROR(100-100/(1+SUMPRODUCT((終値!E6:R6>終値!F6:S6)*(終値!E6:R6-終値!F6:S6))/SUMPRODUCT((終値!E6:R6<終値!F6:S6)*(終値!F6:S6-終値!E6:R6))),100)) -> 49.440433 | R6: =IF($D6="","",IFERROR(100-100/(1+SUMPRODUCT((((高値!E6:R6+安値!E6:R6+終値!E6:R6)/3)>((高値!F6:S6+安値!F6:S6+終値!F6:S6)/3))*((高値!E6:R6+安値!E6:R6+終値!E6:R6)/3)*出来高!E6:R6)/SUMPRODUCT((((高値!E6:R6+安値!E6:R6+終値!E6:R6)/3)<((高値!F6:S6+安値!F6:S6+終値!F6:S6)/3))*((高値!E6:R6+安値!E6:R6+終値!E6:R6)/3)*出来高!E6:R6)),50)) -> 56.165379 | S6: =IF($D6="","",IF(AND(終値!E6<終値!O6,$Q6>(IFERROR(100-100/(1+SUMPRODUCT((終値!O6:AB6>終値!P6:AC6)*(終値!O6:AB6-終値!P6:AC6))/SUMPRODUCT((終値!O6:AB6<終値!P6:AC6)*(終値!P6:AC6-終値!O6:AB6))),100))),"強気div▲",IF(AND(終値!E6>終値!O6,$Q6<(IFERROR(100-100/(1+SUMPRODUCT((終値!O6:AB6>終値!P6:AC6)*(終値!O6:AB6-終値!P6:AC6))/SUMPRODUCT((終値!O6:AB6<終値!P6:AC6)*(終値!P6:AC6-終値!O6:AB6))),100))),"弱気div▼","－"))) -> 強気div▲ | T6: =IF($D6="","",IF($D6>=$H6,"上walk▲",IF($D6<=$I6,"下walk▼","－"))) -> － | U6: =IF(終値!A6="","",BB_スイング!BT6) -> － | V6: =IF($D6="","",IFERROR(出来高!E6/AVERAGE(出来高!E6:I6),"")) -> 0.97157509 | W6: =IF($D6="","",IF(AND($D6>$G6,$O6="拡大↑",OR($N6="スクイーズ★",$N6="収縮")),"◎スクイーズブレイク買",IF(AND($D6>=$H6,$R6>=BB設定!$B$10),"○順張り継続(walk)",IF(AND($S6="強気div▲",$D6>$I6,LEFT($U6,4)<>"二番天井"),"○反発(ダイバ)買",IF($U6="二番底W▲","△二番底買(確)",IF($U6="二番底W形成","△二番底形成",IF(LEFT($U6,4)="二番天井","▼二番天井警戒",IF($D6<$J6,"▼-2σ割れ危険",IF(AND($D6>$E6,$K6<0.6,$R6>=50),"・押し目注目",IF($N6="スクイーズ★","☆スクイーズ監視","様子見")))))))))) -> ○反発(ダイバ)買 | X6: =IF($D6="","",MAX(0,MIN(100,IF($L6<=$M6*1.15,20,IF($L6<=$M6*1.4,10,0))+IF($D6>$G6,20,IF($D6>$H6,12,IF($D6>$E6,5,0)))+IF($O6="拡大↑",10,0)+IF($R6>=80,15,IF($R6>=60,10,IF($R6>=50,5,0)))+IF(AND($Q6>=50,$Q6<=70),10,IF($Q6>70,3,IF($Q6>=40,5,0)))+IF(AND($S6="強気div▲",$T6<>"下walk▼"),15,IF(AND($S6="強気div▲",$T6="下walk▼"),5,0))+IF($T6="上walk▲",5,0)+IF($V6>=2,5,IF($V6>=1.5,3,0))+IF(LEFT($U6,4)="二番天井",-15,0)+IF($D6<$E6,-10,0)+IF($T6="下walk▼",-10,0)+IF($K6<0.2,-5,0)))) -> 35 | Y6: =IF($D6="","",$D6) -> 31970 | Z6: =IF($D6="","",$H6) -> 34939.624 | AA6: =IF($D6="","",IF($D6>$E6,$E6,$AD6)) -> 30890 | AB6: =IF($D6="","",IF($D6>$G6,$E6+3*$F6,$G6)) -> 37766.748 | AC6: =IF($D6="","",IF(($Y6-$AA6)<=0,"－",IFERROR(ROUND(MIN(20,($AB6-$Y6)/($Y6-$AA6)),2),"－"))) -> 5.37 | AD6: =IF($D6="","",MIN(終値!E6:I6)) -> 30890 | AE6: =IF($D6="","",$X6+(10000-ROW())/100000) -> 35.09994
